Workbook

Sheet GUIA
A1: MRP — Planificacion de Requerimientos de Materiales | ATMIN / MukiCloud
A2: ARCHIVO DE CORRIDA (ejemplo llenado). Las celdas naranjas son SUPUESTOS mios: precio, proveedor, lead time, lote, stock de seguridad y stock actual. El consumo por metro es el dato real que diste.
B4: 1. ¿Que es un MRP y que te responde?
B6: Un MRP responde tres preguntas: QUE material pedir, CUANTO pedir y CUANDO lanzar el pedido.
B7: Parte del plan de avance (metros por frente), lo multiplica por el estandar de consumo, le resta lo que ya tienes en almacen y lo que ya esta pedido, y te dice cuanto falta y en que semana debes emitir la orden para que llegue a tiempo.
B9: Necesidad neta = Necesidad bruta − Stock disponible − Ordenes en transito + Stock de seguridad
B10: Fecha de pedido = Semana en que se necesita − Lead time del proveedor
B12: 2. Orden de llenado (sigue las pestañas de izquierda a derecha)
A14: Paso | B14: Pestaña | C14: Que llenas ahi | D14: Ejemplo concreto | E14: Ojo con esto
A15: 1 | B15: Materiales | C15: El maestro: un renglon por material que quieras planificar. Codigo, unidad, precio, proveedor, lead time, lote de compra y stock de seguridad. | D15: EXP-001 · Emulsion 1"x7" · UND · S/ 3.80 · Famesa · 2 semanas · lote 500 · seguridad 800 | E15: El LEAD TIME va en SEMANAS enteras (2 = llega a las 2 semanas). El LOTE es el multiplo de compra: si pones 500, el MRP siempre redondea hacia arriba a 500, 1000, 1500.
A16: 2 | B16: Plan | C16: El plan de avance: cuantos metros (o unidades) vas a producir por frente y por semana. Tambien la fecha de inicio de la Semana 1. | D16: RA Brenda · Metros de avance · Sem1 20 · Sem2 25 · Sem3 25 ... | E16: Tus 6 frentes ya vienen escritos. Si el frente no tiene meta esa semana, deja la celda vacia (=0). La fecha de la Semana 1 manda el calendario de TODAS las hojas.
A17: 3 | B17: Consumo | C17: El estandar de consumo (BOM): cuanto material se gasta por CADA metro de avance, por frente. Una linea por combinacion frente + material. | D17: RA Brenda · EXP-001 · 45 unidades por metro de avance | E17: Aca esta el 80% de la exactitud del MRP. Saca el numero del consumo real historico del Compresorista (consumo del mes / metros del mes), no del catalogo teorico.
A18: 4 | B18: Inventario | C18: Lo que HOY tienes en almacen (stock actual) y las ordenes de compra ya emitidas que aun no llegan, puestas en la semana en que llegaran. | D18: EXP-001 · stock 1,200 · OC-1024 Famesa · llegan 500 en Sem 2 | E18: El stock actual es el del Almacen General + NV2820 juntos. Si un material tiene 2 ordenes en camino, usa 2 renglones con el mismo codigo.
A19: — | B19: MRP | C19: NO SE LLENA. Es el calculo semana por semana, 6 renglones por material. | D19: Mira el renglon verde: LANZAMIENTO DE ORDEN. | E19: Si el stock proyectado sale en rojo, te vas a quedar sin material esa semana.
A20: — | B20: Ordenes | C20: NO SE LLENA. El resumen para comprar: que pedir, cuanto, en que semana y cuanta plata. | D20: Esta es la hoja que le mandas a Logistica. | E20: Si dice PEDIR YA (atrasado) es porque el material se necesita antes de lo que alcanza el lead time.
B22: 3. Como leer la hoja MRP (los 6 renglones de cada material)
B24: Necesidad bruta | C24: Lo que el plan de avance va a consumir esa semana. = metros del frente × consumo por metro.
B25: Recepciones programadas | C25: Lo que YA esta pedido y llega esa semana (lo escribiste en Inventario).
B26: Stock proyectado disponible | C26: Lo que quedara en almacen al cerrar la semana. En rojo = quiebre de stock.
B27: Necesidad neta | C27: Lo que realmente falta comprar, ya descontado el stock y lo que viene en camino.
B28: Recepcion de orden planificada | C28: La necesidad neta redondeada al lote de compra. Es lo que debe LLEGAR esa semana.
B29: LANZAMIENTO DE ORDEN | C29: La misma cantidad pero corrida hacia atras por el lead time. ES LA SEMANA EN QUE DEBES PEDIR.
B31: 4. Leyenda de colores
C33: Celda que TU llenas (texto azul sobre amarillo)
C34: Fila de EJEMPLO ya llenada: reemplazala con tus datos reales
C35: Celda calculada por formula: no la toques
C36: Resultado accionable: la orden que debes lanzar
C37: Rojo = quiebre de stock proyectado esa semana
B39: 5. Supuestos de esta plantilla
B41: • Horizonte de 8 semanas. La Semana 1 arranca en la fecha que pongas en la hoja Plan (celda C2).
B42: • Moneda: Soles (S/). Si trabajas en dolares, cambia el formato de las columnas de precio.
B43: • Capacidad: 15 materiales, 20 frentes, 100 lineas de estandar de consumo, 25 lineas de inventario.
B44: • Lead time expresado en semanas enteras. Lote de compra = multiplo; si lo dejas en 0 se pide la cantidad exacta.
B45: • Los 6 frentes vienen precargados de la constante FRENTES de index.html (RA Brenda, CRNE, GLSE-2, ESCM 4430, ESCM 4410, SN 5100 NW).

Sheet RESUMEN MES
A1: CORRIDA MRP — MES DE SETIEMBRE 2026 (semanas 1 a 4)
A2: Corrida de ejemplo con los estandares de sostenimiento reales de RA Brenda y CRNE. Todo se recalcula solo si cambias el plan de avance en la hoja Plan.
B4: A. El estandar que me diste, convertido a consumo por metro
B6: Frente | C6: Regla de sostenimiento | D6: Disparo | E6: Material | F6: Por disparo | G6: Por metro
B7: RA Brenda | C7: Sostenimiento pesado: cimbra en cada disparo | D7: 1.5 | E7: Cimbra | F7: 1 | G7: 0.6667
B8: CRNE | C8: Malla electrosoldada, seccion 3.5 x 3.5 m | D8: 1.5 | E8: Malla | F8: 1 | G8: 0.6667
B9: CRNE | C9: Pernos, seccion 3.5 x 3.5 m | D9: 1.5 | E9: Perno helicoidal | F9: 11 | G9: 7.3333
B11: B. Plan de avance del mes
B13: Frente | C13: Unidad | D13: Sem 1 | E13: Sem 2 | F13: Sem 3 | G13: Sem 4 | H13: Metros del mes | I13: Disparos del mes
B14: =Plan!A5 | C14: =Plan!B5 | D14: =Plan!E5 | E14: =Plan!F5 | F14: =Plan!G5 | G14: =Plan!H5 | H14: =SUM(D14:G14) | I14: =H14/1.5
B15: =Plan!A6 | C15: =Plan!B6 | D15: =Plan!E6 | E15: =Plan!F6 | F15: =Plan!G6 | G15: =Plan!H6 | H15: =SUM(D15:G15) | I15: =H15/1.5
B16: TOTAL | D16: =SUM(D14:D15) | E16: =SUM(E14:E15) | F16: =SUM(F14:F15) | G16: =SUM(G14:G15) | H16: =SUM(H14:H15) | I16: =SUM(I14:I15)
B18: C. Lo que el mes consume (necesidad bruta = plan x estandar)
B20: Codigo | C20: Material | D20: Sem 1 | E20: Sem 2 | F20: Sem 3 | G20: Sem 4 | H20: Total del mes | I20: Costo del mes (S/)
B21: =Materiales!A4 | C21: =Materiales!B4 | D21: =MRP!E5 | E21: =MRP!F5 | F21: =MRP!G5 | G21: =MRP!H5 | H21: =SUM(D21:G21) | I21: =H21*Materiales!D4
B22: =Materiales!A5 | C22: =Materiales!B5 | D22: =MRP!E12 | E22: =MRP!F12 | F22: =MRP!G12 | G22: =MRP!H12 | H22: =SUM(D22:G22) | I22: =H22*Materiales!D5
B23: =Materiales!A6 | C23: =Materiales!B6 | D23: =MRP!E19 | E23: =MRP!F19 | F23: =MRP!G19 | G23: =MRP!H19 | H23: =SUM(D23:G23) | I23: =H23*Materiales!D6
B24: TOTAL CONSUMO DEL MES | I24: =SUM(I21:I23)
B26: D. Lo que hay que COMPRAR y en que semana lanzarlo (esto es la salida del MRP)
B28: Codigo | C28: Material | D28: Sem 1 | E28: Sem 2 | F28: Sem 3 | G28: Sem 4 | H28: Total a pedir | I28: Alerta
B29: =Materiales!A4 | C29: =Materiales!B4 | D29: =MRP!E10 | E29: =MRP!F10 | F29: =MRP!G10 | G29: =MRP!H10 | H29: =SUM(D29:G29) | I29: =MRP!M10
B30: =Materiales!A5 | C30: =Materiales!B5 | D30: =MRP!E17 | E30: =MRP!F17 | F30: =MRP!G17 | G30: =MRP!H17 | H30: =SUM(D30:G30) | I30: =MRP!M17
B31: =Materiales!A6 | C31: =Materiales!B6 | D31: =MRP!E24 | E31: =MRP!F24 | F31: =MRP!G24 | G31: =MRP!H24 | H31: =SUM(D31:G31) | I31: =MRP!M24
B33: E. Como leer esta corrida
B35: Las cimbras salen atrasadas. | C35: El lead time supuesto es de 3 semanas y el stock (4) no cubre ni la primera semana. Por eso el MRP marca PEDIR YA: las cimbras de las semanas 1 a 3 se debieron ordenar el mes pasado.
B36: Las mallas y pernos aguantan el mes. | C36: Las ordenes en transito (20 mallas y 200 pernos que llegan en la Semana 2) cubren casi todo el mes. El MRP recien vuelve a pedir hacia el final del horizonte.
B37: Si cambias un metro de avance, cambia todo. | C37: Toca la hoja Plan y este resumen, la hoja MRP y la hoja Ordenes se recalculan solas. Asi puedes simular: que pasa si Brenda avanza 18 m en vez de 15.
B38: Lo unico que debes ajustar son los supuestos naranjas. | C38: Precio, proveedor, lead time, lote de compra, stock de seguridad y stock actual los puse yo como referencia. El consumo por metro si es el tuyo.

Sheet Materiales
A1: PASO 1 — Maestro de materiales
A2: Un renglon por material a planificar. Llena las celdas amarillas. La fila naranja es un ejemplo: reemplazala.
A3: Codigo | B3: Material | C3: Unidad | D3: Precio unitario (S/) | E3: Proveedor | F3: Lead time (semanas) | G3: Lote de compra (multiplo) | H3: Stock de seguridad | I3: Notas
A4: SOS-CIM-001 | B4: Cimbra metalica 6"x4" — seccion 3.5x3.5 m | C4: UND | D4: 1850 | E4: Por definir | F4: 3 | G4: 5 | H4: 6 | I4: Consumo CONFIRMADO por operacion. Precio/proveedor/LT/lote/seguridad = SUPUESTO, ajustar.
A5: SOS-MAL-001 | B5: Malla electrosoldada 3.5x3.5 m | C5: UND | D5: 160 | E5: Por definir | F5: 2 | G5: 20 | H5: 8 | I5: Consumo CONFIRMADO por operacion. Precio/proveedor/LT/lote/seguridad = SUPUESTO, ajustar.
A6: SOS-PER-001 | B6: Perno helicoidal 7 pies | C6: UND | D6: 38 | E6: Por definir | F6: 2 | G6: 100 | H6: 90 | I6: Consumo CONFIRMADO por operacion. Precio/proveedor/LT/lote/seguridad = SUPUESTO, ajustar.

Sheet Plan
A1: PASO 2 — Plan de avance por frente y semana (MPS)
A2: Escribe la meta de produccion de cada frente en cada semana. Define tambien la fecha de inicio de la Semana 1.
A3: Fecha de inicio de la Semana 1 → | C3: 46265 | D3: (Sem 1 a 4 = el mes; Sem 5 a 8 = continuidad, necesaria porque el lead time es de 2 a 3 semanas) | E3: =$C$3 | F3: =E3+7 | G3: =F3+7 | H3: =G3+7 | I3: =H3+7 | J3: =I3+7 | K3: =J3+7 | L3: =K3+7
A4: Frente | B4: Unidad de produccion | C4: Total horizonte | D4: Notas | E4: Sem 1 | F4: Sem 2 | G4: Sem 3 | H4: Sem 4 | I4: Sem 5 | J4: Sem 6 | K4: Sem 7 | L4: Sem 8
A5: RA Brenda | B5: Metros de avance | C5: =IF($A5="","",SUM(E5:L5)) | D5: 1 disparo = 1.5 m | E5: 12 | F5: 15 | G5: 15 | H5: 18 | I5: 15 | J5: 15 | K5: 15 | L5: 15
A6: CRNE (Cortada Noreste) | B6: Metros de avance | C6: =IF($A6="","",SUM(E6:L6)) | D6: 1 disparo = 1.5 m | E6: 9 | F6: 12 | G6: 15 | H6: 12 | I6: 12 | J6: 12 | K6: 12 | L6: 12
A7: GLSE-2 | B7: Metros de avance | C7: =IF($A7="","",SUM(E7:L7))
A8: ESCM 4430 | B8: Metros de avance | C8: =IF($A8="","",SUM(E8:L8))
A9: ESCM 4410 | B9: Metros de avance | C9: =IF($A9="","",SUM(E9:L9))
A10: SN 5100 NW | B10: Metros de avance | C10: =IF($A10="","",SUM(E10:L10))
C11: =IF($A11="","",SUM(E11:L11))
C12: =IF($A12="","",SUM(E12:L12))
C13: =IF($A13="","",SUM(E13:L13))
C14: =IF($A14="","",SUM(E14:L14))
C15: =IF($A15="","",SUM(E15:L15))
C16: =IF($A16="","",SUM(E16:L16))
C17: =IF($A17="","",SUM(E17:L17))
C18: =IF($A18="","",SUM(E18:L18))
C19: =IF($A19="","",SUM(E19:L19))
C20: =IF($A20="","",SUM(E20:L20))
C21: =IF($A21="","",SUM(E21:L21))
C22: =IF($A22="","",SUM(E22:L22))
... C24: =IF($A24="","",SUM(E24:L24))

Sheet Consumo
A1: PASO 3 — Estandar de consumo por unidad producida (BOM)
A2: Una linea por combinacion FRENTE + MATERIAL. Columna E: cuanto material se gasta por CADA metro de avance. Las columnas grises Sem 1..8 se calculan solas (demanda de esa linea).
A3: Frente / Actividad | B3: Codigo material | C3: Material (auto) | D3: Unidad (auto) | E3: Consumo por unidad producida | F3: Notas / fuente del estandar | G3: Demanda Sem 1 | H3: Demanda Sem 2 | I3: Demanda Sem 3 | J3: Demanda Sem 4 | K3: Demanda Sem 5 | L3: Demanda Sem 6 | M3: Demanda Sem 7 | N3: Demanda Sem 8
A4: RA Brenda | B4: SOS-CIM-001 | C4: =IFERROR(INDEX(Materiales!$B$4:$B$18,MATCH($B4,Materiales!$A$4:$A$18,0)),"") | D4: =IFERROR(INDEX(Materiales!$C$4:$C$18,MATCH($B4,Materiales!$A$4:$A$18,0)),"") | E4: =1/1.5 | F4: Sostenimiento pesado: 1 cimbra por disparo de 1.5 m -> 1 / 1.5 | G4: =IF($B4="",0,$E4*SUMIF(Plan!$A$5:$A$24,$A4,Plan!E$5:E$24)) | H4: =IF($B4="",0,$E4*SUMIF(Plan!$A$5:$A$24,$A4,Plan!F$5:F$24)) | I4: =IF($B4="",0,$E4*SUMIF(Plan!$A$5:$A$24,$A4,Plan!G$5:G$24)) | J4: =IF($B4="",0,$E4*SUMIF(Plan!$A$5:$A$24,$A4,Plan!H$5:H$24)) | K4: =IF($B4="",0,$E4*SUMIF(Plan!$A$5:$A$24,$A4,Plan!I$5:I$24)) | L4: =IF($B4="",0,$E4*SUMIF(Plan!$A$5:$A$24,$A4,Plan!J$5:J$24)) | M4: =IF($B4="",0,$E4*SUMIF(Plan!$A$5:$A$24,$A4,Plan!K$5:K$24)) | N4: =IF($B4="",0,$E4*SUMIF(Plan!$A$5:$A$24,$A4,Plan!L$5:L$24))
A5: CRNE (Cortada Noreste) | B5: SOS-MAL-001 | C5: =IFERROR(INDEX(Materiales!$B$4:$B$18,MATCH($B5,Materiales!$A$4:$A$18,0)),"") | D5: =IFERROR(INDEX(Materiales!$C$4:$C$18,MATCH($B5,Materiales!$A$4:$A$18,0)),"") | E5: =1/1.5 | F5: 1 malla electrosoldada por disparo de 1.5 m, seccion 3.5 x 3.5 m -> 1 / 1.5 | G5: =IF($B5="",0,$E5*SUMIF(Plan!$A$5:$A$24,$A5,Plan!E$5:E$24)) | H5: =IF($B5="",0,$E5*SUMIF(Plan!$A$5:$A$24,$A5,Plan!F$5:F$24)) | I5: =IF($B5="",0,$E5*SUMIF(Plan!$A$5:$A$24,$A5,Plan!G$5:G$24)) | J5: =IF($B5="",0,$E5*SUMIF(Plan!$A$5:$A$24,$A5,Plan!H$5:H$24)) | K5: =IF($B5="",0,$E5*SUMIF(Plan!$A$5:$A$24,$A5,Plan!I$5:I$24)) | L5: =IF($B5="",0,$E5*SUMIF(Plan!$A$5:$A$24,$A5,Plan!J$5:J$24)) | M5: =IF($B5="",0,$E5*SUMIF(Plan!$A$5:$A$24,$A5,Plan!K$5:K$24)) | N5: =IF($B5="",0,$E5*SUMIF(Plan!$A$5:$A$24,$A5,Plan!L$5:L$24))
A6: CRNE (Cortada Noreste) | B6: SOS-PER-001 | C6: =IFERROR(INDEX(Materiales!$B$4:$B$18,MATCH($B6,Materiales!$A$4:$A$18,0)),"") | D6: =IFERROR(INDEX(Materiales!$C$4:$C$18,MATCH($B6,Materiales!$A$4:$A$18,0)),"") | E6: =11/1.5 | F6: 11 pernos por disparo de 1.5 m, seccion 3.5 x 3.5 m -> 11 / 1.5 | G6: =IF($B6="",0,$E6*SUMIF(Plan!$A$5:$A$24,$A6,Plan!E$5:E$24)) | H6: =IF($B6="",0,$E6*SUMIF(Plan!$A$5:$A$24,$A6,Plan!F$5:F$24)) | I6: =IF($B6="",0,$E6*SUMIF(Plan!$A$5:$A$24,$A6,Plan!G$5:G$24)) | J6: =IF($B6="",0,$E6*SUMIF(Plan!$A$5:$A$24,$A6,Plan!H$5:H$24)) | K6: =IF($B6="",0,$E6*SUMIF(Plan!$A$5:$A$24,$A6,Plan!I$5:I$24)) | L6: =IF($B6="",0,$E6*SUMIF(Plan!$A$5:$A$24,$A6,Plan!J$5:J$24)) | M6: =IF($B6="",0,$E6*SUMIF(Plan!$A$5:$A$24,$A6,Plan!K$5:K$24)) | N6: =IF($B6="",0,$E6*SUMIF(Plan!$A$5:$A$24,$A6,Plan!L$5:L$24))
C7: =IFERROR(INDEX(Materiales!$B$4:$B$18,MATCH($B7,Materiales!$A$4:$A$18,0)),"") | D7: =IFERROR(INDEX(Materiales!$C$4:$C$18,MATCH($B7,Materiales!$A$4:$A$18,0)),"") | G7: =IF($B7="",0,$E7*SUMIF(Plan!$A$5:$A$24,$A7,Plan!E$5:E$24)) | H7: =IF($B7="",0,$E7*SUMIF(Plan!$A$5:$A$24,$A7,Plan!F$5:F$24)) | I7: =IF($B7="",0,$E7*SUMIF(Plan!$A$5:$A$24,$A7,Plan!G$5:G$24)) | J7: =IF($B7="",0,$E7*SUMIF(Plan!$A$5:$A$24,$A7,Plan!H$5:H$24)) | K7: =IF($B7="",0,$E7*SUMIF(Plan!$A$5:$A$24,$A7,Plan!I$5:I$24)) | L7: =IF($B7="",0,$E7*SUMIF(Plan!$A$5:$A$24,$A7,Plan!J$5:J$24)) | M7: =IF($B7="",0,$E7*SUMIF(Plan!$A$5:$A$24,$A7,Plan!K$5:K$24)) | N7: =IF($B7="",0,$E7*SUMIF(Plan!$A$5:$A$24,$A7,Plan!L$5:L$24))
C8: =IFERROR(INDEX(Materiales!$B$4:$B$18,MATCH($B8,Materiales!$A$4:$A$18,0)),"") | D8: =IFERROR(INDEX(Materiales!$C$4:$C$18,MATCH($B8,Materiales!$A$4:$A$18,0)),"") | G8: =IF($B8="",0,$E8*SUMIF(Plan!$A$5:$A$24,$A8,Plan!E$5:E$24)) | H8: =IF($B8="",0,$E8*SUMIF(Plan!$A$5:$A$24,$A8,Plan!F$5:F$24)) | I8: =IF($B8="",0,$E8*SUMIF(Plan!$A$5:$A$24,$A8,Plan!G$5:G$24)) | J8: =IF($B8="",0,$E8*SUMIF(Plan!$A$5:$A$24,$A8,Plan!H$5:H$24)) | K8: =IF($B8="",0,$E8*SUMIF(Plan!$A$5:$A$24,$A8,Plan!I$5:I$24)) | L8: =IF($B8="",0,$E8*SUMIF(Plan!$A$5:$A$24,$A8,Plan!J$5:J$24)) | M8: =IF($B8="",0,$E8*SUMIF(Plan!$A$5:$A$24,$A8,Plan!K$5:K$24)) | N8: =IF($B8="",0,$E8*SUMIF(Plan!$A$5:$A$24,$A8,Plan!L$5:L$24))
C9: =IFERROR(INDEX(Materiales!$B$4:$B$18,MATCH($B9,Materiales!$A$4:$A$18,0)),"") | D9: =IFERROR(INDEX(Materiales!$C$4:$C$18,MATCH($B9,Materiales!$A$4:$A$18,0)),"") | G9: =IF($B9="",0,$E9*SUMIF(Plan!$A$5:$A$24,$A9,Plan!E$5:E$24)) | H9: =IF($B9="",0,$E9*SUMIF(Plan!$A$5:$A$24,$A9,Plan!F$5:F$24)) | I9: =IF($B9="",0,$E9*SUMIF(Plan!$A$5:$A$24,$A9,Plan!G$5:G$24)) | J9: =IF($B9="",0,$E9*SUMIF(Plan!$A$5:$A$24,$A9,Plan!H$5:H$24)) | K9: =IF($B9="",0,$E9*SUMIF(Plan!$A$5:$A$24,$A9,Plan!I$5:I$24)) | L9: =IF($B9="",0,$E9*SUMIF(Plan!$A$5:$A$24,$A9,Plan!J$5:J$24)) | M9: =IF($B9="",0,$E9*SUMIF(Plan!$A$5:$A$24,$A9,Plan!K$5:K$24)) | N9: =IF($B9="",0,$E9*SUMIF(Plan!$A$5:$A$24,$A9,Plan!L$5:L$24))
C10: =IFERROR(INDEX(Materiales!$B$4:$B$18,MATCH($B10,Materiales!$A$4:$A$18,0)),"") | D10: =IFERROR(INDEX(Materiales!$C$4:$C$18,MATCH($B10,Materiales!$A$4:$A$18,0)),"") | G10: =IF($B10="",0,$E10*SUMIF(Plan!$A$5:$A$24,$A10,Plan!E$5:E$24)) | H10: =IF($B10="",0,$E10*SUMIF(Plan!$A$5:$A$24,$A10,Plan!F$5:F$24)) | I10: =IF($B10="",0,$E10*SUMIF(Plan!$A$5:$A$24,$A10,Plan!G$5:G$24)) | J10: =IF($B10="",0,$E10*SUMIF(Plan!$A$5:$A$24,$A10,Plan!H$5:H$24)) | K10: =IF($B10="",0,$E10*SUMIF(Plan!$A$5:$A$24,$A10,Plan!I$5:I$24)) | L10: =IF($B10="",0,$E10*SUMIF(Plan!$A$5:$A$24,$A10,Plan!J$5:J$24)) | M10: =IF($B10="",0,$E10*SUMIF(Plan!$A$5:$A$24,$A10,Plan!K$5:K$24)) | N10: =IF($B10="",0,$E10*SUMIF(Plan!$A$5:$A$24,$A10,Plan!L$5:L$24))
C11: =IFERROR(INDEX(Materiales!$B$4:$B$18,MATCH($B11,Materiales!$A$4:$A$18,0)),"") | D11: =IFERROR(INDEX(Materiales!$C$4:$C$18,MATCH($B11,Materiales!$A$4:$A$18,0)),"") | G11: =IF($B11="",0,$E11*SUMIF(Plan!$A$5:$A$24,$A11,Plan!E$5:E$24)) | H11: =IF($B11="",0,$E11*SUMIF(Plan!$A$5:$A$24,$A11,Plan!F$5:F$24)) | I11: =IF($B11="",0,$E11*SUMIF(Plan!$A$5:$A$24,$A11,Plan!G$5:G$24)) | J11: =IF($B11="",0,$E11*SUMIF(Plan!$A$5:$A$24,$A11,Plan!H$5:H$24)) | K11: =IF($B11="",0,$E11*SUMIF(Plan!$A$5:$A$24,$A11,Plan!I$5:I$24)) | L11: =IF($B11="",0,$E11*SUMIF(Plan!$A$5:$A$24,$A11,Plan!J$5:J$24)) | M11: =IF($B11="",0,$E11*SUMIF(Plan!$A$5:$A$24,$A11,Plan!K$5:K$24)) | N11: =IF($B11="",0,$E11*SUMIF(Plan!$A$5:$A$24,$A11,Plan!L$5:L$24))
C12: =IFERROR(INDEX(Materiales!$B$4:$B$18,MATCH($B12,Materiales!$A$4:$A$18,0)),"") | D12: =IFERROR(INDEX(Materiales!$C$4:$C$18,MATCH($B12,Materiales!$A$4:$A$18,0)),"") | G12: =IF($B12="",0,$E12*SUMIF(Plan!$A$5:$A$24,$A12,Plan!E$5:E$24)) | H12: =IF($B12="",0,$E12*SUMIF(Plan!$A$5:$A$24,$A12,Plan!F$5:F$24)) | I12: =IF($B12="",0,$E12*SUMIF(Plan!$A$5:$A$24,$A12,Plan!G$5:G$24)) | J12: =IF($B12="",0,$E12*SUMIF(Plan!$A$5:$A$24,$A12,Plan!H$5:H$24)) | K12: =IF($B12="",0,$E12*SUMIF(Plan!$A$5:$A$24,$A12,Plan!I$5:I$24)) | L12: =IF($B12="",0,$E12*SUMIF(Plan!$A$5:$A$24,$A12,Plan!J$5:J$24)) | M12: =IF($B12="",0,$E12*SUMIF(Plan!$A$5:$A$24,$A12,Plan!K$5:K$24)) | N12: =IF($B12="",0,$E12*SUMIF(Plan!$A$5:$A$24,$A12,Plan!L$5:L$24))
C13: =IFERROR(INDEX(Materiales!$B$4:$B$18,MATCH($B13,Materiales!$A$4:$A$18,0)),"") | D13: =IFERROR(INDEX(Materiales!$C$4:$C$18,MATCH($B13,Materiales!$A$4:$A$18,0)),"") | G13: =IF($B13="",0,$E13*SUMIF(Plan!$A$5:$A$24,$A13,Plan!E$5:E$24)) | H13: =IF($B13="",0,$E13*SUMIF(Plan!$A$5:$A$24,$A13,Plan!F$5:F$24)) | I13: =IF($B13="",0,$E13*SUMIF(Plan!$A$5:$A$24,$A13,Plan!G$5:G$24)) | J13: =IF($B13="",0,$E13*SUMIF(Plan!$A$5:$A$24,$A13,Plan!H$5:H$24)) | K13: =IF($B13="",0,$E13*SUMIF(Plan!$A$5:$A$24,$A13,Plan!I$5:I$24)) | L13: =IF($B13="",0,$E13*SUMIF(Plan!$A$5:$A$24,$A13,Plan!J$5:J$24)) | M13: =IF($B13="",0,$E13*SUMIF(Plan!$A$5:$A$24,$A13,Plan!K$5:K$24)) | N13: =IF($B13="",0,$E13*SUMIF(Plan!$A$5:$A$24,$A13,Plan!L$5:L$24))
C14: =IFERROR(INDEX(Materiales!$B$4:$B$18,MATCH($B14,Materiales!$A$4:$A$18,0)),"") | D14: =IFERROR(INDEX(Materiales!$C$4:$C$18,MATCH($B14,Materiales!$A$4:$A$18,0)),"") | G14: =IF($B14="",0,$E14*SUMIF(Plan!$A$5:$A$24,$A14,Plan!E$5:E$24)) | H14: =IF($B14="",0,$E14*SUMIF(Plan!$A$5:$A$24,$A14,Plan!F$5:F$24)) | I14: =IF($B14="",0,$E14*SUMIF(Plan!$A$5:$A$24,$A14,Plan!G$5:G$24)) | J14: =IF($B14="",0,$E14*SUMIF(Plan!$A$5:$A$24,$A14,Plan!H$5:H$24)) | K14: =IF($B14="",0,$E14*SUMIF(Plan!$A$5:$A$24,$A14,Plan!I$5:I$24)) | L14: =IF($B14="",0,$E14*SUMIF(Plan!$A$5:$A$24,$A14,Plan!J$5:J$24)) | M14: =IF($B14="",0,$E14*SUMIF(Plan!$A$5:$A$24,$A14,Plan!K$5:K$24)) | N14: =IF($B14="",0,$E14*SUMIF(Plan!$A$5:$A$24,$A14,Plan!L$5:L$24))
C15: =IFERROR(INDEX(Materiales!$B$4:$B$18,MATCH($B15,Materiales!$A$4:$A$18,0)),"") | D15: =IFERROR(INDEX(Materiales!$C$4:$C$18,MATCH($B15,Materiales!$A$4:$A$18,0)),"") | G15: =IF($B15="",0,$E15*SUMIF(Plan!$A$5:$A$24,$A15,Plan!E$5:E$24)) | H15: =IF($B15="",0,$E15*SUMIF(Plan!$A$5:$A$24,$A15,Plan!F$5:F$24)) | I15: =IF($B15="",0,$E15*SUMIF(Plan!$A$5:$A$24,$A15,Plan!G$5:G$24)) | J15: =IF($B15="",0,$E15*SUMIF(Plan!$A$5:$A$24,$A15,Plan!H$5:H$24)) | K15: =IF($B15="",0,$E15*SUMIF(Plan!$A$5:$A$24,$A15,Plan!I$5:I$24)) | L15: =IF($B15="",0,$E15*SUMIF(Plan!$A$5:$A$24,$A15,Plan!J$5:J$24)) | M15: =IF($B15="",0,$E15*SUMIF(Plan!$A$5:$A$24,$A15,Plan!K$5:K$24)) | N15: =IF($B15="",0,$E15*SUMIF(Plan!$A$5:$A$24,$A15,Plan!L$5:L$24))
C16: =IFERROR(INDEX(Materiales!$B$4:$B$18,MATCH($B16,Materiales!$A$4:$A$18,0)),"") | D16: =IFERROR(INDEX(Materiales!$C$4:$C$18,MATCH($B16,Materiales!$A$4:$A$18,0)),"") | G16: =IF($B16="",0,$E16*SUMIF(Plan!$A$5:$A$24,$A16,Plan!E$5:E$24)) | H16: =IF($B16="",0,$E16*SUMIF(Plan!$A$5:$A$24,$A16,Plan!F$5:F$24)) | I16: =IF($B16="",0,$E16*SUMIF(Plan!$A$5:$A$24,$A16,Plan!G$5:G$24)) | J16: =IF($B16="",0,$E16*SUMIF(Plan!$A$5:$A$24,$A16,Plan!H$5:H$24)) | K16: =IF($B16="",0,$E16*SUMIF(Plan!$A$5:$A$24,$A16,Plan!I$5:I$24)) | L16: =IF($B16="",0,$E16*SUMIF(Plan!$A$5:$A$24,$A16,Plan!J$5:J$24)) | M16: =IF($B16="",0,$E16*SUMIF(Plan!$A$5:$A$24,$A16,Plan!K$5:K$24)) | N16: =IF($B16="",0,$E16*SUMIF(Plan!$A$5:$A$24,$A16,Plan!L$5:L$24))
C17: =IFERROR(INDEX(Materiales!$B$4:$B$18,MATCH($B17,Materiales!$A$4:$A$18,0)),"") | D17: =IFERROR(INDEX(Materiales!$C$4:$C$18,MATCH($B17,Materiales!$A$4:$A$18,0)),"") | G17: =IF($B17="",0,$E17*SUMIF(Plan!$A$5:$A$24,$A17,Plan!E$5:E$24)) | H17: =IF($B17="",0,$E17*SUMIF(Plan!$A$5:$A$24,$A17,Plan!F$5:F$24)) | I17: =IF($B17="",0,$E17*SUMIF(Plan!$A$5:$A$24,$A17,Plan!G$5:G$24)) | J17: =IF($B17="",0,$E17*SUMIF(Plan!$A$5:$A$24,$A17,Plan!H$5:H$24)) | K17: =IF($B17="",0,$E17*SUMIF(Plan!$A$5:$A$24,$A17,Plan!I$5:I$24)) | L17: =IF($B17="",0,$E17*SUMIF(Plan!$A$5:$A$24,$A17,Plan!J$5:J$24)) | M17: =IF($B17="",0,$E17*SUMIF(Plan!$A$5:$A$24,$A17,Plan!K$5:K$24)) | N17: =IF($B17="",0,$E17*SUMIF(Plan!$A$5:$A$24,$A17,Plan!L$5:L$24))
C18: =IFERROR(INDEX(Materiales!$B$4:$B$18,MATCH($B18,Materiales!$A$4:$A$18,0)),"") | D18: =IFERROR(INDEX(Materiales!$C$4:$C$18,MATCH($B18,Materiales!$A$4:$A$18,0)),"") | G18: =IF($B18="",0,$E18*SUMIF(Plan!$A$5:$A$24,$A18,Plan!E$5:E$24)) | H18: =IF($B18="",0,$E18*SUMIF(Plan!$A$5:$A$24,$A18,Plan!F$5:F$24)) | I18: =IF($B18="",0,$E18*SUMIF(Plan!$A$5:$A$24,$A18,Plan!G$5:G$24)) | J18: =IF($B18="",0,$E18*SUMIF(Plan!$A$5:$A$24,$A18,Plan!H$5:H$24)) | K18: =IF($B18="",0,$E18*SUMIF(Plan!$A$5:$A$24,$A18,Plan!I$5:I$24)) | L18: =IF($B18="",0,$E18*SUMIF(Plan!$A$5:$A$24,$A18,Plan!J$5:J$24)) | M18: =IF($B18="",0,$E18*SUMIF(Plan!$A$5:$A$24,$A18,Plan!K$5:K$24)) | N18: =IF($B18="",0,$E18*SUMIF(Plan!$A$5:$A$24,$A18,Plan!L$5:L$24))
... C103: =IFERROR(INDEX(Materiales!$B$4:$B$18,MATCH($B103,Materiales!$A$4:$A$18,0)),"") | D103: =IFERROR(INDEX(Materiales!$C$4:$C$18,MATCH($B103,Materiales!$A$4:$A$18,0)),"") | G103: =IF($B103="",0,$E103*SUMIF(Plan!$A$5:$A$24,$A103,Plan!E$5:E$24)) | H103: =IF($B103="",0,$E103*SUMIF(Plan!$A$5:$A$24,$A103,Plan!F$5:F$24)) | I103: =IF($B103="",0,$E103*SUMIF(Plan!$A$5:$A$24,$A103,Plan!G$5:G$24)) | J103: =IF($B103="",0,$E103*SUMIF(Plan!$A$5:$A$24,$A103,Plan!H$5:H$24)) | K103: =IF($B103="",0,$E103*SUMIF(Plan!$A$5:$A$24,$A103,Plan!I$5:I$24)) | L103: =IF($B103="",0,$E103*SUMIF(Plan!$A$5:$A$24,$A103,Plan!J$5:J$24)) | M103: =IF($B103="",0,$E103*SUMIF(Plan!$A$5:$A$24,$A103,Plan!K$5:K$24)) | N103: =IF($B103="",0,$E103*SUMIF(Plan!$A$5:$A$24,$A103,Plan!L$5:L$24))

Sheet Inventario
A1: PASO 4 — Stock actual y ordenes ya emitidas (en transito)
A2: Stock que HOY tienes, y las cantidades de ordenes ya emitidas puestas en la semana en que llegaran. Puedes repetir un codigo en varios renglones (una linea por orden de compra).
E3: =Plan!E$3 | F3: =Plan!F$3 | G3: =Plan!G$3 | H3: =Plan!H$3 | I3: =Plan!I$3 | J3: =Plan!J$3 | K3: =Plan!K$3 | L3: =Plan!L$3
A4: Codigo | B4: Material (auto) | C4: Stock actual | D4: N° OC / Proveedor | E4: Sem 1 | F4: Sem 2 | G4: Sem 3 | H4: Sem 4 | I4: Sem 5 | J4: Sem 6 | K4: Sem 7 | L4: Sem 8
A5: SOS-CIM-001 | B5: =IFERROR(INDEX(Materiales!$B$4:$B$18,MATCH($A5,Materiales!$A$4:$A$18,0)),"") | C5: 4 | D5: sin OC emitida | E5: 0 | F5: 0 | G5: 0 | H5: 0 | I5: 0 | J5: 0 | K5: 0 | L5: 0
A6: SOS-MAL-001 | B6: =IFERROR(INDEX(Materiales!$B$4:$B$18,MATCH($A6,Materiales!$A$4:$A$18,0)),"") | C6: 10 | D6: OC-2211 (en transito) | E6: 0 | F6: 20 | G6: 0 | H6: 0 | I6: 0 | J6: 0 | K6: 0 | L6: 0
A7: SOS-PER-001 | B7: =IFERROR(INDEX(Materiales!$B$4:$B$18,MATCH($A7,Materiales!$A$4:$A$18,0)),"") | C7: 150 | D7: OC-2212 (en transito) | E7: 0 | F7: 200 | G7: 0 | H7: 0 | I7: 0 | J7: 0 | K7: 0 | L7: 0
B8: =IFERROR(INDEX(Materiales!$B$4:$B$18,MATCH($A8,Materiales!$A$4:$A$18,0)),"")
B9: =IFERROR(INDEX(Materiales!$B$4:$B$18,MATCH($A9,Materiales!$A$4:$A$18,0)),"")
B10: =IFERROR(INDEX(Materiales!$B$4:$B$18,MATCH($A10,Materiales!$A$4:$A$18,0)),"")
B11: =IFERROR(INDEX(Materiales!$B$4:$B$18,MATCH($A11,Materiales!$A$4:$A$18,0)),"")
B12: =IFERROR(INDEX(Materiales!$B$4:$B$18,MATCH($A12,Materiales!$A$4:$A$18,0)),"")
B13: =IFERROR(INDEX(Materiales!$B$4:$B$18,MATCH($A13,Materiales!$A$4:$A$18,0)),"")
B14: =IFERROR(INDEX(Materiales!$B$4:$B$18,MATCH($A14,Materiales!$A$4:$A$18,0)),"")
B15: =IFERROR(INDEX(Materiales!$B$4:$B$18,MATCH($A15,Materiales!$A$4:$A$18,0)),"")
B16: =IFERROR(INDEX(Materiales!$B$4:$B$18,MATCH($A16,Materiales!$A$4:$A$18,0)),"")
B17: =IFERROR(INDEX(Materiales!$B$4:$B$18,MATCH($A17,Materiales!$A$4:$A$18,0)),"")
B18: =IFERROR(INDEX(Materiales!$B$4:$B$18,MATCH($A18,Materiales!$A$4:$A$18,0)),"")
B19: =IFERROR(INDEX(Materiales!$B$4:$B$18,MATCH($A19,Materiales!$A$4:$A$18,0)),"")
... B29: =IFERROR(INDEX(Materiales!$B$4:$B$18,MATCH($A29,Materiales!$A$4:$A$18,0)),"")

Sheet MRP
A1: CALCULO MRP — no escribas en esta hoja
A2: Todo se calcula desde Materiales, Plan, Consumo e Inventario. Lee el renglon verde: es la semana en que debes pedir.
E3: =Plan!E$3 | F3: =Plan!F$3 | G3: =Plan!G$3 | H3: =Plan!H$3 | I3: =Plan!I$3 | J3: =Plan!J$3 | K3: =Plan!K$3 | L3: =Plan!L$3
A4: Codigo | B4: Material | C4: Concepto | D4: Inicial / hoy | E4: Sem 1 | F4: Sem 2 | G4: Sem 3 | H4: Sem 4 | I4: Sem 5 | J4: Sem 6 | K4: Sem 7 | L4: Sem 8 | M4: Alerta
A5: =IF(Materiales!$A$4="","",Materiales!$A$4) | B5: =IF(Materiales!$B$4="","",Materiales!$B$4) | C5: Necesidad bruta | E5: =ROUND(SUMIF(Consumo!$B$4:$B$103,$A5,Consumo!G$4:G$103),4) | F5: =ROUND(SUMIF(Consumo!$B$4:$B$103,$A5,Consumo!H$4:H$103),4) | G5: =ROUND(SUMIF(Consumo!$B$4:$B$103,$A5,Consumo!I$4:I$103),4) | H5: =ROUND(SUMIF(Consumo!$B$4:$B$103,$A5,Consumo!J$4:J$103),4) | I5: =ROUND(SUMIF(Consumo!$B$4:$B$103,$A5,Consumo!K$4:K$103),4) | J5: =ROUND(SUMIF(Consumo!$B$4:$B$103,$A5,Consumo!L$4:L$103),4) | K5: =ROUND(SUMIF(Consumo!$B$4:$B$103,$A5,Consumo!M$4:M$103),4) | L5: =ROUND(SUMIF(Consumo!$B$4:$B$103,$A5,Consumo!N$4:N$103),4)
C6: Recepciones programadas (ya pedido) | E6: =SUMIF(Inventario!$A$5:$A$29,$A5,Inventario!E$5:E$29) | F6: =SUMIF(Inventario!$A$5:$A$29,$A5,Inventario!F$5:F$29) | G6: =SUMIF(Inventario!$A$5:$A$29,$A5,Inventario!G$5:G$29) | H6: =SUMIF(Inventario!$A$5:$A$29,$A5,Inventario!H$5:H$29) | I6: =SUMIF(Inventario!$A$5:$A$29,$A5,Inventario!I$5:I$29) | J6: =SUMIF(Inventario!$A$5:$A$29,$A5,Inventario!J$5:J$29) | K6: =SUMIF(Inventario!$A$5:$A$29,$A5,Inventario!K$5:K$29) | L6: =SUMIF(Inventario!$A$5:$A$29,$A5,Inventario!L$5:L$29)
C7: Stock proyectado disponible | D7: =SUMIF(Inventario!$A$5:$A$29,$A5,Inventario!$C$5:$C$29) | E7: =D7+E6+E9-E5 | F7: =E7+F6+F9-F5 | G7: =F7+G6+G9-G5 | H7: =G7+H6+H9-H5 | I7: =H7+I6+I9-I5 | J7: =I7+J6+J9-J5 | K7: =J7+K6+K9-K5 | L7: =K7+L6+L9-L5
C8: Necesidad neta | E8: =MAX(0,ROUND(E5+Materiales!$H$4-D7-E6,4)) | F8: =MAX(0,ROUND(F5+Materiales!$H$4-E7-F6,4)) | G8: =MAX(0,ROUND(G5+Materiales!$H$4-F7-G6,4)) | H8: =MAX(0,ROUND(H5+Materiales!$H$4-G7-H6,4)) | I8: =MAX(0,ROUND(I5+Materiales!$H$4-H7-I6,4)) | J8: =MAX(0,ROUND(J5+Materiales!$H$4-I7-J6,4)) | K8: =MAX(0,ROUND(K5+Materiales!$H$4-J7-K6,4)) | L8: =MAX(0,ROUND(L5+Materiales!$H$4-K7-L6,4))
C9: Recepcion de orden planificada | E9: =IF(E8<=0,0,IF(Materiales!$G$4<=0,E8,ROUNDUP(E8/Materiales!$G$4,0)*Materiales!$G$4)) | F9: =IF(F8<=0,0,IF(Materiales!$G$4<=0,F8,ROUNDUP(F8/Materiales!$G$4,0)*Materiales!$G$4)) | G9: =IF(G8<=0,0,IF(Materiales!$G$4<=0,G8,ROUNDUP(G8/Materiales!$G$4,0)*Materiales!$G$4)) | H9: =IF(H8<=0,0,IF(Materiales!$G$4<=0,H8,ROUNDUP(H8/Materiales!$G$4,0)*Materiales!$G$4)) | I9: =IF(I8<=0,0,IF(Materiales!$G$4<=0,I8,ROUNDUP(I8/Materiales!$G$4,0)*Materiales!$G$4)) | J9: =IF(J8<=0,0,IF(Materiales!$G$4<=0,J8,ROUNDUP(J8/Materiales!$G$4,0)*Materiales!$G$4)) | K9: =IF(K8<=0,0,IF(Materiales!$G$4<=0,K8,ROUNDUP(K8/Materiales!$G$4,0)*Materiales!$G$4)) | L9: =IF(L8<=0,0,IF(Materiales!$G$4<=0,L8,ROUNDUP(L8/Materiales!$G$4,0)*Materiales!$G$4))
C10: LANZAMIENTO DE ORDEN — pedir esta semana | E10: =IF(1+Materiales!$F$4>8,0,INDEX($E$9:$L$9,1,1+Materiales!$F$4)) | F10: =IF(2+Materiales!$F$4>8,0,INDEX($E$9:$L$9,1,2+Materiales!$F$4)) | G10: =IF(3+Materiales!$F$4>8,0,INDEX($E$9:$L$9,1,3+Materiales!$F$4)) | H10: =IF(4+Materiales!$F$4>8,0,INDEX($E$9:$L$9,1,4+Materiales!$F$4)) | I10: =IF(5+Materiales!$F$4>8,0,INDEX($E$9:$L$9,1,5+Materiales!$F$4)) | J10: =IF(6+Materiales!$F$4>8,0,INDEX($E$9:$L$9,1,6+Materiales!$F$4)) | K10: =IF(7+Materiales!$F$4>8,0,INDEX($E$9:$L$9,1,7+Materiales!$F$4)) | L10: =IF(8+Materiales!$F$4>8,0,INDEX($E$9:$L$9,1,8+Materiales!$F$4)) | M10: =IF($A5="","",IF(SUMPRODUCT((COLUMN($E$9:$L$9)-4<=Materiales!$F$4)*$E$9:$L$9)>0,"PEDIR YA (atrasado)","OK"))
A12: =IF(Materiales!$A$5="","",Materiales!$A$5) | B12: =IF(Materiales!$B$5="","",Materiales!$B$5) | C12: Necesidad bruta | E12: =ROUND(SUMIF(Consumo!$B$4:$B$103,$A12,Consumo!G$4:G$103),4) | F12: =ROUND(SUMIF(Consumo!$B$4:$B$103,$A12,Consumo!H$4:H$103),4) | G12: =ROUND(SUMIF(Consumo!$B$4:$B$103,$A12,Consumo!I$4:I$103),4) | H12: =ROUND(SUMIF(Consumo!$B$4:$B$103,$A12,Consumo!J$4:J$103),4) | I12: =ROUND(SUMIF(Consumo!$B$4:$B$103,$A12,Consumo!K$4:K$103),4) | J12: =ROUND(SUMIF(Consumo!$B$4:$B$103,$A12,Consumo!L$4:L$103),4) | K12: =ROUND(SUMIF(Consumo!$B$4:$B$103,$A12,Consumo!M$4:M$103),4) | L12: =ROUND(SUMIF(Consumo!$B$4:$B$103,$A12,Consumo!N$4:N$103),4)
C13: Recepciones programadas (ya pedido) | E13: =SUMIF(Inventario!$A$5:$A$29,$A12,Inventario!E$5:E$29) | F13: =SUMIF(Inventario!$A$5:$A$29,$A12,Inventario!F$5:F$29) | G13: =SUMIF(Inventario!$A$5:$A$29,$A12,Inventario!G$5:G$29) | H13: =SUMIF(Inventario!$A$5:$A$29,$A12,Inventario!H$5:H$29) | I13: =SUMIF(Inventario!$A$5:$A$29,$A12,Inventario!I$5:I$29) | J13: =SUMIF(Inventario!$A$5:$A$29,$A12,Inventario!J$5:J$29) | K13: =SUMIF(Inventario!$A$5:$A$29,$A12,Inventario!K$5:K$29) | L13: =SUMIF(Inventario!$A$5:$A$29,$A12,Inventario!L$5:L$29)
C14: Stock proyectado disponible | D14: =SUMIF(Inventario!$A$5:$A$29,$A12,Inventario!$C$5:$C$29) | E14: =D14+E13+E16-E12 | F14: =E14+F13+F16-F12 | G14: =F14+G13+G16-G12 | H14: =G14+H13+H16-H12 | I14: =H14+I13+I16-I12 | J14: =I14+J13+J16-J12 | K14: =J14+K13+K16-K12 | L14: =K14+L13+L16-L12
C15: Necesidad neta | E15: =MAX(0,ROUND(E12+Materiales!$H$5-D14-E13,4)) | F15: =MAX(0,ROUND(F12+Materiales!$H$5-E14-F13,4)) | G15: =MAX(0,ROUND(G12+Materiales!$H$5-F14-G13,4)) | H15: =MAX(0,ROUND(H12+Materiales!$H$5-G14-H13,4)) | I15: =MAX(0,ROUND(I12+Materiales!$H$5-H14-I13,4)) | J15: =MAX(0,ROUND(J12+Materiales!$H$5-I14-J13,4)) | K15: =MAX(0,ROUND(K12+Materiales!$H$5-J14-K13,4)) | L15: =MAX(0,ROUND(L12+Materiales!$H$5-K14-L13,4))
C16: Recepcion de orden planificada | E16: =IF(E15<=0,0,IF(Materiales!$G$5<=0,E15,ROUNDUP(E15/Materiales!$G$5,0)*Materiales!$G$5)) | F16: =IF(F15<=0,0,IF(Materiales!$G$5<=0,F15,ROUNDUP(F15/Materiales!$G$5,0)*Materiales!$G$5)) | G16: =IF(G15<=0,0,IF(Materiales!$G$5<=0,G15,ROUNDUP(G15/Materiales!$G$5,0)*Materiales!$G$5)) | H16: =IF(H15<=0,0,IF(Materiales!$G$5<=0,H15,ROUNDUP(H15/Materiales!$G$5,0)*Materiales!$G$5)) | I16: =IF(I15<=0,0,IF(Materiales!$G$5<=0,I15,ROUNDUP(I15/Materiales!$G$5,0)*Materiales!$G$5)) | J16: =IF(J15<=0,0,IF(Materiales!$G$5<=0,J15,ROUNDUP(J15/Materiales!$G$5,0)*Materiales!$G$5)) | K16: =IF(K15<=0,0,IF(Materiales!$G$5<=0,K15,ROUNDUP(K15/Materiales!$G$5,0)*Materiales!$G$5)) | L16: =IF(L15<=0,0,IF(Materiales!$G$5<=0,L15,ROUNDUP(L15/Materiales!$G$5,0)*Materiales!$G$5))
C17: LANZAMIENTO DE ORDEN — pedir esta semana | E17: =IF(1+Materiales!$F$5>8,0,INDEX($E$16:$L$16,1,1+Materiales!$F$5)) | F17: =IF(2+Materiales!$F$5>8,0,INDEX($E$16:$L$16,1,2+Materiales!$F$5)) | G17: =IF(3+Materiales!$F$5>8,0,INDEX($E$16:$L$16,1,3+Materiales!$F$5)) | H17: =IF(4+Materiales!$F$5>8,0,INDEX($E$16:$L$16,1,4+Materiales!$F$5)) | I17: =IF(5+Materiales!$F$5>8,0,INDEX($E$16:$L$16,1,5+Materiales!$F$5)) | J17: =IF(6+Materiales!$F$5>8,0,INDEX($E$16:$L$16,1,6+Materiales!$F$5)) | K17: =IF(7+Materiales!$F$5>8,0,INDEX($E$16:$L$16,1,7+Materiales!$F$5)) | L17: =IF(8+Materiales!$F$5>8,0,INDEX($E$16:$L$16,1,8+Materiales!$F$5)) | M17: =IF($A12="","",IF(SUMPRODUCT((COLUMN($E$16:$L$16)-4<=Materiales!$F$5)*$E$16:$L$16)>0,"PEDIR YA (atrasado)","OK"))
A19: =IF(Materiales!$A$6="","",Materiales!$A$6) | B19: =IF(Materiales!$B$6="","",Materiales!$B$6) | C19: Necesidad bruta | E19: =ROUND(SUMIF(Consumo!$B$4:$B$103,$A19,Consumo!G$4:G$103),4) | F19: =ROUND(SUMIF(Consumo!$B$4:$B$103,$A19,Consumo!H$4:H$103),4) | G19: =ROUND(SUMIF(Consumo!$B$4:$B$103,$A19,Consumo!I$4:I$103),4) | H19: =ROUND(SUMIF(Consumo!$B$4:$B$103,$A19,Consumo!J$4:J$103),4) | I19: =ROUND(SUMIF(Consumo!$B$4:$B$103,$A19,Consumo!K$4:K$103),4) | J19: =ROUND(SUMIF(Consumo!$B$4:$B$103,$A19,Consumo!L$4:L$103),4) | K19: =ROUND(SUMIF(Consumo!$B$4:$B$103,$A19,Consumo!M$4:M$103),4) | L19: =ROUND(SUMIF(Consumo!$B$4:$B$103,$A19,Consumo!N$4:N$103),4)
C20: Recepciones programadas (ya pedido) | E20: =SUMIF(Inventario!$A$5:$A$29,$A19,Inventario!E$5:E$29) | F20: =SUMIF(Inventario!$A$5:$A$29,$A19,Inventario!F$5:F$29) | G20: =SUMIF(Inventario!$A$5:$A$29,$A19,Inventario!G$5:G$29) | H20: =SUMIF(Inventario!$A$5:$A$29,$A19,Inventario!H$5:H$29) | I20: =SUMIF(Inventario!$A$5:$A$29,$A19,Inventario!I$5:I$29) | J20: =SUMIF(Inventario!$A$5:$A$29,$A19,Inventario!J$5:J$29) | K20: =SUMIF(Inventario!$A$5:$A$29,$A19,Inventario!K$5:K$29) | L20: =SUMIF(Inventario!$A$5:$A$29,$A19,Inventario!L$5:L$29)
C21: Stock proyectado disponible | D21: =SUMIF(Inventario!$A$5:$A$29,$A19,Inventario!$C$5:$C$29) | E21: =D21+E20+E23-E19 | F21: =E21+F20+F23-F19 | G21: =F21+G20+G23-G19 | H21: =G21+H20+H23-H19 | I21: =H21+I20+I23-I19 | J21: =I21+J20+J23-J19 | K21: =J21+K20+K23-K19 | L21: =K21+L20+L23-L19
C22: Necesidad neta | E22: =MAX(0,ROUND(E19+Materiales!$H$6-D21-E20,4)) | F22: =MAX(0,ROUND(F19+Materiales!$H$6-E21-F20,4)) | G22: =MAX(0,ROUND(G19+Materiales!$H$6-F21-G20,4)) | H22: =MAX(0,ROUND(H19+Materiales!$H$6-G21-H20,4)) | I22: =MAX(0,ROUND(I19+Materiales!$H$6-H21-I20,4)) | J22: =MAX(0,ROUND(J19+Materiales!$H$6-I21-J20,4)) | K22: =MAX(0,ROUND(K19+Materiales!$H$6-J21-K20,4)) | L22: =MAX(0,ROUND(L19+Materiales!$H$6-K21-L20,4))
C23: Recepcion de orden planificada | E23: =IF(E22<=0,0,IF(Materiales!$G$6<=0,E22,ROUNDUP(E22/Materiales!$G$6,0)*Materiales!$G$6)) | F23: =IF(F22<=0,0,IF(Materiales!$G$6<=0,F22,ROUNDUP(F22/Materiales!$G$6,0)*Materiales!$G$6)) | G23: =IF(G22<=0,0,IF(Materiales!$G$6<=0,G22,ROUNDUP(G22/Materiales!$G$6,0)*Materiales!$G$6)) | H23: =IF(H22<=0,0,IF(Materiales!$G$6<=0,H22,ROUNDUP(H22/Materiales!$G$6,0)*Materiales!$G$6)) | I23: =IF(I22<=0,0,IF(Materiales!$G$6<=0,I22,ROUNDUP(I22/Materiales!$G$6,0)*Materiales!$G$6)) | J23: =IF(J22<=0,0,IF(Materiales!$G$6<=0,J22,ROUNDUP(J22/Materiales!$G$6,0)*Materiales!$G$6)) | K23: =IF(K22<=0,0,IF(Materiales!$G$6<=0,K22,ROUNDUP(K22/Materiales!$G$6,0)*Materiales!$G$6)) | L23: =IF(L22<=0,0,IF(Materiales!$G$6<=0,L22,ROUNDUP(L22/Materiales!$G$6,0)*Materiales!$G$6))
C24: LANZAMIENTO DE ORDEN — pedir esta semana | E24: =IF(1+Materiales!$F$6>8,0,INDEX($E$23:$L$23,1,1+Materiales!$F$6)) | F24: =IF(2+Materiales!$F$6>8,0,INDEX($E$23:$L$23,1,2+Materiales!$F$6)) | G24: =IF(3+Materiales!$F$6>8,0,INDEX($E$23:$L$23,1,3+Materiales!$F$6)) | H24: =IF(4+Materiales!$F$6>8,0,INDEX($E$23:$L$23,1,4+Materiales!$F$6)) | I24: =IF(5+Materiales!$F$6>8,0,INDEX($E$23:$L$23,1,5+Materiales!$F$6)) | J24: =IF(6+Materiales!$F$6>8,0,INDEX($E$23:$L$23,1,6+Materiales!$F$6)) | K24: =IF(7+Materiales!$F$6>8,0,INDEX($E$23:$L$23,1,7+Materiales!$F$6)) | L24: =IF(8+Materiales!$F$6>8,0,INDEX($E$23:$L$23,1,8+Materiales!$F$6)) | M24: =IF($A19="","",IF(SUMPRODUCT((COLUMN($E$23:$L$23)-4<=Materiales!$F$6)*$E$23:$L$23)>0,"PEDIR YA (atrasado)","OK"))
A26: =IF(Materiales!$A$7="","",Materiales!$A$7) | B26: =IF(Materiales!$B$7="","",Materiales!$B$7) | C26: Necesidad bruta | E26: =ROUND(SUMIF(Consumo!$B$4:$B$103,$A26,Consumo!G$4:G$103),4) | F26: =ROUND(SUMIF(Consumo!$B$4:$B$103,$A26,Consumo!H$4:H$103),4) | G26: =ROUND(SUMIF(Consumo!$B$4:$B$103,$A26,Consumo!I$4:I$103),4) | H26: =ROUND(SUMIF(Consumo!$B$4:$B$103,$A26,Consumo!J$4:J$103),4) | I26: =ROUND(SUMIF(Consumo!$B$4:$B$103,$A26,Consumo!K$4:K$103),4) | J26: =ROUND(SUMIF(Consumo!$B$4:$B$103,$A26,Consumo!L$4:L$103),4) | K26: =ROUND(SUMIF(Consumo!$B$4:$B$103,$A26,Consumo!M$4:M$103),4) | L26: =ROUND(SUMIF(Consumo!$B$4:$B$103,$A26,Consumo!N$4:N$103),4)
C27: Recepciones programadas (ya pedido) | E27: =SUMIF(Inventario!$A$5:$A$29,$A26,Inventario!E$5:E$29) | F27: =SUMIF(Inventario!$A$5:$A$29,$A26,Inventario!F$5:F$29) | G27: =SUMIF(Inventario!$A$5:$A$29,$A26,Inventario!G$5:G$29) | H27: =SUMIF(Inventario!$A$5:$A$29,$A26,Inventario!H$5:H$29) | I27: =SUMIF(Inventario!$A$5:$A$29,$A26,Inventario!I$5:I$29) | J27: =SUMIF(Inventario!$A$5:$A$29,$A26,Inventario!J$5:J$29) | K27: =SUMIF(Inventario!$A$5:$A$29,$A26,Inventario!K$5:K$29) | L27: =SUMIF(Inventario!$A$5:$A$29,$A26,Inventario!L$5:L$29)
C28: Stock proyectado disponible | D28: =SUMIF(Inventario!$A$5:$A$29,$A26,Inventario!$C$5:$C$29) | E28: =D28+E27+E30-E26 | F28: =E28+F27+F30-F26 | G28: =F28+G27+G30-G26 | H28: =G28+H27+H30-H26 | I28: =H28+I27+I30-I26 | J28: =I28+J27+J30-J26 | K28: =J28+K27+K30-K26 | L28: =K28+L27+L30-L26
C29: Necesidad neta | E29: =MAX(0,ROUND(E26+Materiales!$H$7-D28-E27,4)) | F29: =MAX(0,ROUND(F26+Materiales!$H$7-E28-F27,4)) | G29: =MAX(0,ROUND(G26+Materiales!$H$7-F28-G27,4)) | H29: =MAX(0,ROUND(H26+Materiales!$H$7-G28-H27,4)) | I29: =MAX(0,ROUND(I26+Materiales!$H$7-H28-I27,4)) | J29: =MAX(0,ROUND(J26+Materiales!$H$7-I28-J27,4)) | K29: =MAX(0,ROUND(K26+Materiales!$H$7-J28-K27,4)) | L29: =MAX(0,ROUND(L26+Materiales!$H$7-K28-L27,4))
C30: Recepcion de orden planificada | E30: =IF(E29<=0,0,IF(Materiales!$G$7<=0,E29,ROUNDUP(E29/Materiales!$G$7,0)*Materiales!$G$7)) | F30: =IF(F29<=0,0,IF(Materiales!$G$7<=0,F29,ROUNDUP(F29/Materiales!$G$7,0)*Materiales!$G$7)) | G30: =IF(G29<=0,0,IF(Materiales!$G$7<=0,G29,ROUNDUP(G29/Materiales!$G$7,0)*Materiales!$G$7)) | H30: =IF(H29<=0,0,IF(Materiales!$G$7<=0,H29,ROUNDUP(H29/Materiales!$G$7,0)*Materiales!$G$7)) | I30: =IF(I29<=0,0,IF(Materiales!$G$7<=0,I29,ROUNDUP(I29/Materiales!$G$7,0)*Materiales!$G$7)) | J30: =IF(J29<=0,0,IF(Materiales!$G$7<=0,J29,ROUNDUP(J29/Materiales!$G$7,0)*Materiales!$G$7)) | K30: =IF(K29<=0,0,IF(Materiales!$G$7<=0,K29,ROUNDUP(K29/Materiales!$G$7,0)*Materiales!$G$7)) | L30: =IF(L29<=0,0,IF(Materiales!$G$7<=0,L29,ROUNDUP(L29/Materiales!$G$7,0)*Materiales!$G$7))
C31: LANZAMIENTO DE ORDEN — pedir esta semana | E31: =IF(1+Materiales!$F$7>8,0,INDEX($E$30:$L$30,1,1+Materiales!$F$7)) | F31: =IF(2+Materiales!$F$7>8,0,INDEX($E$30:$L$30,1,2+Materiales!$F$7)) | G31: =IF(3+Materiales!$F$7>8,0,INDEX($E$30:$L$30,1,3+Materiales!$F$7)) | H31: =IF(4+Materiales!$F$7>8,0,INDEX($E$30:$L$30,1,4+Materiales!$F$7)) | I31: =IF(5+Materiales!$F$7>8,0,INDEX($E$30:$L$30,1,5+Materiales!$F$7)) | J31: =IF(6+Materiales!$F$7>8,0,INDEX($E$30:$L$30,1,6+Materiales!$F$7)) | K31: =IF(7+Materiales!$F$7>8,0,INDEX($E$30:$L$30,1,7+Materiales!$F$7)) | L31: =IF(8+Materiales!$F$7>8,0,INDEX($E$30:$L$30,1,8+Materiales!$F$7)) | M31: =IF($A26="","",IF(SUMPRODUCT((COLUMN($E$30:$L$30)-4<=Materiales!$F$7)*$E$30:$L$30)>0,"PEDIR YA (atrasado)","OK"))
A33: =IF(Materiales!$A$8="","",Materiales!$A$8) | B33: =IF(Materiales!$B$8="","",Materiales!$B$8) | C33: Necesidad bruta | E33: =ROUND(SUMIF(Consumo!$B$4:$B$103,$A33,Consumo!G$4:G$103),4) | F33: =ROUND(SUMIF(Consumo!$B$4:$B$103,$A33,Consumo!H$4:H$103),4) | G33: =ROUND(SUMIF(Consumo!$B$4:$B$103,$A33,Consumo!I$4:I$103),4) | H33: =ROUND(SUMIF(Consumo!$B$4:$B$103,$A33,Consumo!J$4:J$103),4) | I33: =ROUND(SUMIF(Consumo!$B$4:$B$103,$A33,Consumo!K$4:K$103),4) | J33: =ROUND(SUMIF(Consumo!$B$4:$B$103,$A33,Consumo!L$4:L$103),4) | K33: =ROUND(SUMIF(Consumo!$B$4:$B$103,$A33,Consumo!M$4:M$103),4) | L33: =ROUND(SUMIF(Consumo!$B$4:$B$103,$A33,Consumo!N$4:N$103),4)
C34: Recepciones programadas (ya pedido) | E34: =SUMIF(Inventario!$A$5:$A$29,$A33,Inventario!E$5:E$29) | F34: =SUMIF(Inventario!$A$5:$A$29,$A33,Inventario!F$5:F$29) | G34: =SUMIF(Inventario!$A$5:$A$29,$A33,Inventario!G$5:G$29) | H34: =SUMIF(Inventario!$A$5:$A$29,$A33,Inventario!H$5:H$29) | I34: =SUMIF(Inventario!$A$5:$A$29,$A33,Inventario!I$5:I$29) | J34: =SUMIF(Inventario!$A$5:$A$29,$A33,Inventario!J$5:J$29) | K34: =SUMIF(Inventario!$A$5:$A$29,$A33,Inventario!K$5:K$29) | L34: =SUMIF(Inventario!$A$5:$A$29,$A33,Inventario!L$5:L$29)
C35: Stock proyectado disponible | D35: =SUMIF(Inventario!$A$5:$A$29,$A33,Inventario!$C$5:$C$29) | E35: =D35+E34+E37-E33 | F35: =E35+F34+F37-F33 | G35: =F35+G34+G37-G33 | H35: =G35+H34+H37-H33 | I35: =H35+I34+I37-I33 | J35: =I35+J34+J37-J33 | K35: =J35+K34+K37-K33 | L35: =K35+L34+L37-L33
C36: Necesidad neta | E36: =MAX(0,ROUND(E33+Materiales!$H$8-D35-E34,4)) | F36: =MAX(0,ROUND(F33+Materiales!$H$8-E35-F34,4)) | G36: =MAX(0,ROUND(G33+Materiales!$H$8-F35-G34,4)) | H36: =MAX(0,ROUND(H33+Materiales!$H$8-G35-H34,4)) | I36: =MAX(0,ROUND(I33+Materiales!$H$8-H35-I34,4)) | J36: =MAX(0,ROUND(J33+Materiales!$H$8-I35-J34,4)) | K36: =MAX(0,ROUND(K33+Materiales!$H$8-J35-K34,4)) | L36: =MAX(0,ROUND(L33+Materiales!$H$8-K35-L34,4))
C37: Recepcion de orden planificada | E37: =IF(E36<=0,0,IF(Materiales!$G$8<=0,E36,ROUNDUP(E36/Materiales!$G$8,0)*Materiales!$G$8)) | F37: =IF(F36<=0,0,IF(Materiales!$G$8<=0,F36,ROUNDUP(F36/Materiales!$G$8,0)*Materiales!$G$8)) | G37: =IF(G36<=0,0,IF(Materiales!$G$8<=0,G36,ROUNDUP(G36/Materiales!$G$8,0)*Materiales!$G$8)) | H37: =IF(H36<=0,0,IF(Materiales!$G$8<=0,H36,ROUNDUP(H36/Materiales!$G$8,0)*Materiales!$G$8)) | I37: =IF(I36<=0,0,IF(Materiales!$G$8<=0,I36,ROUNDUP(I36/Materiales!$G$8,0)*Materiales!$G$8)) | J37: =IF(J36<=0,0,IF(Materiales!$G$8<=0,J36,ROUNDUP(J36/Materiales!$G$8,0)*Materiales!$G$8)) | K37: =IF(K36<=0,0,IF(Materiales!$G$8<=0,K36,ROUNDUP(K36/Materiales!$G$8,0)*Materiales!$G$8)) | L37: =IF(L36<=0,0,IF(Materiales!$G$8<=0,L36,ROUNDUP(L36/Materiales!$G$8,0)*Materiales!$G$8))
C38: LANZAMIENTO DE ORDEN — pedir esta semana | E38: =IF(1+Materiales!$F$8>8,0,INDEX($E$37:$L$37,1,1+Materiales!$F$8)) | F38: =IF(2+Materiales!$F$8>8,0,INDEX($E$37:$L$37,1,2+Materiales!$F$8)) | G38: =IF(3+Materiales!$F$8>8,0,INDEX($E$37:$L$37,1,3+Materiales!$F$8)) | H38: =IF(4+Materiales!$F$8>8,0,INDEX($E$37:$L$37,1,4+Materiales!$F$8)) | I38: =IF(5+Materiales!$F$8>8,0,INDEX($E$37:$L$37,1,5+Materiales!$F$8)) | J38: =IF(6+Materiales!$F$8>8,0,INDEX($E$37:$L$37,1,6+Materiales!$F$8)) | K38: =IF(7+Materiales!$F$8>8,0,INDEX($E$37:$L$37,1,7+Materiales!$F$8)) | L38: =IF(8+Materiales!$F$8>8,0,INDEX($E$37:$L$37,1,8+Materiales!$F$8)) | M38: =IF($A33="","",IF(SUMPRODUCT((COLUMN($E$37:$L$37)-4<=Materiales!$F$8)*$E$37:$L$37)>0,"PEDIR YA (atrasado)","OK"))
A40: =IF(Materiales!$A$9="","",Materiales!$A$9) | B40: =IF(Materiales!$B$9="","",Materiales!$B$9) | C40: Necesidad bruta | E40: =ROUND(SUMIF(Consumo!$B$4:$B$103,$A40,Consumo!G$4:G$103),4) | F40: =ROUND(SUMIF(Consumo!$B$4:$B$103,$A40,Consumo!H$4:H$103),4) | G40: =ROUND(SUMIF(Consumo!$B$4:$B$103,$A40,Consumo!I$4:I$103),4) | H40: =ROUND(SUMIF(Consumo!$B$4:$B$103,$A40,Consumo!J$4:J$103),4) | I40: =ROUND(SUMIF(Consumo!$B$4:$B$103,$A40,Consumo!K$4:K$103),4) | J40: =ROUND(SUMIF(Consumo!$B$4:$B$103,$A40,Consumo!L$4:L$103),4) | K40: =ROUND(SUMIF(Consumo!$B$4:$B$103,$A40,Consumo!M$4:M$103),4) | L40: =ROUND(SUMIF(Consumo!$B$4:$B$103,$A40,Consumo!N$4:N$103),4)
C41: Recepciones programadas (ya pedido) | E41: =SUMIF(Inventario!$A$5:$A$29,$A40,Inventario!E$5:E$29) | F41: =SUMIF(Inventario!$A$5:$A$29,$A40,Inventario!F$5:F$29) | G41: =SUMIF(Inventario!$A$5:$A$29,$A40,Inventario!G$5:G$29) | H41: =SUMIF(Inventario!$A$5:$A$29,$A40,Inventario!H$5:H$29) | I41: =SUMIF(Inventario!$A$5:$A$29,$A40,Inventario!I$5:I$29) | J41: =SUMIF(Inventario!$A$5:$A$29,$A40,Inventario!J$5:J$29) | K41: =SUMIF(Inventario!$A$5:$A$29,$A40,Inventario!K$5:K$29) | L41: =SUMIF(Inventario!$A$5:$A$29,$A40,Inventario!L$5:L$29)
C42: Stock proyectado disponible | D42: =SUMIF(Inventario!$A$5:$A$29,$A40,Inventario!$C$5:$C$29) | E42: =D42+E41+E44-E40 | F42: =E42+F41+F44-F40 | G42: =F42+G41+G44-G40 | H42: =G42+H41+H44-H40 | I42: =H42+I41+I44-I40 | J42: =I42+J41+J44-J40 | K42: =J42+K41+K44-K40 | L42: =K42+L41+L44-L40
C43: Necesidad neta | E43: =MAX(0,ROUND(E40+Materiales!$H$9-D42-E41,4)) | F43: =MAX(0,ROUND(F40+Materiales!$H$9-E42-F41,4)) | G43: =MAX(0,ROUND(G40+Materiales!$H$9-F42-G41,4)) | H43: =MAX(0,ROUND(H40+Materiales!$H$9-G42-H41,4)) | I43: =MAX(0,ROUND(I40+Materiales!$H$9-H42-I41,4)) | J43: =MAX(0,ROUND(J40+Materiales!$H$9-I42-J41,4)) | K43: =MAX(0,ROUND(K40+Materiales!$H$9-J42-K41,4)) | L43: =MAX(0,ROUND(L40+Materiales!$H$9-K42-L41,4))
C44: Recepcion de orden planificada | E44: =IF(E43<=0,0,IF(Materiales!$G$9<=0,E43,ROUNDUP(E43/Materiales!$G$9,0)*Materiales!$G$9)) | F44: =IF(F43<=0,0,IF(Materiales!$G$9<=0,F43,ROUNDUP(F43/Materiales!$G$9,0)*Materiales!$G$9)) | G44: =IF(G43<=0,0,IF(Materiales!$G$9<=0,G43,ROUNDUP(G43/Materiales!$G$9,0)*Materiales!$G$9)) | H44: =IF(H43<=0,0,IF(Materiales!$G$9<=0,H43,ROUNDUP(H43/Materiales!$G$9,0)*Materiales!$G$9)) | I44: =IF(I43<=0,0,IF(Materiales!$G$9<=0,I43,ROUNDUP(I43/Materiales!$G$9,0)*Materiales!$G$9)) | J44: =IF(J43<=0,0,IF(Materiales!$G$9<=0,J43,ROUNDUP(J43/Materiales!$G$9,0)*Materiales!$G$9)) | K44: =IF(K43<=0,0,IF(Materiales!$G$9<=0,K43,ROUNDUP(K43/Materiales!$G$9,0)*Materiales!$G$9)) | L44: =IF(L43<=0,0,IF(Materiales!$G$9<=0,L43,ROUNDUP(L43/Materiales!$G$9,0)*Materiales!$G$9))
C45: LANZAMIENTO DE ORDEN — pedir esta semana | E45: =IF(1+Materiales!$F$9>8,0,INDEX($E$44:$L$44,1,1+Materiales!$F$9)) | F45: =IF(2+Materiales!$F$9>8,0,INDEX($E$44:$L$44,1,2+Materiales!$F$9)) | G45: =IF(3+Materiales!$F$9>8,0,INDEX($E$44:$L$44,1,3+Materiales!$F$9)) | H45: =IF(4+Materiales!$F$9>8,0,INDEX($E$44:$L$44,1,4+Materiales!$F$9)) | I45: =IF(5+Materiales!$F$9>8,0,INDEX($E$44:$L$44,1,5+Materiales!$F$9)) | J45: =IF(6+Materiales!$F$9>8,0,INDEX($E$44:$L$44,1,6+Materiales!$F$9)) | K45: =IF(7+Materiales!$F$9>8,0,INDEX($E$44:$L$44,1,7+Materiales!$F$9)) | L45: =IF(8+Materiales!$F$9>8,0,INDEX($E$44:$L$44,1,8+Materiales!$F$9)) | M45: =IF($A40="","",IF(SUMPRODUCT((COLUMN($E$44:$L$44)-4<=Materiales!$F$9)*$E$44:$L$44)>0,"PEDIR YA (atrasado)","OK"))
...

Sheet Ordenes
A1: RESULTADO — Que pedir, cuanto y en que semana
A2: Resumen del renglon LANZAMIENTO DE ORDEN del MRP. Esta es la hoja que le pasas a Logistica.
E3: =Plan!E$3 | F3: =Plan!F$3 | G3: =Plan!G$3 | H3: =Plan!H$3 | I3: =Plan!I$3 | J3: =Plan!J$3 | K3: =Plan!K$3 | L3: =Plan!L$3
A4: Codigo | B4: Material | C4: Unidad | D4: Precio (S/) | E4: Sem 1 | F4: Sem 2 | G4: Sem 3 | H4: Sem 4 | I4: Sem 5 | J4: Sem 6 | K4: Sem 7 | L4: Sem 8 | M4: Total unidades | N4: Total S/
A5: =IF(Materiales!$A$4="","",Materiales!$A$4) | B5: =IF(Materiales!$B$4="","",Materiales!$B$4) | C5: =IF(Materiales!$C$4="","",Materiales!$C$4) | D5: =IF(Materiales!$D$4="","",Materiales!$D$4) | E5: =IF($A5="","",MRP!E10) | F5: =IF($A5="","",MRP!F10) | G5: =IF($A5="","",MRP!G10) | H5: =IF($A5="","",MRP!H10) | I5: =IF($A5="","",MRP!I10) | J5: =IF($A5="","",MRP!J10) | K5: =IF($A5="","",MRP!K10) | L5: =IF($A5="","",MRP!L10) | M5: =IF($A5="","",SUM(E5:L5)) | N5: =IF($A5="","",M5*D5)
A6: =IF(Materiales!$A$5="","",Materiales!$A$5) | B6: =IF(Materiales!$B$5="","",Materiales!$B$5) | C6: =IF(Materiales!$C$5="","",Materiales!$C$5) | D6: =IF(Materiales!$D$5="","",Materiales!$D$5) | E6: =IF($A6="","",MRP!E17) | F6: =IF($A6="","",MRP!F17) | G6: =IF($A6="","",MRP!G17) | H6: =IF($A6="","",MRP!H17) | I6: =IF($A6="","",MRP!I17) | J6: =IF($A6="","",MRP!J17) | K6: =IF($A6="","",MRP!K17) | L6: =IF($A6="","",MRP!L17) | M6: =IF($A6="","",SUM(E6:L6)) | N6: =IF($A6="","",M6*D6)
A7: =IF(Materiales!$A$6="","",Materiales!$A$6) | B7: =IF(Materiales!$B$6="","",Materiales!$B$6) | C7: =IF(Materiales!$C$6="","",Materiales!$C$6) | D7: =IF(Materiales!$D$6="","",Materiales!$D$6) | E7: =IF($A7="","",MRP!E24) | F7: =IF($A7="","",MRP!F24) | G7: =IF($A7="","",MRP!G24) | H7: =IF($A7="","",MRP!H24) | I7: =IF($A7="","",MRP!I24) | J7: =IF($A7="","",MRP!J24) | K7: =IF($A7="","",MRP!K24) | L7: =IF($A7="","",MRP!L24) | M7: =IF($A7="","",SUM(E7:L7)) | N7: =IF($A7="","",M7*D7)
A8: =IF(Materiales!$A$7="","",Materiales!$A$7) | B8: =IF(Materiales!$B$7="","",Materiales!$B$7) | C8: =IF(Materiales!$C$7="","",Materiales!$C$7) | D8: =IF(Materiales!$D$7="","",Materiales!$D$7) | E8: =IF($A8="","",MRP!E31) | F8: =IF($A8="","",MRP!F31) | G8: =IF($A8="","",MRP!G31) | H8: =IF($A8="","",MRP!H31) | I8: =IF($A8="","",MRP!I31) | J8: =IF($A8="","",MRP!J31) | K8: =IF($A8="","",MRP!K31) | L8: =IF($A8="","",MRP!L31) | M8: =IF($A8="","",SUM(E8:L8)) | N8: =IF($A8="","",M8*D8)
A9: =IF(Materiales!$A$8="","",Materiales!$A$8) | B9: =IF(Materiales!$B$8="","",Materiales!$B$8) | C9: =IF(Materiales!$C$8="","",Materiales!$C$8) | D9: =IF(Materiales!$D$8="","",Materiales!$D$8) | E9: =IF($A9="","",MRP!E38) | F9: =IF($A9="","",MRP!F38) | G9: =IF($A9="","",MRP!G38) | H9: =IF($A9="","",MRP!H38) | I9: =IF($A9="","",MRP!I38) | J9: =IF($A9="","",MRP!J38) | K9: =IF($A9="","",MRP!K38) | L9: =IF($A9="","",MRP!L38) | M9: =IF($A9="","",SUM(E9:L9)) | N9: =IF($A9="","",M9*D9)
A10: =IF(Materiales!$A$9="","",Materiales!$A$9) | B10: =IF(Materiales!$B$9="","",Materiales!$B$9) | C10: =IF(Materiales!$C$9="","",Materiales!$C$9) | D10: =IF(Materiales!$D$9="","",Materiales!$D$9) | E10: =IF($A10="","",MRP!E45) | F10: =IF($A10="","",MRP!F45) | G10: =IF($A10="","",MRP!G45) | H10: =IF($A10="","",MRP!H45) | I10: =IF($A10="","",MRP!I45) | J10: =IF($A10="","",MRP!J45) | K10: =IF($A10="","",MRP!K45) | L10: =IF($A10="","",MRP!L45) | M10: =IF($A10="","",SUM(E10:L10)) | N10: =IF($A10="","",M10*D10)
A11: =IF(Materiales!$A$10="","",Materiales!$A$10) | B11: =IF(Materiales!$B$10="","",Materiales!$B$10) | C11: =IF(Materiales!$C$10="","",Materiales!$C$10) | D11: =IF(Materiales!$D$10="","",Materiales!$D$10) | E11: =IF($A11="","",MRP!E52) | F11: =IF($A11="","",MRP!F52) | G11: =IF($A11="","",MRP!G52) | H11: =IF($A11="","",MRP!H52) | I11: =IF($A11="","",MRP!I52) | J11: =IF($A11="","",MRP!J52) | K11: =IF($A11="","",MRP!K52) | L11: =IF($A11="","",MRP!L52) | M11: =IF($A11="","",SUM(E11:L11)) | N11: =IF($A11="","",M11*D11)
A12: =IF(Materiales!$A$11="","",Materiales!$A$11) | B12: =IF(Materiales!$B$11="","",Materiales!$B$11) | C12: =IF(Materiales!$C$11="","",Materiales!$C$11) | D12: =IF(Materiales!$D$11="","",Materiales!$D$11) | E12: =IF($A12="","",MRP!E59) | F12: =IF($A12="","",MRP!F59) | G12: =IF($A12="","",MRP!G59) | H12: =IF($A12="","",MRP!H59) | I12: =IF($A12="","",MRP!I59) | J12: =IF($A12="","",MRP!J59) | K12: =IF($A12="","",MRP!K59) | L12: =IF($A12="","",MRP!L59) | M12: =IF($A12="","",SUM(E12:L12)) | N12: =IF($A12="","",M12*D12)
A13: =IF(Materiales!$A$12="","",Materiales!$A$12) | B13: =IF(Materiales!$B$12="","",Materiales!$B$12) | C13: =IF(Materiales!$C$12="","",Materiales!$C$12) | D13: =IF(Materiales!$D$12="","",Materiales!$D$12) | E13: =IF($A13="","",MRP!E66) | F13: =IF($A13="","",MRP!F66) | G13: =IF($A13="","",MRP!G66) | H13: =IF($A13="","",MRP!H66) | I13: =IF($A13="","",MRP!I66) | J13: =IF($A13="","",MRP!J66) | K13: =IF($A13="","",MRP!K66) | L13: =IF($A13="","",MRP!L66) | M13: =IF($A13="","",SUM(E13:L13)) | N13: =IF($A13="","",M13*D13)
A14: =IF(Materiales!$A$13="","",Materiales!$A$13) | B14: =IF(Materiales!$B$13="","",Materiales!$B$13) | C14: =IF(Materiales!$C$13="","",Materiales!$C$13) | D14: =IF(Materiales!$D$13="","",Materiales!$D$13) | E14: =IF($A14="","",MRP!E73) | F14: =IF($A14="","",MRP!F73) | G14: =IF($A14="","",MRP!G73) | H14: =IF($A14="","",MRP!H73) | I14: =IF($A14="","",MRP!I73) | J14: =IF($A14="","",MRP!J73) | K14: =IF($A14="","",MRP!K73) | L14: =IF($A14="","",MRP!L73) | M14: =IF($A14="","",SUM(E14:L14)) | N14: =IF($A14="","",M14*D14)
A15: =IF(Materiales!$A$14="","",Materiales!$A$14) | B15: =IF(Materiales!$B$14="","",Materiales!$B$14) | C15: =IF(Materiales!$C$14="","",Materiales!$C$14) | D15: =IF(Materiales!$D$14="","",Materiales!$D$14) | E15: =IF($A15="","",MRP!E80) | F15: =IF($A15="","",MRP!F80) | G15: =IF($A15="","",MRP!G80) | H15: =IF($A15="","",MRP!H80) | I15: =IF($A15="","",MRP!I80) | J15: =IF($A15="","",MRP!J80) | K15: =IF($A15="","",MRP!K80) | L15: =IF($A15="","",MRP!L80) | M15: =IF($A15="","",SUM(E15:L15)) | N15: =IF($A15="","",M15*D15)
A16: =IF(Materiales!$A$15="","",Materiales!$A$15) | B16: =IF(Materiales!$B$15="","",Materiales!$B$15) | C16: =IF(Materiales!$C$15="","",Materiales!$C$15) | D16: =IF(Materiales!$D$15="","",Materiales!$D$15) | E16: =IF($A16="","",MRP!E87) | F16: =IF($A16="","",MRP!F87) | G16: =IF($A16="","",MRP!G87) | H16: =IF($A16="","",MRP!H87) | I16: =IF($A16="","",MRP!I87) | J16: =IF($A16="","",MRP!J87) | K16: =IF($A16="","",MRP!K87) | L16: =IF($A16="","",MRP!L87) | M16: =IF($A16="","",SUM(E16:L16)) | N16: =IF($A16="","",M16*D16)
A17: =IF(Materiales!$A$16="","",Materiales!$A$16) | B17: =IF(Materiales!$B$16="","",Materiales!$B$16) | C17: =IF(Materiales!$C$16="","",Materiales!$C$16) | D17: =IF(Materiales!$D$16="","",Materiales!$D$16) | E17: =IF($A17="","",MRP!E94) | F17: =IF($A17="","",MRP!F94) | G17: =IF($A17="","",MRP!G94) | H17: =IF($A17="","",MRP!H94) | I17: =IF($A17="","",MRP!I94) | J17: =IF($A17="","",MRP!J94) | K17: =IF($A17="","",MRP!K94) | L17: =IF($A17="","",MRP!L94) | M17: =IF($A17="","",SUM(E17:L17)) | N17: =IF($A17="","",M17*D17)
A18: =IF(Materiales!$A$17="","",Materiales!$A$17) | B18: =IF(Materiales!$B$17="","",Materiales!$B$17) | C18: =IF(Materiales!$C$17="","",Materiales!$C$17) | D18: =IF(Materiales!$D$17="","",Materiales!$D$17) | E18: =IF($A18="","",MRP!E101) | F18: =IF($A18="","",MRP!F101) | G18: =IF($A18="","",MRP!G101) | H18: =IF($A18="","",MRP!H101) | I18: =IF($A18="","",MRP!I101) | J18: =IF($A18="","",MRP!J101) | K18: =IF($A18="","",MRP!K101) | L18: =IF($A18="","",MRP!L101) | M18: =IF($A18="","",SUM(E18:L18)) | N18: =IF($A18="","",M18*D18)
A19: =IF(Materiales!$A$18="","",Materiales!$A$18) | B19: =IF(Materiales!$B$18="","",Materiales!$B$18) | C19: =IF(Materiales!$C$18="","",Materiales!$C$18) | D19: =IF(Materiales!$D$18="","",Materiales!$D$18) | E19: =IF($A19="","",MRP!E108) | F19: =IF($A19="","",MRP!F108) | G19: =IF($A19="","",MRP!G108) | H19: =IF($A19="","",MRP!H108) | I19: =IF($A19="","",MRP!I108) | J19: =IF($A19="","",MRP!J108) | K19: =IF($A19="","",MRP!K108) | L19: =IF($A19="","",MRP!L108) | M19: =IF($A19="","",SUM(E19:L19)) | N19: =IF($A19="","",M19*D19)
A20: TOTAL A COMPRAR EN EL HORIZONTE | E20: =SUM(E5:E19) | F20: =SUM(F5:F19) | G20: =SUM(G5:G19) | H20: =SUM(H5:H19) | I20: =SUM(I5:I19) | J20: =SUM(J5:J19) | K20: =SUM(K5:K19) | L20: =SUM(L5:L19) | ... N20: =SUM(N5:N19)
