Workbook

Sheet GUIA
A1: MRP — Planificacion de Requerimientos de Materiales | ATMIN / MukiCloud
A2: Los 481 items del maestro (productos + explosivos) ya vienen cargados con codigo, unidad, almacen y precio. Llena solo las celdas amarillas.
B4: 1. Que responde un MRP
B6: QUE material pedir, CUANTO pedir y CUANDO lanzar el pedido para que llegue a tiempo.
B8: Necesidad neta = Necesidad bruta − Stock disponible − Ordenes en transito + Stock de seguridad
B9: Fecha de pedido = Semana en que se necesita − Lead time del proveedor
B11: 2. Orden de llenado
A13: Paso | B13: Pestaña | C13: Que llenas ahi | D13: Ya viene cargado | E13: Ojo con esto
A14: 1 | B14: Materiales | C14: Proveedor, lead time, lote de compra y stock de seguridad. El precio solo donde falte. | D14: Los 481 items del maestro: codigo, producto, unidad, almacen y precio. | E14: LEAD TIME en SEMANAS enteras. LOTE = multiplo de compra; en 0 se pide la cantidad exacta. Hay items del maestro sin precio: esos quedan en amarillo.
A15: 2 | B15: Plan | C15: Metros de avance por frente y semana, y la fecha de inicio de la Semana 1. | D15: Tus 6 frentes. | E15: Trabaja en multiplos de 1.5 m (un disparo) para que las semanas cierren en disparos enteros.
A16: 3 | B16: Consumo | C16: EL CORAZON DEL MRP: por cada frente, TODO lo que se consume para avanzar UN METRO. Perforacion, voladura, sostenimiento, ventilacion y servicios. | D16: Un bloque por frente con 30 renglones, y en Brenda y CRNE la lista de productos ya puesta para que solo escribas el consumo. | E16: Todo va POR METRO. Si tu dato es por disparo, dividelo entre 1.5. Saca los numeros del consumo real del Compresorista: consumo del mes / metros del mes.
A17: 4 | B17: Inventario | C17: El stock actual de cada item y las ordenes ya emitidas, en la semana en que llegaran. | D17: Los 481 codigos, listos para poner el stock al costado. | E17: Este maestro NO trae stock: hay que cargarlo. Sin stock, el MRP asume cero y pide de mas.
A18: — | B18: MRP | C18: NO SE LLENA. El calculo semana por semana, 6 renglones por item. | D18: Los 481 items. | E18: Renglon verde = la semana en que debes pedir. Stock proyectado en rojo = quiebre.
A19: — | B19: Ordenes | C19: NO SE LLENA. El resumen de compra para Logistica. | D19: — | E19: Filtra la columna Total a pedir para ver solo lo que hay que comprar.
B21: 3. Como sacar el consumo por metro (los tres casos)
B23: Dato por disparo | C23: Divide entre 1.5. Ej: 11 pernos por disparo -> 11/1.5 = 7.33 pernos por metro.
B24: Dato por avance | C24: Divide entre los metros que cubre. Ej: 1 malla cada 2 m -> 1/2 = 0.5 mallas por metro.
B25: Consumo historico | C25: Toma el consumo real de un mes y divide entre los metros de ese mes. Es el metodo mas confiable para brocas, barrenos y aceites.
B27: 4. Los 6 renglones de cada item en la hoja MRP
B29: Necesidad bruta | C29: Lo que el plan consume esa semana = metros del frente x consumo por metro.
B30: Recepciones programadas | C30: Lo que YA esta pedido y llega esa semana.
B31: Stock proyectado disponible | C31: Lo que quedara al cerrar la semana. En rojo = quiebre.
B32: Necesidad neta | C32: Lo que falta comprar, descontado el stock y lo que viene en camino.
B33: Recepcion de orden planificada | C33: La necesidad neta redondeada al lote. Lo que debe LLEGAR esa semana.
B34: LANZAMIENTO DE ORDEN | C34: La misma cantidad corrida hacia atras por el lead time. ES CUANDO DEBES PEDIR.
B36: 5. Leyenda de colores
C38: Dato del maestro: ya viene cargado
C39: Celda que TU llenas
C40: SUPUESTO mio — confirmalo
C41: Celda calculada: no la toques
C42: La orden que debes lanzar
C43: Rojo = quiebre de stock esa semana
B45: 6. Supuestos
B47: • Horizonte de 8 semanas. La Semana 1 arranca en la fecha de la hoja Plan (celda C3).
B48: • Moneda: Soles (S/). Un disparo = 1.5 m de avance.
B49: • Fuente: maestro_productos_20260823.xlsx — 481 productos y explosivos, con precio.
B50: • El maestro no trae stock ni lead times: esos campos son tuyos.
B51: • Cada hoja lleva una columna clave oculta que antepone # al codigo. Es para que Excel compare los codigos como texto y no los interprete como fecha o numero. No la borres.

Sheet Materiales
A1: PASO 1 — Maestro de items (481)
A2: Azul = del maestro. Amarillo = lo llenas tu. Usa el filtro de la fila 3 para ubicar un item.
A3: Codigo | B3: Producto | C3: Unidad | D3: Precio (S/) | E3: Proveedor | F3: Lead time (semanas) | G3: Lote de compra | H3: Stock de seguridad | I3: Almacen | J3: Notas | K3: clave
A4: 1 | B4: FRENO 7/8 HEXÁGONAL RNS53F-36A | C4: PZA | D4: 221.41 | I4: Mantenimiento | K4: =IF(A4="","","#"&A4)
A5: 2 | B5: PERNO SUJETADOR RNS53F-36TA | C5: PZA | D5: 149.31 | I5: Mantenimiento | K5: =IF(A5="","","#"&A5)
A6: 3 | B6: ANILLOS (2) RNORP-214B | C6: PZA | D6: 3.8 | I6: Mantenimiento | K6: =IF(A6="","","#"&A6)
A7: 4 | B7: TUERCA DEL FRENO (2) RNS53F-36N | C7: PZA | D7: 20.48 | I7: Mantenimiento | K7: =IF(A7="","","#"&A7)
A8: 5 | B8: PARTE DELANTERA (TROMPA) RNS58F-17FC | C8: PZA | D8: 2208 | I8: Mantenimiento | K8: =IF(A8="","","#"&A8)
A9: 6 | B9: PERNO PASADOR RNS58F-36K | C9: PZA | D9: 18.53 | I9: Mantenimiento | K9: =IF(A9="","","#"&A9)
A10: 7 | B10: TUERCA TORNILLO LATERAL RNS58-3N | C10: PZA | D10: 52.13 | I10: Mantenimiento | K10: =IF(A10="","","#"&A10)
A11: 8 | B11: ARANDELA (2) RND73-3S | C11: PZA | D11: 13.91 | I11: Mantenimiento | K11: =IF(A11="","","#"&A11)
A12: 9 | B12: PERNO GUÍA RNS53F-36P | C12: PZA | D12: 45.29 | I12: Mantenimiento | K12: =IF(A12="","","#"&A12)
A13: 10 | B13: RESORTE SUJETADOR RNS58F-36N | C13: PZA | D13: 24.15 | I13: Mantenimiento | K13: =IF(A13="","","#"&A13)
A14: 11 | B14: ANILLO RNORP-210B | C14: PZA | D14: 3.8 | I14: Mantenimiento | K14: =IF(A14="","","#"&A14)
A15: 12 | B15: CANDADO RNS58F-36RA | C15: PZA | D15: 98.47 | I15: Mantenimiento | K15: =IF(A15="","","#"&A15)
... A19: 16 | B19: TUERCA CHUCK RNS63F-7N | C19: PZA | D19: 185.36 | I19: Mantenimiento | K19: =IF(A19="","","#"&A19)
A20: 17 | B20: PARTE INTERMEDIA RNS83F-1B | C20: PZA | I20: Mantenimiento | K20: =IF(A20="","","#"&A20)
A21: 18 | B21: BUJE BRONCE RNS53F-1L | C21: PZA | D21: 171.59 | I21: Mantenimiento | K21: =IF(A21="","","#"&A21)
A22: 19 | B22: PISTON RNS83F-9A | C22: PZA | D22: 499.31 | I22: Mantenimiento | K22: =IF(A22="","","#"&A22)
A23: 20 | B23: TUERCA RIFLE RNS83F-25-28 | C23: PZA | D23: 154.9 | I23: Mantenimiento | K23: =IF(A23="","","#"&A23)
A24: 21 | B24: CILINDRO RNS83F-1T | C24: PZA | I24: Mantenimiento | K24: =IF(A24="","","#"&A24)
A25: 22 | B25: EMPAQUE TAPON (2) RNS83F-715H | C25: PZA | D25: 28.3 | I25: Mantenimiento | K25: =IF(A25="","","#"&A25)
A26: 23 | B26: TAPA DE VÁLVULA RNS83F-15B | C26: PZA | D26: 413.65 | I26: Mantenimiento | K26: =IF(A26="","","#"&A26)
A27: 24 | B27: VALVULA AUTOMATICA RNS83F-16 | C27: PZA | D27: 270.5 | I27: Mantenimiento | K27: =IF(A27="","","#"&A27)
A28: 25 | B28: CAJA DE VÁLVULA RNS83F-15 | C28: PZA | I28: Mantenimiento | K28: =IF(A28="","","#"&A28)
A29: 26 | B29: PERNO DE CAJA VÁLVULA RNS83F-15D | C29: PZA | D29: 10.06 | I29: Mantenimiento | K29: =IF(A29="","","#"&A29)
A30: 27 | B30: BARRA DE ROTACIÓN RNS83F-26-28 | C30: PZA | D30: 412.01 | I30: Mantenimiento | K30: =IF(A30="","","#"&A30)
A31: 28 | B31: RESORTE ALETA (4) RN711C | C31: PZA | D31: 5.17 | I31: Mantenimiento | K31: =IF(A31="","","#"&A31)
A32: 29 | B32: PERNO ALETA (4) RN711B | C32: PZA | D32: 8.01 | I32: Mantenimiento | K32: =IF(A32="","","#"&A32)
A33: 30 | B33: ALETA RNR91-11A | C33: PZA | D33: 21.34 | I33: Mantenimiento | K33: =IF(A33="","","#"&A33)
A34: 31 | B34: TRINQUETE RNS83F-3335 | C34: PZA | D34: 286.91 | I34: Mantenimiento | K34: =IF(A34="","","#"&A34)
A35: 32 | B35: CABEZA RNS63F-2 | C35: PZA | I35: Mantenimiento | K35: =IF(A35="","","#"&A35)
A36: 33 | B36: CUÑA DE MANIJA RNS58F-12K | C36: PZA | D36: 9.27 | I36: Mantenimiento | K36: =IF(A36="","","#"&A36)
A37: 34 | B37: MANIJA DE CONTROL RNS58F-12E | C37: PZA | D37: 226.21 | I37: Mantenimiento | K37: =IF(A37="","","#"&A37)
A38: 35 | B38: RONDANA DE PRESIÓN RNWP-31 | C38: PZA | D38: 9.27 | I38: Mantenimiento | K38: =IF(A38="","","#"&A38)
A39: 36 | B39: TUERCA CABEZA RNS48F-12N | C39: PZA | D39: 30.9 | I39: Mantenimiento | K39: =IF(A39="","","#"&A39)
A40: 37 | B40: RESORTE RN72ES | C40: PZA | D40: 8.83 | I40: Mantenimiento | K40: =IF(A40="","","#"&A40)
A41: 38 | B41: RETÉN RN72A | C41: PZA | D41: 18.04 | I41: Mantenimiento | K41: =IF(A41="","","#"&A41)
A42: 39 | B42: EMPAQUE DEL TUBO DE AGUA RN729B | C42: PZA | D42: 24.72 | I42: Mantenimiento | K42: =IF(A42="","","#"&A42)
A43: 40 | B43: RONDANA GLÁNDULA DE AGUA RN1739A | C43: PZA | D43: 9.27 | I43: Mantenimiento | K43: =IF(A43="","","#"&A43)
...

Sheet Plan
A1: PASO 2 — Plan de avance por frente y semana (MPS)
A2: Metros de avance de cada frente en cada semana. Un disparo = 1.5 m.
A3: Fecha de inicio de la Semana 1 → | C3: 46265 | D3: (un lunes) | E3: =$C$3 | F3: =E3+7 | G3: =F3+7 | H3: =G3+7 | I3: =H3+7 | J3: =I3+7 | K3: =J3+7 | L3: =K3+7
A4: Frente | B4: Unidad de produccion | C4: Total horizonte | D4: Notas | E4: Sem 1 | F4: Sem 2 | G4: Sem 3 | H4: Sem 4 | I4: Sem 5 | J4: Sem 6 | K4: Sem 7 | L4: Sem 8 | M4: clave
A5: RA Brenda | B5: Metros de avance | C5: =IF($A5="","",SUM(E5:L5)) | M5: =IF(A5="","","#"&A5)
A6: CRNE (Cortada Noreste) | B6: Metros de avance | C6: =IF($A6="","",SUM(E6:L6)) | M6: =IF(A6="","","#"&A6)
A7: GLSE-2 | B7: Metros de avance | C7: =IF($A7="","",SUM(E7:L7)) | M7: =IF(A7="","","#"&A7)
A8: ESCM 4430 | B8: Metros de avance | C8: =IF($A8="","",SUM(E8:L8)) | M8: =IF(A8="","","#"&A8)
A9: ESCM 4410 | B9: Metros de avance | C9: =IF($A9="","",SUM(E9:L9)) | M9: =IF(A9="","","#"&A9)
A10: SN 5100 NW | B10: Metros de avance | C10: =IF($A10="","",SUM(E10:L10)) | M10: =IF(A10="","","#"&A10)
C11: =IF($A11="","",SUM(E11:L11)) | M11: =IF(A11="","","#"&A11)
C12: =IF($A12="","",SUM(E12:L12)) | M12: =IF(A12="","","#"&A12)
C13: =IF($A13="","",SUM(E13:L13)) | M13: =IF(A13="","","#"&A13)
C14: =IF($A14="","",SUM(E14:L14)) | M14: =IF(A14="","","#"&A14)
C15: =IF($A15="","",SUM(E15:L15)) | M15: =IF(A15="","","#"&A15)
C16: =IF($A16="","",SUM(E16:L16)) | M16: =IF(A16="","","#"&A16)
C17: =IF($A17="","",SUM(E17:L17)) | M17: =IF(A17="","","#"&A17)
C18: =IF($A18="","",SUM(E18:L18)) | M18: =IF(A18="","","#"&A18)
C19: =IF($A19="","",SUM(E19:L19)) | M19: =IF(A19="","","#"&A19)
C20: =IF($A20="","",SUM(E20:L20)) | M20: =IF(A20="","","#"&A20)
C21: =IF($A21="","",SUM(E21:L21)) | M21: =IF(A21="","","#"&A21)
C22: =IF($A22="","",SUM(E22:L22)) | M22: =IF(A22="","","#"&A22)
... C24: =IF($A24="","",SUM(E24:L24)) | M24: =IF(A24="","","#"&A24)

Sheet Consumo
A1: PASO 3 — Todo lo que consume UN METRO de avance, por frente (BOM)
A2: Un bloque por frente. Escribe el consumo POR METRO de cada producto. Si tu dato es por disparo, dividelo entre 1.5. Agrega los productos que falten en los renglones vacios.
A3: Frente | B3: Codigo | C3: Producto (auto) | D3: Unidad (auto) | E3: Consumo por METRO | F3: Etapa | G3: Notas / de donde sale el numero | H3: Demanda Sem 1 | I3: Demanda Sem 2 | J3: Demanda Sem 3 | K3: Demanda Sem 4 | L3: Demanda Sem 5 | M3: Demanda Sem 6 | N3: Demanda Sem 7 | O3: Demanda Sem 8 | P3: clave mat | Q3: clave frente
A4: FRENTE: RA Brenda — consumo por CADA metro de avance
A5: RA Brenda | B5: 1300000026 | C5: =IFERROR(INDEX(Materiales!$B$4:$B$484,MATCH("#"&$B5,Materiales!$K$4:$K$484,0)),"") | D5: =IFERROR(INDEX(Materiales!$C$4:$C$484,MATCH("#"&$B5,Materiales!$K$4:$K$484,0)),"") | F5: Perforacion | G5: Brocas por metro: (brocas gastadas al mes) / (metros del mes) | H5: =IF($B5="",0,$E5*SUMIF(Plan!$M$5:$M$24,"#"&$A5,Plan!E$5:E$24)) | I5: =IF($B5="",0,$E5*SUMIF(Plan!$M$5:$M$24,"#"&$A5,Plan!F$5:F$24)) | J5: =IF($B5="",0,$E5*SUMIF(Plan!$M$5:$M$24,"#"&$A5,Plan!G$5:G$24)) | K5: =IF($B5="",0,$E5*SUMIF(Plan!$M$5:$M$24,"#"&$A5,Plan!H$5:H$24)) | L5: =IF($B5="",0,$E5*SUMIF(Plan!$M$5:$M$24,"#"&$A5,Plan!I$5:I$24)) | M5: =IF($B5="",0,$E5*SUMIF(Plan!$M$5:$M$24,"#"&$A5,Plan!J$5:J$24)) | N5: =IF($B5="",0,$E5*SUMIF(Plan!$M$5:$M$24,"#"&$A5,Plan!K$5:K$24)) | O5: =IF($B5="",0,$E5*SUMIF(Plan!$M$5:$M$24,"#"&$A5,Plan!L$5:L$24)) | P5: =IF(B5="","","#"&B5) | Q5: =IF(A5="","","#"&A5)
A6: RA Brenda | B6: 1300000023 | C6: =IFERROR(INDEX(Materiales!$B$4:$B$484,MATCH("#"&$B6,Materiales!$K$4:$K$484,0)),"") | D6: =IFERROR(INDEX(Materiales!$C$4:$C$484,MATCH("#"&$B6,Materiales!$K$4:$K$484,0)),"") | F6: Perforacion | G6: Broca de 32 mm, si se usa | H6: =IF($B6="",0,$E6*SUMIF(Plan!$M$5:$M$24,"#"&$A6,Plan!E$5:E$24)) | I6: =IF($B6="",0,$E6*SUMIF(Plan!$M$5:$M$24,"#"&$A6,Plan!F$5:F$24)) | J6: =IF($B6="",0,$E6*SUMIF(Plan!$M$5:$M$24,"#"&$A6,Plan!G$5:G$24)) | K6: =IF($B6="",0,$E6*SUMIF(Plan!$M$5:$M$24,"#"&$A6,Plan!H$5:H$24)) | L6: =IF($B6="",0,$E6*SUMIF(Plan!$M$5:$M$24,"#"&$A6,Plan!I$5:I$24)) | M6: =IF($B6="",0,$E6*SUMIF(Plan!$M$5:$M$24,"#"&$A6,Plan!J$5:J$24)) | N6: =IF($B6="",0,$E6*SUMIF(Plan!$M$5:$M$24,"#"&$A6,Plan!K$5:K$24)) | O6: =IF($B6="",0,$E6*SUMIF(Plan!$M$5:$M$24,"#"&$A6,Plan!L$5:L$24)) | P6: =IF(B6="","","#"&B6) | Q6: =IF(A6="","","#"&A6)
A7: RA Brenda | B7: 1300000036 | C7: =IFERROR(INDEX(Materiales!$B$4:$B$484,MATCH("#"&$B7,Materiales!$K$4:$K$484,0)),"") | D7: =IFERROR(INDEX(Materiales!$C$4:$C$484,MATCH("#"&$B7,Materiales!$K$4:$K$484,0)),"") | F7: Perforacion | G7: Barreno / barra conica 6'. Vida util: metros perforados antes de descarte | H7: =IF($B7="",0,$E7*SUMIF(Plan!$M$5:$M$24,"#"&$A7,Plan!E$5:E$24)) | I7: =IF($B7="",0,$E7*SUMIF(Plan!$M$5:$M$24,"#"&$A7,Plan!F$5:F$24)) | J7: =IF($B7="",0,$E7*SUMIF(Plan!$M$5:$M$24,"#"&$A7,Plan!G$5:G$24)) | K7: =IF($B7="",0,$E7*SUMIF(Plan!$M$5:$M$24,"#"&$A7,Plan!H$5:H$24)) | L7: =IF($B7="",0,$E7*SUMIF(Plan!$M$5:$M$24,"#"&$A7,Plan!I$5:I$24)) | M7: =IF($B7="",0,$E7*SUMIF(Plan!$M$5:$M$24,"#"&$A7,Plan!J$5:J$24)) | N7: =IF($B7="",0,$E7*SUMIF(Plan!$M$5:$M$24,"#"&$A7,Plan!K$5:K$24)) | O7: =IF($B7="",0,$E7*SUMIF(Plan!$M$5:$M$24,"#"&$A7,Plan!L$5:L$24)) | P7: =IF(B7="","","#"&B7) | Q7: =IF(A7="","","#"&A7)
A8: RA Brenda | B8: 1300000037 | C8: =IFERROR(INDEX(Materiales!$B$4:$B$484,MATCH("#"&$B8,Materiales!$K$4:$K$484,0)),"") | D8: =IFERROR(INDEX(Materiales!$C$4:$C$484,MATCH("#"&$B8,Materiales!$K$4:$K$484,0)),"") | F8: Perforacion | G8: Barreno / barra conica 4' | H8: =IF($B8="",0,$E8*SUMIF(Plan!$M$5:$M$24,"#"&$A8,Plan!E$5:E$24)) | I8: =IF($B8="",0,$E8*SUMIF(Plan!$M$5:$M$24,"#"&$A8,Plan!F$5:F$24)) | J8: =IF($B8="",0,$E8*SUMIF(Plan!$M$5:$M$24,"#"&$A8,Plan!G$5:G$24)) | K8: =IF($B8="",0,$E8*SUMIF(Plan!$M$5:$M$24,"#"&$A8,Plan!H$5:H$24)) | L8: =IF($B8="",0,$E8*SUMIF(Plan!$M$5:$M$24,"#"&$A8,Plan!I$5:I$24)) | M8: =IF($B8="",0,$E8*SUMIF(Plan!$M$5:$M$24,"#"&$A8,Plan!J$5:J$24)) | N8: =IF($B8="",0,$E8*SUMIF(Plan!$M$5:$M$24,"#"&$A8,Plan!K$5:K$24)) | O8: =IF($B8="",0,$E8*SUMIF(Plan!$M$5:$M$24,"#"&$A8,Plan!L$5:L$24)) | P8: =IF(B8="","","#"&B8) | Q8: =IF(A8="","","#"&A8)
A9: RA Brenda | B9: 1200000022 | C9: =IFERROR(INDEX(Materiales!$B$4:$B$484,MATCH("#"&$B9,Materiales!$K$4:$K$484,0)),"") | D9: =IFERROR(INDEX(Materiales!$C$4:$C$484,MATCH("#"&$B9,Materiales!$K$4:$K$484,0)),"") | F9: Perforacion | G9: Aceite de la perforadora por metro | H9: =IF($B9="",0,$E9*SUMIF(Plan!$M$5:$M$24,"#"&$A9,Plan!E$5:E$24)) | I9: =IF($B9="",0,$E9*SUMIF(Plan!$M$5:$M$24,"#"&$A9,Plan!F$5:F$24)) | J9: =IF($B9="",0,$E9*SUMIF(Plan!$M$5:$M$24,"#"&$A9,Plan!G$5:G$24)) | K9: =IF($B9="",0,$E9*SUMIF(Plan!$M$5:$M$24,"#"&$A9,Plan!H$5:H$24)) | L9: =IF($B9="",0,$E9*SUMIF(Plan!$M$5:$M$24,"#"&$A9,Plan!I$5:I$24)) | M9: =IF($B9="",0,$E9*SUMIF(Plan!$M$5:$M$24,"#"&$A9,Plan!J$5:J$24)) | N9: =IF($B9="",0,$E9*SUMIF(Plan!$M$5:$M$24,"#"&$A9,Plan!K$5:K$24)) | O9: =IF($B9="",0,$E9*SUMIF(Plan!$M$5:$M$24,"#"&$A9,Plan!L$5:L$24)) | P9: =IF(B9="","","#"&B9) | Q9: =IF(A9="","","#"&A9)
A10: RA Brenda | B10: M1000 | C10: =IFERROR(INDEX(Materiales!$B$4:$B$484,MATCH("#"&$B10,Materiales!$K$4:$K$484,0)),"") | D10: =IFERROR(INDEX(Materiales!$C$4:$C$484,MATCH("#"&$B10,Materiales!$K$4:$K$484,0)),"") | F10: Voladura | G10: Emulnor 1000: cartuchos por disparo / 1.5 | H10: =IF($B10="",0,$E10*SUMIF(Plan!$M$5:$M$24,"#"&$A10,Plan!E$5:E$24)) | I10: =IF($B10="",0,$E10*SUMIF(Plan!$M$5:$M$24,"#"&$A10,Plan!F$5:F$24)) | J10: =IF($B10="",0,$E10*SUMIF(Plan!$M$5:$M$24,"#"&$A10,Plan!G$5:G$24)) | K10: =IF($B10="",0,$E10*SUMIF(Plan!$M$5:$M$24,"#"&$A10,Plan!H$5:H$24)) | L10: =IF($B10="",0,$E10*SUMIF(Plan!$M$5:$M$24,"#"&$A10,Plan!I$5:I$24)) | M10: =IF($B10="",0,$E10*SUMIF(Plan!$M$5:$M$24,"#"&$A10,Plan!J$5:J$24)) | N10: =IF($B10="",0,$E10*SUMIF(Plan!$M$5:$M$24,"#"&$A10,Plan!K$5:K$24)) | O10: =IF($B10="",0,$E10*SUMIF(Plan!$M$5:$M$24,"#"&$A10,Plan!L$5:L$24)) | P10: =IF(B10="","","#"&B10) | Q10: =IF(A10="","","#"&A10)
A11: RA Brenda | B11: M3000 | C11: =IFERROR(INDEX(Materiales!$B$4:$B$484,MATCH("#"&$B11,Materiales!$K$4:$K$484,0)),"") | D11: =IFERROR(INDEX(Materiales!$C$4:$C$484,MATCH("#"&$B11,Materiales!$K$4:$K$484,0)),"") | F11: Voladura | G11: Emulnor 3000: cartuchos por disparo / 1.5 | H11: =IF($B11="",0,$E11*SUMIF(Plan!$M$5:$M$24,"#"&$A11,Plan!E$5:E$24)) | I11: =IF($B11="",0,$E11*SUMIF(Plan!$M$5:$M$24,"#"&$A11,Plan!F$5:F$24)) | J11: =IF($B11="",0,$E11*SUMIF(Plan!$M$5:$M$24,"#"&$A11,Plan!G$5:G$24)) | K11: =IF($B11="",0,$E11*SUMIF(Plan!$M$5:$M$24,"#"&$A11,Plan!H$5:H$24)) | L11: =IF($B11="",0,$E11*SUMIF(Plan!$M$5:$M$24,"#"&$A11,Plan!I$5:I$24)) | M11: =IF($B11="",0,$E11*SUMIF(Plan!$M$5:$M$24,"#"&$A11,Plan!J$5:J$24)) | N11: =IF($B11="",0,$E11*SUMIF(Plan!$M$5:$M$24,"#"&$A11,Plan!K$5:K$24)) | O11: =IF($B11="",0,$E11*SUMIF(Plan!$M$5:$M$24,"#"&$A11,Plan!L$5:L$24)) | P11: =IF(B11="","","#"&B11) | Q11: =IF(A11="","","#"&A11)
A12: RA Brenda | B12: CARMEX240 | C12: =IFERROR(INDEX(Materiales!$B$4:$B$484,MATCH("#"&$B12,Materiales!$K$4:$K$484,0)),"") | D12: =IFERROR(INDEX(Materiales!$C$4:$C$484,MATCH("#"&$B12,Materiales!$K$4:$K$484,0)),"") | F12: Voladura | G12: Carmex: uno por taladro cargado / 1.5 | H12: =IF($B12="",0,$E12*SUMIF(Plan!$M$5:$M$24,"#"&$A12,Plan!E$5:E$24)) | I12: =IF($B12="",0,$E12*SUMIF(Plan!$M$5:$M$24,"#"&$A12,Plan!F$5:F$24)) | J12: =IF($B12="",0,$E12*SUMIF(Plan!$M$5:$M$24,"#"&$A12,Plan!G$5:G$24)) | K12: =IF($B12="",0,$E12*SUMIF(Plan!$M$5:$M$24,"#"&$A12,Plan!H$5:H$24)) | L12: =IF($B12="",0,$E12*SUMIF(Plan!$M$5:$M$24,"#"&$A12,Plan!I$5:I$24)) | M12: =IF($B12="",0,$E12*SUMIF(Plan!$M$5:$M$24,"#"&$A12,Plan!J$5:J$24)) | N12: =IF($B12="",0,$E12*SUMIF(Plan!$M$5:$M$24,"#"&$A12,Plan!K$5:K$24)) | O12: =IF($B12="",0,$E12*SUMIF(Plan!$M$5:$M$24,"#"&$A12,Plan!L$5:L$24)) | P12: =IF(B12="","","#"&B12) | Q12: =IF(A12="","","#"&A12)
A13: RA Brenda | B13: NEITHER | C13: =IFERROR(INDEX(Materiales!$B$4:$B$484,MATCH("#"&$B13,Materiales!$K$4:$K$484,0)),"") | D13: =IFERROR(INDEX(Materiales!$C$4:$C$484,MATCH("#"&$B13,Materiales!$K$4:$K$484,0)),"") | F13: Voladura | G13: Mecha rapida de ignicion, metros por disparo / 1.5 | H13: =IF($B13="",0,$E13*SUMIF(Plan!$M$5:$M$24,"#"&$A13,Plan!E$5:E$24)) | I13: =IF($B13="",0,$E13*SUMIF(Plan!$M$5:$M$24,"#"&$A13,Plan!F$5:F$24)) | J13: =IF($B13="",0,$E13*SUMIF(Plan!$M$5:$M$24,"#"&$A13,Plan!G$5:G$24)) | K13: =IF($B13="",0,$E13*SUMIF(Plan!$M$5:$M$24,"#"&$A13,Plan!H$5:H$24)) | L13: =IF($B13="",0,$E13*SUMIF(Plan!$M$5:$M$24,"#"&$A13,Plan!I$5:I$24)) | M13: =IF($B13="",0,$E13*SUMIF(Plan!$M$5:$M$24,"#"&$A13,Plan!J$5:J$24)) | N13: =IF($B13="",0,$E13*SUMIF(Plan!$M$5:$M$24,"#"&$A13,Plan!K$5:K$24)) | O13: =IF($B13="",0,$E13*SUMIF(Plan!$M$5:$M$24,"#"&$A13,Plan!L$5:L$24)) | P13: =IF(B13="","","#"&B13) | Q13: =IF(A13="","","#"&A13)
A14: RA Brenda | B14: 1500000031 | C14: =IFERROR(INDEX(Materiales!$B$4:$B$484,MATCH("#"&$B14,Materiales!$K$4:$K$484,0)),"") | D14: =IFERROR(INDEX(Materiales!$C$4:$C$484,MATCH("#"&$B14,Materiales!$K$4:$K$484,0)),"") | F14: Voladura | G14: Atacadores de madera | H14: =IF($B14="",0,$E14*SUMIF(Plan!$M$5:$M$24,"#"&$A14,Plan!E$5:E$24)) | I14: =IF($B14="",0,$E14*SUMIF(Plan!$M$5:$M$24,"#"&$A14,Plan!F$5:F$24)) | J14: =IF($B14="",0,$E14*SUMIF(Plan!$M$5:$M$24,"#"&$A14,Plan!G$5:G$24)) | K14: =IF($B14="",0,$E14*SUMIF(Plan!$M$5:$M$24,"#"&$A14,Plan!H$5:H$24)) | L14: =IF($B14="",0,$E14*SUMIF(Plan!$M$5:$M$24,"#"&$A14,Plan!I$5:I$24)) | M14: =IF($B14="",0,$E14*SUMIF(Plan!$M$5:$M$24,"#"&$A14,Plan!J$5:J$24)) | N14: =IF($B14="",0,$E14*SUMIF(Plan!$M$5:$M$24,"#"&$A14,Plan!K$5:K$24)) | O14: =IF($B14="",0,$E14*SUMIF(Plan!$M$5:$M$24,"#"&$A14,Plan!L$5:L$24)) | P14: =IF(B14="","","#"&B14) | Q14: =IF(A14="","","#"&A14)
A15: RA Brenda | B15: 1500002859 | C15: =IFERROR(INDEX(Materiales!$B$4:$B$484,MATCH("#"&$B15,Materiales!$K$4:$K$484,0)),"") | D15: =IFERROR(INDEX(Materiales!$C$4:$C$484,MATCH("#"&$B15,Materiales!$K$4:$K$484,0)),"") | F15: Voladura | G15: Saco metalero | H15: =IF($B15="",0,$E15*SUMIF(Plan!$M$5:$M$24,"#"&$A15,Plan!E$5:E$24)) | I15: =IF($B15="",0,$E15*SUMIF(Plan!$M$5:$M$24,"#"&$A15,Plan!F$5:F$24)) | J15: =IF($B15="",0,$E15*SUMIF(Plan!$M$5:$M$24,"#"&$A15,Plan!G$5:G$24)) | K15: =IF($B15="",0,$E15*SUMIF(Plan!$M$5:$M$24,"#"&$A15,Plan!H$5:H$24)) | L15: =IF($B15="",0,$E15*SUMIF(Plan!$M$5:$M$24,"#"&$A15,Plan!I$5:I$24)) | M15: =IF($B15="",0,$E15*SUMIF(Plan!$M$5:$M$24,"#"&$A15,Plan!J$5:J$24)) | N15: =IF($B15="",0,$E15*SUMIF(Plan!$M$5:$M$24,"#"&$A15,Plan!K$5:K$24)) | O15: =IF($B15="",0,$E15*SUMIF(Plan!$M$5:$M$24,"#"&$A15,Plan!L$5:L$24)) | P15: =IF(B15="","","#"&B15) | Q15: =IF(A15="","","#"&A15)
A16: RA Brenda | B16: 1700000144 | C16: =IFERROR(INDEX(Materiales!$B$4:$B$484,MATCH("#"&$B16,Materiales!$K$4:$K$484,0)),"") | D16: =IFERROR(INDEX(Materiales!$C$4:$C$484,MATCH("#"&$B16,Materiales!$K$4:$K$484,0)),"") | E16: =1/1.5 | F16: Sostenimiento | G16: DATO REAL: sostenimiento pesado, 1 juego de cimbra por disparo de 1.5 m | H16: =IF($B16="",0,$E16*SUMIF(Plan!$M$5:$M$24,"#"&$A16,Plan!E$5:E$24)) | I16: =IF($B16="",0,$E16*SUMIF(Plan!$M$5:$M$24,"#"&$A16,Plan!F$5:F$24)) | J16: =IF($B16="",0,$E16*SUMIF(Plan!$M$5:$M$24,"#"&$A16,Plan!G$5:G$24)) | K16: =IF($B16="",0,$E16*SUMIF(Plan!$M$5:$M$24,"#"&$A16,Plan!H$5:H$24)) | L16: =IF($B16="",0,$E16*SUMIF(Plan!$M$5:$M$24,"#"&$A16,Plan!I$5:I$24)) | M16: =IF($B16="",0,$E16*SUMIF(Plan!$M$5:$M$24,"#"&$A16,Plan!J$5:J$24)) | N16: =IF($B16="",0,$E16*SUMIF(Plan!$M$5:$M$24,"#"&$A16,Plan!K$5:K$24)) | O16: =IF($B16="",0,$E16*SUMIF(Plan!$M$5:$M$24,"#"&$A16,Plan!L$5:L$24)) | P16: =IF(B16="","","#"&B16) | Q16: =IF(A16="","","#"&A16)
A17: RA Brenda | B17: 1500001454 | C17: =IFERROR(INDEX(Materiales!$B$4:$B$484,MATCH("#"&$B17,Materiales!$K$4:$K$484,0)),"") | D17: =IFERROR(INDEX(Materiales!$C$4:$C$484,MATCH("#"&$B17,Materiales!$K$4:$K$484,0)),"") | F17: Sostenimiento | G17: Alcayatas para fijar la cimbra: cuantas por cimbra / 1.5 | H17: =IF($B17="",0,$E17*SUMIF(Plan!$M$5:$M$24,"#"&$A17,Plan!E$5:E$24)) | I17: =IF($B17="",0,$E17*SUMIF(Plan!$M$5:$M$24,"#"&$A17,Plan!F$5:F$24)) | J17: =IF($B17="",0,$E17*SUMIF(Plan!$M$5:$M$24,"#"&$A17,Plan!G$5:G$24)) | K17: =IF($B17="",0,$E17*SUMIF(Plan!$M$5:$M$24,"#"&$A17,Plan!H$5:H$24)) | L17: =IF($B17="",0,$E17*SUMIF(Plan!$M$5:$M$24,"#"&$A17,Plan!I$5:I$24)) | M17: =IF($B17="",0,$E17*SUMIF(Plan!$M$5:$M$24,"#"&$A17,Plan!J$5:J$24)) | N17: =IF($B17="",0,$E17*SUMIF(Plan!$M$5:$M$24,"#"&$A17,Plan!K$5:K$24)) | O17: =IF($B17="",0,$E17*SUMIF(Plan!$M$5:$M$24,"#"&$A17,Plan!L$5:L$24)) | P17: =IF(B17="","","#"&B17) | Q17: =IF(A17="","","#"&A17)
A18: RA Brenda | B18: 1500001437 | C18: =IFERROR(INDEX(Materiales!$B$4:$B$484,MATCH("#"&$B18,Materiales!$K$4:$K$484,0)),"") | D18: =IFERROR(INDEX(Materiales!$C$4:$C$484,MATCH("#"&$B18,Materiales!$K$4:$K$484,0)),"") | F18: Sostenimiento | G18: Alcayata T-G, si se usa | H18: =IF($B18="",0,$E18*SUMIF(Plan!$M$5:$M$24,"#"&$A18,Plan!E$5:E$24)) | I18: =IF($B18="",0,$E18*SUMIF(Plan!$M$5:$M$24,"#"&$A18,Plan!F$5:F$24)) | J18: =IF($B18="",0,$E18*SUMIF(Plan!$M$5:$M$24,"#"&$A18,Plan!G$5:G$24)) | K18: =IF($B18="",0,$E18*SUMIF(Plan!$M$5:$M$24,"#"&$A18,Plan!H$5:H$24)) | L18: =IF($B18="",0,$E18*SUMIF(Plan!$M$5:$M$24,"#"&$A18,Plan!I$5:I$24)) | M18: =IF($B18="",0,$E18*SUMIF(Plan!$M$5:$M$24,"#"&$A18,Plan!J$5:J$24)) | N18: =IF($B18="",0,$E18*SUMIF(Plan!$M$5:$M$24,"#"&$A18,Plan!K$5:K$24)) | O18: =IF($B18="",0,$E18*SUMIF(Plan!$M$5:$M$24,"#"&$A18,Plan!L$5:L$24)) | P18: =IF(B18="","","#"&B18) | Q18: =IF(A18="","","#"&A18)
A19: RA Brenda | B19: 1500001438 | C19: =IFERROR(INDEX(Materiales!$B$4:$B$484,MATCH("#"&$B19,Materiales!$K$4:$K$484,0)),"") | D19: =IFERROR(INDEX(Materiales!$C$4:$C$484,MATCH("#"&$B19,Materiales!$K$4:$K$484,0)),"") | F19: Sostenimiento | G19: Alcayata T-L, si se usa | H19: =IF($B19="",0,$E19*SUMIF(Plan!$M$5:$M$24,"#"&$A19,Plan!E$5:E$24)) | I19: =IF($B19="",0,$E19*SUMIF(Plan!$M$5:$M$24,"#"&$A19,Plan!F$5:F$24)) | J19: =IF($B19="",0,$E19*SUMIF(Plan!$M$5:$M$24,"#"&$A19,Plan!G$5:G$24)) | K19: =IF($B19="",0,$E19*SUMIF(Plan!$M$5:$M$24,"#"&$A19,Plan!H$5:H$24)) | L19: =IF($B19="",0,$E19*SUMIF(Plan!$M$5:$M$24,"#"&$A19,Plan!I$5:I$24)) | M19: =IF($B19="",0,$E19*SUMIF(Plan!$M$5:$M$24,"#"&$A19,Plan!J$5:J$24)) | N19: =IF($B19="",0,$E19*SUMIF(Plan!$M$5:$M$24,"#"&$A19,Plan!K$5:K$24)) | O19: =IF($B19="",0,$E19*SUMIF(Plan!$M$5:$M$24,"#"&$A19,Plan!L$5:L$24)) | P19: =IF(B19="","","#"&B19) | Q19: =IF(A19="","","#"&A19)
A20: RA Brenda | B20: 1600000008 | C20: =IFERROR(INDEX(Materiales!$B$4:$B$484,MATCH("#"&$B20,Materiales!$K$4:$K$484,0)),"") | D20: =IFERROR(INDEX(Materiales!$C$4:$C$484,MATCH("#"&$B20,Materiales!$K$4:$K$484,0)),"") | F20: Sostenimiento | G20: Liston para encribado entre cimbras | H20: =IF($B20="",0,$E20*SUMIF(Plan!$M$5:$M$24,"#"&$A20,Plan!E$5:E$24)) | I20: =IF($B20="",0,$E20*SUMIF(Plan!$M$5:$M$24,"#"&$A20,Plan!F$5:F$24)) | J20: =IF($B20="",0,$E20*SUMIF(Plan!$M$5:$M$24,"#"&$A20,Plan!G$5:G$24)) | K20: =IF($B20="",0,$E20*SUMIF(Plan!$M$5:$M$24,"#"&$A20,Plan!H$5:H$24)) | L20: =IF($B20="",0,$E20*SUMIF(Plan!$M$5:$M$24,"#"&$A20,Plan!I$5:I$24)) | M20: =IF($B20="",0,$E20*SUMIF(Plan!$M$5:$M$24,"#"&$A20,Plan!J$5:J$24)) | N20: =IF($B20="",0,$E20*SUMIF(Plan!$M$5:$M$24,"#"&$A20,Plan!K$5:K$24)) | O20: =IF($B20="",0,$E20*SUMIF(Plan!$M$5:$M$24,"#"&$A20,Plan!L$5:L$24)) | P20: =IF(B20="","","#"&B20) | Q20: =IF(A20="","","#"&A20)
A21: RA Brenda | B21: 1600000009 | C21: =IFERROR(INDEX(Materiales!$B$4:$B$484,MATCH("#"&$B21,Materiales!$K$4:$K$484,0)),"") | D21: =IFERROR(INDEX(Materiales!$C$4:$C$484,MATCH("#"&$B21,Materiales!$K$4:$K$484,0)),"") | F21: Sostenimiento | G21: Tabla aserrada para encribado | H21: =IF($B21="",0,$E21*SUMIF(Plan!$M$5:$M$24,"#"&$A21,Plan!E$5:E$24)) | I21: =IF($B21="",0,$E21*SUMIF(Plan!$M$5:$M$24,"#"&$A21,Plan!F$5:F$24)) | J21: =IF($B21="",0,$E21*SUMIF(Plan!$M$5:$M$24,"#"&$A21,Plan!G$5:G$24)) | K21: =IF($B21="",0,$E21*SUMIF(Plan!$M$5:$M$24,"#"&$A21,Plan!H$5:H$24)) | L21: =IF($B21="",0,$E21*SUMIF(Plan!$M$5:$M$24,"#"&$A21,Plan!I$5:I$24)) | M21: =IF($B21="",0,$E21*SUMIF(Plan!$M$5:$M$24,"#"&$A21,Plan!J$5:J$24)) | N21: =IF($B21="",0,$E21*SUMIF(Plan!$M$5:$M$24,"#"&$A21,Plan!K$5:K$24)) | O21: =IF($B21="",0,$E21*SUMIF(Plan!$M$5:$M$24,"#"&$A21,Plan!L$5:L$24)) | P21: =IF(B21="","","#"&B21) | Q21: =IF(A21="","","#"&A21)
A22: RA Brenda | B22: 1500000032 | C22: =IFERROR(INDEX(Materiales!$B$4:$B$484,MATCH("#"&$B22,Materiales!$K$4:$K$484,0)),"") | D22: =IFERROR(INDEX(Materiales!$C$4:$C$484,MATCH("#"&$B22,Materiales!$K$4:$K$484,0)),"") | F22: Sostenimiento | G22: Guiadores de madera | H22: =IF($B22="",0,$E22*SUMIF(Plan!$M$5:$M$24,"#"&$A22,Plan!E$5:E$24)) | I22: =IF($B22="",0,$E22*SUMIF(Plan!$M$5:$M$24,"#"&$A22,Plan!F$5:F$24)) | J22: =IF($B22="",0,$E22*SUMIF(Plan!$M$5:$M$24,"#"&$A22,Plan!G$5:G$24)) | K22: =IF($B22="",0,$E22*SUMIF(Plan!$M$5:$M$24,"#"&$A22,Plan!H$5:H$24)) | L22: =IF($B22="",0,$E22*SUMIF(Plan!$M$5:$M$24,"#"&$A22,Plan!I$5:I$24)) | M22: =IF($B22="",0,$E22*SUMIF(Plan!$M$5:$M$24,"#"&$A22,Plan!J$5:J$24)) | N22: =IF($B22="",0,$E22*SUMIF(Plan!$M$5:$M$24,"#"&$A22,Plan!K$5:K$24)) | O22: =IF($B22="",0,$E22*SUMIF(Plan!$M$5:$M$24,"#"&$A22,Plan!L$5:L$24)) | P22: =IF(B22="","","#"&B22) | Q22: =IF(A22="","","#"&A22)
A23: RA Brenda | B23: 2100000014 | C23: =IFERROR(INDEX(Materiales!$B$4:$B$484,MATCH("#"&$B23,Materiales!$K$4:$K$484,0)),"") | D23: =IFERROR(INDEX(Materiales!$C$4:$C$484,MATCH("#"&$B23,Materiales!$K$4:$K$484,0)),"") | F23: Ventilacion | G23: Manga de 30": metros de manga por metro de avance (normalmente 1) | H23: =IF($B23="",0,$E23*SUMIF(Plan!$M$5:$M$24,"#"&$A23,Plan!E$5:E$24)) | I23: =IF($B23="",0,$E23*SUMIF(Plan!$M$5:$M$24,"#"&$A23,Plan!F$5:F$24)) | J23: =IF($B23="",0,$E23*SUMIF(Plan!$M$5:$M$24,"#"&$A23,Plan!G$5:G$24)) | K23: =IF($B23="",0,$E23*SUMIF(Plan!$M$5:$M$24,"#"&$A23,Plan!H$5:H$24)) | L23: =IF($B23="",0,$E23*SUMIF(Plan!$M$5:$M$24,"#"&$A23,Plan!I$5:I$24)) | M23: =IF($B23="",0,$E23*SUMIF(Plan!$M$5:$M$24,"#"&$A23,Plan!J$5:J$24)) | N23: =IF($B23="",0,$E23*SUMIF(Plan!$M$5:$M$24,"#"&$A23,Plan!K$5:K$24)) | O23: =IF($B23="",0,$E23*SUMIF(Plan!$M$5:$M$24,"#"&$A23,Plan!L$5:L$24)) | P23: =IF(B23="","","#"&B23) | Q23: =IF(A23="","","#"&A23)
A24: RA Brenda | B24: 1900000203 | C24: =IFERROR(INDEX(Materiales!$B$4:$B$484,MATCH("#"&$B24,Materiales!$K$4:$K$484,0)),"") | D24: =IFERROR(INDEX(Materiales!$C$4:$C$484,MATCH("#"&$B24,Materiales!$K$4:$K$484,0)),"") | F24: Servicios | G24: Tuberia de agua 2": metros por metro de avance | H24: =IF($B24="",0,$E24*SUMIF(Plan!$M$5:$M$24,"#"&$A24,Plan!E$5:E$24)) | I24: =IF($B24="",0,$E24*SUMIF(Plan!$M$5:$M$24,"#"&$A24,Plan!F$5:F$24)) | J24: =IF($B24="",0,$E24*SUMIF(Plan!$M$5:$M$24,"#"&$A24,Plan!G$5:G$24)) | K24: =IF($B24="",0,$E24*SUMIF(Plan!$M$5:$M$24,"#"&$A24,Plan!H$5:H$24)) | L24: =IF($B24="",0,$E24*SUMIF(Plan!$M$5:$M$24,"#"&$A24,Plan!I$5:I$24)) | M24: =IF($B24="",0,$E24*SUMIF(Plan!$M$5:$M$24,"#"&$A24,Plan!J$5:J$24)) | N24: =IF($B24="",0,$E24*SUMIF(Plan!$M$5:$M$24,"#"&$A24,Plan!K$5:K$24)) | O24: =IF($B24="",0,$E24*SUMIF(Plan!$M$5:$M$24,"#"&$A24,Plan!L$5:L$24)) | P24: =IF(B24="","","#"&B24) | Q24: =IF(A24="","","#"&A24)
A25: RA Brenda | B25: 1900000205 | C25: =IFERROR(INDEX(Materiales!$B$4:$B$484,MATCH("#"&$B25,Materiales!$K$4:$K$484,0)),"") | D25: =IFERROR(INDEX(Materiales!$C$4:$C$484,MATCH("#"&$B25,Materiales!$K$4:$K$484,0)),"") | F25: Servicios | G25: Tuberia de aire 1": metros por metro de avance | H25: =IF($B25="",0,$E25*SUMIF(Plan!$M$5:$M$24,"#"&$A25,Plan!E$5:E$24)) | I25: =IF($B25="",0,$E25*SUMIF(Plan!$M$5:$M$24,"#"&$A25,Plan!F$5:F$24)) | J25: =IF($B25="",0,$E25*SUMIF(Plan!$M$5:$M$24,"#"&$A25,Plan!G$5:G$24)) | K25: =IF($B25="",0,$E25*SUMIF(Plan!$M$5:$M$24,"#"&$A25,Plan!H$5:H$24)) | L25: =IF($B25="",0,$E25*SUMIF(Plan!$M$5:$M$24,"#"&$A25,Plan!I$5:I$24)) | M25: =IF($B25="",0,$E25*SUMIF(Plan!$M$5:$M$24,"#"&$A25,Plan!J$5:J$24)) | N25: =IF($B25="",0,$E25*SUMIF(Plan!$M$5:$M$24,"#"&$A25,Plan!K$5:K$24)) | O25: =IF($B25="",0,$E25*SUMIF(Plan!$M$5:$M$24,"#"&$A25,Plan!L$5:L$24)) | P25: =IF(B25="","","#"&B25) | Q25: =IF(A25="","","#"&A25)
A26: RA Brenda | C26: =IFERROR(INDEX(Materiales!$B$4:$B$484,MATCH("#"&$B26,Materiales!$K$4:$K$484,0)),"") | D26: =IFERROR(INDEX(Materiales!$C$4:$C$484,MATCH("#"&$B26,Materiales!$K$4:$K$484,0)),"") | H26: =IF($B26="",0,$E26*SUMIF(Plan!$M$5:$M$24,"#"&$A26,Plan!E$5:E$24)) | I26: =IF($B26="",0,$E26*SUMIF(Plan!$M$5:$M$24,"#"&$A26,Plan!F$5:F$24)) | J26: =IF($B26="",0,$E26*SUMIF(Plan!$M$5:$M$24,"#"&$A26,Plan!G$5:G$24)) | K26: =IF($B26="",0,$E26*SUMIF(Plan!$M$5:$M$24,"#"&$A26,Plan!H$5:H$24)) | L26: =IF($B26="",0,$E26*SUMIF(Plan!$M$5:$M$24,"#"&$A26,Plan!I$5:I$24)) | M26: =IF($B26="",0,$E26*SUMIF(Plan!$M$5:$M$24,"#"&$A26,Plan!J$5:J$24)) | N26: =IF($B26="",0,$E26*SUMIF(Plan!$M$5:$M$24,"#"&$A26,Plan!K$5:K$24)) | O26: =IF($B26="",0,$E26*SUMIF(Plan!$M$5:$M$24,"#"&$A26,Plan!L$5:L$24)) | P26: =IF(B26="","","#"&B26) | Q26: =IF(A26="","","#"&A26)
A27: RA Brenda | C27: =IFERROR(INDEX(Materiales!$B$4:$B$484,MATCH("#"&$B27,Materiales!$K$4:$K$484,0)),"") | D27: =IFERROR(INDEX(Materiales!$C$4:$C$484,MATCH("#"&$B27,Materiales!$K$4:$K$484,0)),"") | H27: =IF($B27="",0,$E27*SUMIF(Plan!$M$5:$M$24,"#"&$A27,Plan!E$5:E$24)) | I27: =IF($B27="",0,$E27*SUMIF(Plan!$M$5:$M$24,"#"&$A27,Plan!F$5:F$24)) | J27: =IF($B27="",0,$E27*SUMIF(Plan!$M$5:$M$24,"#"&$A27,Plan!G$5:G$24)) | K27: =IF($B27="",0,$E27*SUMIF(Plan!$M$5:$M$24,"#"&$A27,Plan!H$5:H$24)) | L27: =IF($B27="",0,$E27*SUMIF(Plan!$M$5:$M$24,"#"&$A27,Plan!I$5:I$24)) | M27: =IF($B27="",0,$E27*SUMIF(Plan!$M$5:$M$24,"#"&$A27,Plan!J$5:J$24)) | N27: =IF($B27="",0,$E27*SUMIF(Plan!$M$5:$M$24,"#"&$A27,Plan!K$5:K$24)) | O27: =IF($B27="",0,$E27*SUMIF(Plan!$M$5:$M$24,"#"&$A27,Plan!L$5:L$24)) | P27: =IF(B27="","","#"&B27) | Q27: =IF(A27="","","#"&A27)
A28: RA Brenda | C28: =IFERROR(INDEX(Materiales!$B$4:$B$484,MATCH("#"&$B28,Materiales!$K$4:$K$484,0)),"") | D28: =IFERROR(INDEX(Materiales!$C$4:$C$484,MATCH("#"&$B28,Materiales!$K$4:$K$484,0)),"") | H28: =IF($B28="",0,$E28*SUMIF(Plan!$M$5:$M$24,"#"&$A28,Plan!E$5:E$24)) | I28: =IF($B28="",0,$E28*SUMIF(Plan!$M$5:$M$24,"#"&$A28,Plan!F$5:F$24)) | J28: =IF($B28="",0,$E28*SUMIF(Plan!$M$5:$M$24,"#"&$A28,Plan!G$5:G$24)) | K28: =IF($B28="",0,$E28*SUMIF(Plan!$M$5:$M$24,"#"&$A28,Plan!H$5:H$24)) | L28: =IF($B28="",0,$E28*SUMIF(Plan!$M$5:$M$24,"#"&$A28,Plan!I$5:I$24)) | M28: =IF($B28="",0,$E28*SUMIF(Plan!$M$5:$M$24,"#"&$A28,Plan!J$5:J$24)) | N28: =IF($B28="",0,$E28*SUMIF(Plan!$M$5:$M$24,"#"&$A28,Plan!K$5:K$24)) | O28: =IF($B28="",0,$E28*SUMIF(Plan!$M$5:$M$24,"#"&$A28,Plan!L$5:L$24)) | P28: =IF(B28="","","#"&B28) | Q28: =IF(A28="","","#"&A28)
A29: RA Brenda | C29: =IFERROR(INDEX(Materiales!$B$4:$B$484,MATCH("#"&$B29,Materiales!$K$4:$K$484,0)),"") | D29: =IFERROR(INDEX(Materiales!$C$4:$C$484,MATCH("#"&$B29,Materiales!$K$4:$K$484,0)),"") | H29: =IF($B29="",0,$E29*SUMIF(Plan!$M$5:$M$24,"#"&$A29,Plan!E$5:E$24)) | I29: =IF($B29="",0,$E29*SUMIF(Plan!$M$5:$M$24,"#"&$A29,Plan!F$5:F$24)) | J29: =IF($B29="",0,$E29*SUMIF(Plan!$M$5:$M$24,"#"&$A29,Plan!G$5:G$24)) | K29: =IF($B29="",0,$E29*SUMIF(Plan!$M$5:$M$24,"#"&$A29,Plan!H$5:H$24)) | L29: =IF($B29="",0,$E29*SUMIF(Plan!$M$5:$M$24,"#"&$A29,Plan!I$5:I$24)) | M29: =IF($B29="",0,$E29*SUMIF(Plan!$M$5:$M$24,"#"&$A29,Plan!J$5:J$24)) | N29: =IF($B29="",0,$E29*SUMIF(Plan!$M$5:$M$24,"#"&$A29,Plan!K$5:K$24)) | O29: =IF($B29="",0,$E29*SUMIF(Plan!$M$5:$M$24,"#"&$A29,Plan!L$5:L$24)) | P29: =IF(B29="","","#"&B29) | Q29: =IF(A29="","","#"&A29)
A30: RA Brenda | C30: =IFERROR(INDEX(Materiales!$B$4:$B$484,MATCH("#"&$B30,Materiales!$K$4:$K$484,0)),"") | D30: =IFERROR(INDEX(Materiales!$C$4:$C$484,MATCH("#"&$B30,Materiales!$K$4:$K$484,0)),"") | H30: =IF($B30="",0,$E30*SUMIF(Plan!$M$5:$M$24,"#"&$A30,Plan!E$5:E$24)) | I30: =IF($B30="",0,$E30*SUMIF(Plan!$M$5:$M$24,"#"&$A30,Plan!F$5:F$24)) | J30: =IF($B30="",0,$E30*SUMIF(Plan!$M$5:$M$24,"#"&$A30,Plan!G$5:G$24)) | K30: =IF($B30="",0,$E30*SUMIF(Plan!$M$5:$M$24,"#"&$A30,Plan!H$5:H$24)) | L30: =IF($B30="",0,$E30*SUMIF(Plan!$M$5:$M$24,"#"&$A30,Plan!I$5:I$24)) | M30: =IF($B30="",0,$E30*SUMIF(Plan!$M$5:$M$24,"#"&$A30,Plan!J$5:J$24)) | N30: =IF($B30="",0,$E30*SUMIF(Plan!$M$5:$M$24,"#"&$A30,Plan!K$5:K$24)) | O30: =IF($B30="",0,$E30*SUMIF(Plan!$M$5:$M$24,"#"&$A30,Plan!L$5:L$24)) | P30: =IF(B30="","","#"&B30) | Q30: =IF(A30="","","#"&A30)
A31: RA Brenda | C31: =IFERROR(INDEX(Materiales!$B$4:$B$484,MATCH("#"&$B31,Materiales!$K$4:$K$484,0)),"") | D31: =IFERROR(INDEX(Materiales!$C$4:$C$484,MATCH("#"&$B31,Materiales!$K$4:$K$484,0)),"") | H31: =IF($B31="",0,$E31*SUMIF(Plan!$M$5:$M$24,"#"&$A31,Plan!E$5:E$24)) | I31: =IF($B31="",0,$E31*SUMIF(Plan!$M$5:$M$24,"#"&$A31,Plan!F$5:F$24)) | J31: =IF($B31="",0,$E31*SUMIF(Plan!$M$5:$M$24,"#"&$A31,Plan!G$5:G$24)) | K31: =IF($B31="",0,$E31*SUMIF(Plan!$M$5:$M$24,"#"&$A31,Plan!H$5:H$24)) | L31: =IF($B31="",0,$E31*SUMIF(Plan!$M$5:$M$24,"#"&$A31,Plan!I$5:I$24)) | M31: =IF($B31="",0,$E31*SUMIF(Plan!$M$5:$M$24,"#"&$A31,Plan!J$5:J$24)) | N31: =IF($B31="",0,$E31*SUMIF(Plan!$M$5:$M$24,"#"&$A31,Plan!K$5:K$24)) | O31: =IF($B31="",0,$E31*SUMIF(Plan!$M$5:$M$24,"#"&$A31,Plan!L$5:L$24)) | P31: =IF(B31="","","#"&B31) | Q31: =IF(A31="","","#"&A31)
A32: RA Brenda | C32: =IFERROR(INDEX(Materiales!$B$4:$B$484,MATCH("#"&$B32,Materiales!$K$4:$K$484,0)),"") | D32: =IFERROR(INDEX(Materiales!$C$4:$C$484,MATCH("#"&$B32,Materiales!$K$4:$K$484,0)),"") | H32: =IF($B32="",0,$E32*SUMIF(Plan!$M$5:$M$24,"#"&$A32,Plan!E$5:E$24)) | I32: =IF($B32="",0,$E32*SUMIF(Plan!$M$5:$M$24,"#"&$A32,Plan!F$5:F$24)) | J32: =IF($B32="",0,$E32*SUMIF(Plan!$M$5:$M$24,"#"&$A32,Plan!G$5:G$24)) | K32: =IF($B32="",0,$E32*SUMIF(Plan!$M$5:$M$24,"#"&$A32,Plan!H$5:H$24)) | L32: =IF($B32="",0,$E32*SUMIF(Plan!$M$5:$M$24,"#"&$A32,Plan!I$5:I$24)) | M32: =IF($B32="",0,$E32*SUMIF(Plan!$M$5:$M$24,"#"&$A32,Plan!J$5:J$24)) | N32: =IF($B32="",0,$E32*SUMIF(Plan!$M$5:$M$24,"#"&$A32,Plan!K$5:K$24)) | O32: =IF($B32="",0,$E32*SUMIF(Plan!$M$5:$M$24,"#"&$A32,Plan!L$5:L$24)) | P32: =IF(B32="","","#"&B32) | Q32: =IF(A32="","","#"&A32)
A33: RA Brenda | C33: =IFERROR(INDEX(Materiales!$B$4:$B$484,MATCH("#"&$B33,Materiales!$K$4:$K$484,0)),"") | D33: =IFERROR(INDEX(Materiales!$C$4:$C$484,MATCH("#"&$B33,Materiales!$K$4:$K$484,0)),"") | H33: =IF($B33="",0,$E33*SUMIF(Plan!$M$5:$M$24,"#"&$A33,Plan!E$5:E$24)) | I33: =IF($B33="",0,$E33*SUMIF(Plan!$M$5:$M$24,"#"&$A33,Plan!F$5:F$24)) | J33: =IF($B33="",0,$E33*SUMIF(Plan!$M$5:$M$24,"#"&$A33,Plan!G$5:G$24)) | K33: =IF($B33="",0,$E33*SUMIF(Plan!$M$5:$M$24,"#"&$A33,Plan!H$5:H$24)) | L33: =IF($B33="",0,$E33*SUMIF(Plan!$M$5:$M$24,"#"&$A33,Plan!I$5:I$24)) | M33: =IF($B33="",0,$E33*SUMIF(Plan!$M$5:$M$24,"#"&$A33,Plan!J$5:J$24)) | N33: =IF($B33="",0,$E33*SUMIF(Plan!$M$5:$M$24,"#"&$A33,Plan!K$5:K$24)) | O33: =IF($B33="",0,$E33*SUMIF(Plan!$M$5:$M$24,"#"&$A33,Plan!L$5:L$24)) | P33: =IF(B33="","","#"&B33) | Q33: =IF(A33="","","#"&A33)
A34: RA Brenda | C34: =IFERROR(INDEX(Materiales!$B$4:$B$484,MATCH("#"&$B34,Materiales!$K$4:$K$484,0)),"") | D34: =IFERROR(INDEX(Materiales!$C$4:$C$484,MATCH("#"&$B34,Materiales!$K$4:$K$484,0)),"") | H34: =IF($B34="",0,$E34*SUMIF(Plan!$M$5:$M$24,"#"&$A34,Plan!E$5:E$24)) | I34: =IF($B34="",0,$E34*SUMIF(Plan!$M$5:$M$24,"#"&$A34,Plan!F$5:F$24)) | J34: =IF($B34="",0,$E34*SUMIF(Plan!$M$5:$M$24,"#"&$A34,Plan!G$5:G$24)) | K34: =IF($B34="",0,$E34*SUMIF(Plan!$M$5:$M$24,"#"&$A34,Plan!H$5:H$24)) | L34: =IF($B34="",0,$E34*SUMIF(Plan!$M$5:$M$24,"#"&$A34,Plan!I$5:I$24)) | M34: =IF($B34="",0,$E34*SUMIF(Plan!$M$5:$M$24,"#"&$A34,Plan!J$5:J$24)) | N34: =IF($B34="",0,$E34*SUMIF(Plan!$M$5:$M$24,"#"&$A34,Plan!K$5:K$24)) | O34: =IF($B34="",0,$E34*SUMIF(Plan!$M$5:$M$24,"#"&$A34,Plan!L$5:L$24)) | P34: =IF(B34="","","#"&B34) | Q34: =IF(A34="","","#"&A34)
A35: FRENTE: CRNE (Cortada Noreste) — consumo por CADA metro de avance
A36: CRNE (Cortada Noreste) | B36: 1300000026 | C36: =IFERROR(INDEX(Materiales!$B$4:$B$484,MATCH("#"&$B36,Materiales!$K$4:$K$484,0)),"") | D36: =IFERROR(INDEX(Materiales!$C$4:$C$484,MATCH("#"&$B36,Materiales!$K$4:$K$484,0)),"") | F36: Perforacion | G36: Brocas por metro: (brocas gastadas al mes) / (metros del mes) | H36: =IF($B36="",0,$E36*SUMIF(Plan!$M$5:$M$24,"#"&$A36,Plan!E$5:E$24)) | I36: =IF($B36="",0,$E36*SUMIF(Plan!$M$5:$M$24,"#"&$A36,Plan!F$5:F$24)) | J36: =IF($B36="",0,$E36*SUMIF(Plan!$M$5:$M$24,"#"&$A36,Plan!G$5:G$24)) | K36: =IF($B36="",0,$E36*SUMIF(Plan!$M$5:$M$24,"#"&$A36,Plan!H$5:H$24)) | L36: =IF($B36="",0,$E36*SUMIF(Plan!$M$5:$M$24,"#"&$A36,Plan!I$5:I$24)) | M36: =IF($B36="",0,$E36*SUMIF(Plan!$M$5:$M$24,"#"&$A36,Plan!J$5:J$24)) | N36: =IF($B36="",0,$E36*SUMIF(Plan!$M$5:$M$24,"#"&$A36,Plan!K$5:K$24)) | O36: =IF($B36="",0,$E36*SUMIF(Plan!$M$5:$M$24,"#"&$A36,Plan!L$5:L$24)) | P36: =IF(B36="","","#"&B36) | Q36: =IF(A36="","","#"&A36)
A37: CRNE (Cortada Noreste) | B37: 1300000023 | C37: =IFERROR(INDEX(Materiales!$B$4:$B$484,MATCH("#"&$B37,Materiales!$K$4:$K$484,0)),"") | D37: =IFERROR(INDEX(Materiales!$C$4:$C$484,MATCH("#"&$B37,Materiales!$K$4:$K$484,0)),"") | F37: Perforacion | G37: Broca de 32 mm, si se usa | H37: =IF($B37="",0,$E37*SUMIF(Plan!$M$5:$M$24,"#"&$A37,Plan!E$5:E$24)) | I37: =IF($B37="",0,$E37*SUMIF(Plan!$M$5:$M$24,"#"&$A37,Plan!F$5:F$24)) | J37: =IF($B37="",0,$E37*SUMIF(Plan!$M$5:$M$24,"#"&$A37,Plan!G$5:G$24)) | K37: =IF($B37="",0,$E37*SUMIF(Plan!$M$5:$M$24,"#"&$A37,Plan!H$5:H$24)) | L37: =IF($B37="",0,$E37*SUMIF(Plan!$M$5:$M$24,"#"&$A37,Plan!I$5:I$24)) | M37: =IF($B37="",0,$E37*SUMIF(Plan!$M$5:$M$24,"#"&$A37,Plan!J$5:J$24)) | N37: =IF($B37="",0,$E37*SUMIF(Plan!$M$5:$M$24,"#"&$A37,Plan!K$5:K$24)) | O37: =IF($B37="",0,$E37*SUMIF(Plan!$M$5:$M$24,"#"&$A37,Plan!L$5:L$24)) | P37: =IF(B37="","","#"&B37) | Q37: =IF(A37="","","#"&A37)
A38: CRNE (Cortada Noreste) | B38: 1300000036 | C38: =IFERROR(INDEX(Materiales!$B$4:$B$484,MATCH("#"&$B38,Materiales!$K$4:$K$484,0)),"") | D38: =IFERROR(INDEX(Materiales!$C$4:$C$484,MATCH("#"&$B38,Materiales!$K$4:$K$484,0)),"") | F38: Perforacion | G38: Barreno / barra conica 6'. Vida util: metros perforados antes de descarte | H38: =IF($B38="",0,$E38*SUMIF(Plan!$M$5:$M$24,"#"&$A38,Plan!E$5:E$24)) | I38: =IF($B38="",0,$E38*SUMIF(Plan!$M$5:$M$24,"#"&$A38,Plan!F$5:F$24)) | J38: =IF($B38="",0,$E38*SUMIF(Plan!$M$5:$M$24,"#"&$A38,Plan!G$5:G$24)) | K38: =IF($B38="",0,$E38*SUMIF(Plan!$M$5:$M$24,"#"&$A38,Plan!H$5:H$24)) | L38: =IF($B38="",0,$E38*SUMIF(Plan!$M$5:$M$24,"#"&$A38,Plan!I$5:I$24)) | M38: =IF($B38="",0,$E38*SUMIF(Plan!$M$5:$M$24,"#"&$A38,Plan!J$5:J$24)) | N38: =IF($B38="",0,$E38*SUMIF(Plan!$M$5:$M$24,"#"&$A38,Plan!K$5:K$24)) | O38: =IF($B38="",0,$E38*SUMIF(Plan!$M$5:$M$24,"#"&$A38,Plan!L$5:L$24)) | P38: =IF(B38="","","#"&B38) | Q38: =IF(A38="","","#"&A38)
A39: CRNE (Cortada Noreste) | B39: 1300000037 | C39: =IFERROR(INDEX(Materiales!$B$4:$B$484,MATCH("#"&$B39,Materiales!$K$4:$K$484,0)),"") | D39: =IFERROR(INDEX(Materiales!$C$4:$C$484,MATCH("#"&$B39,Materiales!$K$4:$K$484,0)),"") | F39: Perforacion | G39: Barreno / barra conica 4' | H39: =IF($B39="",0,$E39*SUMIF(Plan!$M$5:$M$24,"#"&$A39,Plan!E$5:E$24)) | I39: =IF($B39="",0,$E39*SUMIF(Plan!$M$5:$M$24,"#"&$A39,Plan!F$5:F$24)) | J39: =IF($B39="",0,$E39*SUMIF(Plan!$M$5:$M$24,"#"&$A39,Plan!G$5:G$24)) | K39: =IF($B39="",0,$E39*SUMIF(Plan!$M$5:$M$24,"#"&$A39,Plan!H$5:H$24)) | L39: =IF($B39="",0,$E39*SUMIF(Plan!$M$5:$M$24,"#"&$A39,Plan!I$5:I$24)) | M39: =IF($B39="",0,$E39*SUMIF(Plan!$M$5:$M$24,"#"&$A39,Plan!J$5:J$24)) | N39: =IF($B39="",0,$E39*SUMIF(Plan!$M$5:$M$24,"#"&$A39,Plan!K$5:K$24)) | O39: =IF($B39="",0,$E39*SUMIF(Plan!$M$5:$M$24,"#"&$A39,Plan!L$5:L$24)) | P39: =IF(B39="","","#"&B39) | Q39: =IF(A39="","","#"&A39)
A40: CRNE (Cortada Noreste) | B40: 1200000022 | C40: =IFERROR(INDEX(Materiales!$B$4:$B$484,MATCH("#"&$B40,Materiales!$K$4:$K$484,0)),"") | D40: =IFERROR(INDEX(Materiales!$C$4:$C$484,MATCH("#"&$B40,Materiales!$K$4:$K$484,0)),"") | F40: Perforacion | G40: Aceite de la perforadora por metro | H40: =IF($B40="",0,$E40*SUMIF(Plan!$M$5:$M$24,"#"&$A40,Plan!E$5:E$24)) | I40: =IF($B40="",0,$E40*SUMIF(Plan!$M$5:$M$24,"#"&$A40,Plan!F$5:F$24)) | J40: =IF($B40="",0,$E40*SUMIF(Plan!$M$5:$M$24,"#"&$A40,Plan!G$5:G$24)) | K40: =IF($B40="",0,$E40*SUMIF(Plan!$M$5:$M$24,"#"&$A40,Plan!H$5:H$24)) | L40: =IF($B40="",0,$E40*SUMIF(Plan!$M$5:$M$24,"#"&$A40,Plan!I$5:I$24)) | M40: =IF($B40="",0,$E40*SUMIF(Plan!$M$5:$M$24,"#"&$A40,Plan!J$5:J$24)) | N40: =IF($B40="",0,$E40*SUMIF(Plan!$M$5:$M$24,"#"&$A40,Plan!K$5:K$24)) | O40: =IF($B40="",0,$E40*SUMIF(Plan!$M$5:$M$24,"#"&$A40,Plan!L$5:L$24)) | P40: =IF(B40="","","#"&B40) | Q40: =IF(A40="","","#"&A40)
...

Sheet Inventario
A1: PASO 4 — Stock actual y ordenes ya emitidas
A2: Este maestro NO trae stock: cargalo en la columna C. En las columnas de semana pon las ordenes ya emitidas, en la semana en que llegaran.
E3: =Plan!E$3 | F3: =Plan!F$3 | G3: =Plan!G$3 | H3: =Plan!H$3 | I3: =Plan!I$3 | J3: =Plan!J$3 | K3: =Plan!K$3 | L3: =Plan!L$3
A4: Codigo | B4: Producto (auto) | C4: Stock actual | D4: N° OC / Proveedor | E4: Sem 1 | F4: Sem 2 | G4: Sem 3 | H4: Sem 4 | I4: Sem 5 | J4: Sem 6 | K4: Sem 7 | L4: Sem 8 | M4: clave
A5: 1 | B5: =IFERROR(INDEX(Materiales!$B$4:$B$484,MATCH("#"&$A5,Materiales!$K$4:$K$484,0)),"") | M5: =IF(A5="","","#"&A5)
A6: 2 | B6: =IFERROR(INDEX(Materiales!$B$4:$B$484,MATCH("#"&$A6,Materiales!$K$4:$K$484,0)),"") | M6: =IF(A6="","","#"&A6)
A7: 3 | B7: =IFERROR(INDEX(Materiales!$B$4:$B$484,MATCH("#"&$A7,Materiales!$K$4:$K$484,0)),"") | M7: =IF(A7="","","#"&A7)
A8: 4 | B8: =IFERROR(INDEX(Materiales!$B$4:$B$484,MATCH("#"&$A8,Materiales!$K$4:$K$484,0)),"") | M8: =IF(A8="","","#"&A8)
A9: 5 | B9: =IFERROR(INDEX(Materiales!$B$4:$B$484,MATCH("#"&$A9,Materiales!$K$4:$K$484,0)),"") | M9: =IF(A9="","","#"&A9)
A10: 6 | B10: =IFERROR(INDEX(Materiales!$B$4:$B$484,MATCH("#"&$A10,Materiales!$K$4:$K$484,0)),"") | M10: =IF(A10="","","#"&A10)
A11: 7 | B11: =IFERROR(INDEX(Materiales!$B$4:$B$484,MATCH("#"&$A11,Materiales!$K$4:$K$484,0)),"") | M11: =IF(A11="","","#"&A11)
A12: 8 | B12: =IFERROR(INDEX(Materiales!$B$4:$B$484,MATCH("#"&$A12,Materiales!$K$4:$K$484,0)),"") | M12: =IF(A12="","","#"&A12)
A13: 9 | B13: =IFERROR(INDEX(Materiales!$B$4:$B$484,MATCH("#"&$A13,Materiales!$K$4:$K$484,0)),"") | M13: =IF(A13="","","#"&A13)
A14: 10 | B14: =IFERROR(INDEX(Materiales!$B$4:$B$484,MATCH("#"&$A14,Materiales!$K$4:$K$484,0)),"") | M14: =IF(A14="","","#"&A14)
A15: 11 | B15: =IFERROR(INDEX(Materiales!$B$4:$B$484,MATCH("#"&$A15,Materiales!$K$4:$K$484,0)),"") | M15: =IF(A15="","","#"&A15)
A16: 12 | B16: =IFERROR(INDEX(Materiales!$B$4:$B$484,MATCH("#"&$A16,Materiales!$K$4:$K$484,0)),"") | M16: =IF(A16="","","#"&A16)
... A485: FANEL240_16 | B485: =IFERROR(INDEX(Materiales!$B$4:$B$484,MATCH("#"&$A485,Materiales!$K$4:$K$484,0)),"") | M485: =IF(A485="","","#"&A485)
B486: =IFERROR(INDEX(Materiales!$B$4:$B$484,MATCH("#"&$A486,Materiales!$K$4:$K$484,0)),"") | M486: =IF(A486="","","#"&A486)
B487: =IFERROR(INDEX(Materiales!$B$4:$B$484,MATCH("#"&$A487,Materiales!$K$4:$K$484,0)),"") | M487: =IF(A487="","","#"&A487)
B488: =IFERROR(INDEX(Materiales!$B$4:$B$484,MATCH("#"&$A488,Materiales!$K$4:$K$484,0)),"") | M488: =IF(A488="","","#"&A488)
B489: =IFERROR(INDEX(Materiales!$B$4:$B$484,MATCH("#"&$A489,Materiales!$K$4:$K$484,0)),"") | M489: =IF(A489="","","#"&A489)
B490: =IFERROR(INDEX(Materiales!$B$4:$B$484,MATCH("#"&$A490,Materiales!$K$4:$K$484,0)),"") | M490: =IF(A490="","","#"&A490)
B491: =IFERROR(INDEX(Materiales!$B$4:$B$484,MATCH("#"&$A491,Materiales!$K$4:$K$484,0)),"") | M491: =IF(A491="","","#"&A491)
B492: =IFERROR(INDEX(Materiales!$B$4:$B$484,MATCH("#"&$A492,Materiales!$K$4:$K$484,0)),"") | M492: =IF(A492="","","#"&A492)
B493: =IFERROR(INDEX(Materiales!$B$4:$B$484,MATCH("#"&$A493,Materiales!$K$4:$K$484,0)),"") | M493: =IF(A493="","","#"&A493)
B494: =IFERROR(INDEX(Materiales!$B$4:$B$484,MATCH("#"&$A494,Materiales!$K$4:$K$484,0)),"") | M494: =IF(A494="","","#"&A494)
B495: =IFERROR(INDEX(Materiales!$B$4:$B$484,MATCH("#"&$A495,Materiales!$K$4:$K$484,0)),"") | M495: =IF(A495="","","#"&A495)
B496: =IFERROR(INDEX(Materiales!$B$4:$B$484,MATCH("#"&$A496,Materiales!$K$4:$K$484,0)),"") | M496: =IF(A496="","","#"&A496)
B497: =IFERROR(INDEX(Materiales!$B$4:$B$484,MATCH("#"&$A497,Materiales!$K$4:$K$484,0)),"") | M497: =IF(A497="","","#"&A497)
... B505: =IFERROR(INDEX(Materiales!$B$4:$B$484,MATCH("#"&$A505,Materiales!$K$4:$K$484,0)),"") | M505: =IF(A505="","","#"&A505)

Sheet MRP
A1: CALCULO MRP — no escribas en esta hoja
A2: Un bloque de 6 renglones por item. Lee el renglon verde: es la semana en que debes pedir.
E3: =Plan!E$3 | F3: =Plan!F$3 | G3: =Plan!G$3 | H3: =Plan!H$3 | I3: =Plan!I$3 | J3: =Plan!J$3 | K3: =Plan!K$3 | L3: =Plan!L$3
A4: Codigo | B4: Producto | C4: Concepto | D4: Inicial / hoy | E4: Sem 1 | F4: Sem 2 | G4: Sem 3 | H4: Sem 4 | I4: Sem 5 | J4: Sem 6 | K4: Sem 7 | L4: Sem 8 | M4: Alerta
A5: =IF(Materiales!$A$4="","",Materiales!$A$4) | B5: =IF(Materiales!$B$4="","",Materiales!$B$4) | C5: Necesidad bruta | E5: =ROUND(SUMIF(Consumo!$P$4:$P$189,"#"&$A5,Consumo!H$4:H$189),4) | F5: =ROUND(SUMIF(Consumo!$P$4:$P$189,"#"&$A5,Consumo!I$4:I$189),4) | G5: =ROUND(SUMIF(Consumo!$P$4:$P$189,"#"&$A5,Consumo!J$4:J$189),4) | H5: =ROUND(SUMIF(Consumo!$P$4:$P$189,"#"&$A5,Consumo!K$4:K$189),4) | I5: =ROUND(SUMIF(Consumo!$P$4:$P$189,"#"&$A5,Consumo!L$4:L$189),4) | J5: =ROUND(SUMIF(Consumo!$P$4:$P$189,"#"&$A5,Consumo!M$4:M$189),4) | K5: =ROUND(SUMIF(Consumo!$P$4:$P$189,"#"&$A5,Consumo!N$4:N$189),4) | L5: =ROUND(SUMIF(Consumo!$P$4:$P$189,"#"&$A5,Consumo!O$4:O$189),4)
C6: Recepciones programadas (ya pedido) | E6: =SUMIF(Inventario!$M$5:$M$505,"#"&$A5,Inventario!E$5:E$505) | F6: =SUMIF(Inventario!$M$5:$M$505,"#"&$A5,Inventario!F$5:F$505) | G6: =SUMIF(Inventario!$M$5:$M$505,"#"&$A5,Inventario!G$5:G$505) | H6: =SUMIF(Inventario!$M$5:$M$505,"#"&$A5,Inventario!H$5:H$505) | I6: =SUMIF(Inventario!$M$5:$M$505,"#"&$A5,Inventario!I$5:I$505) | J6: =SUMIF(Inventario!$M$5:$M$505,"#"&$A5,Inventario!J$5:J$505) | K6: =SUMIF(Inventario!$M$5:$M$505,"#"&$A5,Inventario!K$5:K$505) | L6: =SUMIF(Inventario!$M$5:$M$505,"#"&$A5,Inventario!L$5:L$505)
C7: Stock proyectado disponible | D7: =SUMIF(Inventario!$M$5:$M$505,"#"&$A5,Inventario!$C$5:$C$505) | E7: =D7+E6+E9-E5 | F7: =E7+F6+F9-F5 | G7: =F7+G6+G9-G5 | H7: =G7+H6+H9-H5 | I7: =H7+I6+I9-I5 | J7: =I7+J6+J9-J5 | K7: =J7+K6+K9-K5 | L7: =K7+L6+L9-L5
C8: Necesidad neta | E8: =MAX(0,ROUND(E5+Materiales!$H$4-D7-E6,4)) | F8: =MAX(0,ROUND(F5+Materiales!$H$4-E7-F6,4)) | G8: =MAX(0,ROUND(G5+Materiales!$H$4-F7-G6,4)) | H8: =MAX(0,ROUND(H5+Materiales!$H$4-G7-H6,4)) | I8: =MAX(0,ROUND(I5+Materiales!$H$4-H7-I6,4)) | J8: =MAX(0,ROUND(J5+Materiales!$H$4-I7-J6,4)) | K8: =MAX(0,ROUND(K5+Materiales!$H$4-J7-K6,4)) | L8: =MAX(0,ROUND(L5+Materiales!$H$4-K7-L6,4))
C9: Recepcion de orden planificada | E9: =IF(E8<=0,0,IF(Materiales!$G$4<=0,E8,ROUNDUP(E8/Materiales!$G$4,0)*Materiales!$G$4)) | F9: =IF(F8<=0,0,IF(Materiales!$G$4<=0,F8,ROUNDUP(F8/Materiales!$G$4,0)*Materiales!$G$4)) | G9: =IF(G8<=0,0,IF(Materiales!$G$4<=0,G8,ROUNDUP(G8/Materiales!$G$4,0)*Materiales!$G$4)) | H9: =IF(H8<=0,0,IF(Materiales!$G$4<=0,H8,ROUNDUP(H8/Materiales!$G$4,0)*Materiales!$G$4)) | I9: =IF(I8<=0,0,IF(Materiales!$G$4<=0,I8,ROUNDUP(I8/Materiales!$G$4,0)*Materiales!$G$4)) | J9: =IF(J8<=0,0,IF(Materiales!$G$4<=0,J8,ROUNDUP(J8/Materiales!$G$4,0)*Materiales!$G$4)) | K9: =IF(K8<=0,0,IF(Materiales!$G$4<=0,K8,ROUNDUP(K8/Materiales!$G$4,0)*Materiales!$G$4)) | L9: =IF(L8<=0,0,IF(Materiales!$G$4<=0,L8,ROUNDUP(L8/Materiales!$G$4,0)*Materiales!$G$4))
C10: LANZAMIENTO DE ORDEN — pedir esta semana | E10: =IF(1+Materiales!$F$4>8,0,INDEX($E$9:$L$9,1,1+Materiales!$F$4)) | F10: =IF(2+Materiales!$F$4>8,0,INDEX($E$9:$L$9,1,2+Materiales!$F$4)) | G10: =IF(3+Materiales!$F$4>8,0,INDEX($E$9:$L$9,1,3+Materiales!$F$4)) | H10: =IF(4+Materiales!$F$4>8,0,INDEX($E$9:$L$9,1,4+Materiales!$F$4)) | I10: =IF(5+Materiales!$F$4>8,0,INDEX($E$9:$L$9,1,5+Materiales!$F$4)) | J10: =IF(6+Materiales!$F$4>8,0,INDEX($E$9:$L$9,1,6+Materiales!$F$4)) | K10: =IF(7+Materiales!$F$4>8,0,INDEX($E$9:$L$9,1,7+Materiales!$F$4)) | L10: =IF(8+Materiales!$F$4>8,0,INDEX($E$9:$L$9,1,8+Materiales!$F$4)) | M10: =IF($A5="","",IF(SUMPRODUCT((COLUMN($E$9:$L$9)-4<=Materiales!$F$4)*$E$9:$L$9)>0,"PEDIR YA (atrasado)","OK"))
A12: =IF(Materiales!$A$5="","",Materiales!$A$5) | B12: =IF(Materiales!$B$5="","",Materiales!$B$5) | C12: Necesidad bruta | E12: =ROUND(SUMIF(Consumo!$P$4:$P$189,"#"&$A12,Consumo!H$4:H$189),4) | F12: =ROUND(SUMIF(Consumo!$P$4:$P$189,"#"&$A12,Consumo!I$4:I$189),4) | G12: =ROUND(SUMIF(Consumo!$P$4:$P$189,"#"&$A12,Consumo!J$4:J$189),4) | H12: =ROUND(SUMIF(Consumo!$P$4:$P$189,"#"&$A12,Consumo!K$4:K$189),4) | I12: =ROUND(SUMIF(Consumo!$P$4:$P$189,"#"&$A12,Consumo!L$4:L$189),4) | J12: =ROUND(SUMIF(Consumo!$P$4:$P$189,"#"&$A12,Consumo!M$4:M$189),4) | K12: =ROUND(SUMIF(Consumo!$P$4:$P$189,"#"&$A12,Consumo!N$4:N$189),4) | L12: =ROUND(SUMIF(Consumo!$P$4:$P$189,"#"&$A12,Consumo!O$4:O$189),4)
C13: Recepciones programadas (ya pedido) | E13: =SUMIF(Inventario!$M$5:$M$505,"#"&$A12,Inventario!E$5:E$505) | F13: =SUMIF(Inventario!$M$5:$M$505,"#"&$A12,Inventario!F$5:F$505) | G13: =SUMIF(Inventario!$M$5:$M$505,"#"&$A12,Inventario!G$5:G$505) | H13: =SUMIF(Inventario!$M$5:$M$505,"#"&$A12,Inventario!H$5:H$505) | I13: =SUMIF(Inventario!$M$5:$M$505,"#"&$A12,Inventario!I$5:I$505) | J13: =SUMIF(Inventario!$M$5:$M$505,"#"&$A12,Inventario!J$5:J$505) | K13: =SUMIF(Inventario!$M$5:$M$505,"#"&$A12,Inventario!K$5:K$505) | L13: =SUMIF(Inventario!$M$5:$M$505,"#"&$A12,Inventario!L$5:L$505)
C14: Stock proyectado disponible | D14: =SUMIF(Inventario!$M$5:$M$505,"#"&$A12,Inventario!$C$5:$C$505) | E14: =D14+E13+E16-E12 | F14: =E14+F13+F16-F12 | G14: =F14+G13+G16-G12 | H14: =G14+H13+H16-H12 | I14: =H14+I13+I16-I12 | J14: =I14+J13+J16-J12 | K14: =J14+K13+K16-K12 | L14: =K14+L13+L16-L12
C15: Necesidad neta | E15: =MAX(0,ROUND(E12+Materiales!$H$5-D14-E13,4)) | F15: =MAX(0,ROUND(F12+Materiales!$H$5-E14-F13,4)) | G15: =MAX(0,ROUND(G12+Materiales!$H$5-F14-G13,4)) | H15: =MAX(0,ROUND(H12+Materiales!$H$5-G14-H13,4)) | I15: =MAX(0,ROUND(I12+Materiales!$H$5-H14-I13,4)) | J15: =MAX(0,ROUND(J12+Materiales!$H$5-I14-J13,4)) | K15: =MAX(0,ROUND(K12+Materiales!$H$5-J14-K13,4)) | L15: =MAX(0,ROUND(L12+Materiales!$H$5-K14-L13,4))
C16: Recepcion de orden planificada | E16: =IF(E15<=0,0,IF(Materiales!$G$5<=0,E15,ROUNDUP(E15/Materiales!$G$5,0)*Materiales!$G$5)) | F16: =IF(F15<=0,0,IF(Materiales!$G$5<=0,F15,ROUNDUP(F15/Materiales!$G$5,0)*Materiales!$G$5)) | G16: =IF(G15<=0,0,IF(Materiales!$G$5<=0,G15,ROUNDUP(G15/Materiales!$G$5,0)*Materiales!$G$5)) | H16: =IF(H15<=0,0,IF(Materiales!$G$5<=0,H15,ROUNDUP(H15/Materiales!$G$5,0)*Materiales!$G$5)) | I16: =IF(I15<=0,0,IF(Materiales!$G$5<=0,I15,ROUNDUP(I15/Materiales!$G$5,0)*Materiales!$G$5)) | J16: =IF(J15<=0,0,IF(Materiales!$G$5<=0,J15,ROUNDUP(J15/Materiales!$G$5,0)*Materiales!$G$5)) | K16: =IF(K15<=0,0,IF(Materiales!$G$5<=0,K15,ROUNDUP(K15/Materiales!$G$5,0)*Materiales!$G$5)) | L16: =IF(L15<=0,0,IF(Materiales!$G$5<=0,L15,ROUNDUP(L15/Materiales!$G$5,0)*Materiales!$G$5))
C17: LANZAMIENTO DE ORDEN — pedir esta semana | E17: =IF(1+Materiales!$F$5>8,0,INDEX($E$16:$L$16,1,1+Materiales!$F$5)) | F17: =IF(2+Materiales!$F$5>8,0,INDEX($E$16:$L$16,1,2+Materiales!$F$5)) | G17: =IF(3+Materiales!$F$5>8,0,INDEX($E$16:$L$16,1,3+Materiales!$F$5)) | H17: =IF(4+Materiales!$F$5>8,0,INDEX($E$16:$L$16,1,4+Materiales!$F$5)) | I17: =IF(5+Materiales!$F$5>8,0,INDEX($E$16:$L$16,1,5+Materiales!$F$5)) | J17: =IF(6+Materiales!$F$5>8,0,INDEX($E$16:$L$16,1,6+Materiales!$F$5)) | K17: =IF(7+Materiales!$F$5>8,0,INDEX($E$16:$L$16,1,7+Materiales!$F$5)) | L17: =IF(8+Materiales!$F$5>8,0,INDEX($E$16:$L$16,1,8+Materiales!$F$5)) | M17: =IF($A12="","",IF(SUMPRODUCT((COLUMN($E$16:$L$16)-4<=Materiales!$F$5)*$E$16:$L$16)>0,"PEDIR YA (atrasado)","OK"))
A19: =IF(Materiales!$A$6="","",Materiales!$A$6) | B19: =IF(Materiales!$B$6="","",Materiales!$B$6) | C19: Necesidad bruta | E19: =ROUND(SUMIF(Consumo!$P$4:$P$189,"#"&$A19,Consumo!H$4:H$189),4) | F19: =ROUND(SUMIF(Consumo!$P$4:$P$189,"#"&$A19,Consumo!I$4:I$189),4) | G19: =ROUND(SUMIF(Consumo!$P$4:$P$189,"#"&$A19,Consumo!J$4:J$189),4) | H19: =ROUND(SUMIF(Consumo!$P$4:$P$189,"#"&$A19,Consumo!K$4:K$189),4) | I19: =ROUND(SUMIF(Consumo!$P$4:$P$189,"#"&$A19,Consumo!L$4:L$189),4) | J19: =ROUND(SUMIF(Consumo!$P$4:$P$189,"#"&$A19,Consumo!M$4:M$189),4) | K19: =ROUND(SUMIF(Consumo!$P$4:$P$189,"#"&$A19,Consumo!N$4:N$189),4) | L19: =ROUND(SUMIF(Consumo!$P$4:$P$189,"#"&$A19,Consumo!O$4:O$189),4)
C20: Recepciones programadas (ya pedido) | E20: =SUMIF(Inventario!$M$5:$M$505,"#"&$A19,Inventario!E$5:E$505) | F20: =SUMIF(Inventario!$M$5:$M$505,"#"&$A19,Inventario!F$5:F$505) | G20: =SUMIF(Inventario!$M$5:$M$505,"#"&$A19,Inventario!G$5:G$505) | H20: =SUMIF(Inventario!$M$5:$M$505,"#"&$A19,Inventario!H$5:H$505) | I20: =SUMIF(Inventario!$M$5:$M$505,"#"&$A19,Inventario!I$5:I$505) | J20: =SUMIF(Inventario!$M$5:$M$505,"#"&$A19,Inventario!J$5:J$505) | K20: =SUMIF(Inventario!$M$5:$M$505,"#"&$A19,Inventario!K$5:K$505) | L20: =SUMIF(Inventario!$M$5:$M$505,"#"&$A19,Inventario!L$5:L$505)
C21: Stock proyectado disponible | D21: =SUMIF(Inventario!$M$5:$M$505,"#"&$A19,Inventario!$C$5:$C$505) | E21: =D21+E20+E23-E19 | F21: =E21+F20+F23-F19 | G21: =F21+G20+G23-G19 | H21: =G21+H20+H23-H19 | I21: =H21+I20+I23-I19 | J21: =I21+J20+J23-J19 | K21: =J21+K20+K23-K19 | L21: =K21+L20+L23-L19
C22: Necesidad neta | E22: =MAX(0,ROUND(E19+Materiales!$H$6-D21-E20,4)) | F22: =MAX(0,ROUND(F19+Materiales!$H$6-E21-F20,4)) | G22: =MAX(0,ROUND(G19+Materiales!$H$6-F21-G20,4)) | H22: =MAX(0,ROUND(H19+Materiales!$H$6-G21-H20,4)) | I22: =MAX(0,ROUND(I19+Materiales!$H$6-H21-I20,4)) | J22: =MAX(0,ROUND(J19+Materiales!$H$6-I21-J20,4)) | K22: =MAX(0,ROUND(K19+Materiales!$H$6-J21-K20,4)) | L22: =MAX(0,ROUND(L19+Materiales!$H$6-K21-L20,4))
C23: Recepcion de orden planificada | E23: =IF(E22<=0,0,IF(Materiales!$G$6<=0,E22,ROUNDUP(E22/Materiales!$G$6,0)*Materiales!$G$6)) | F23: =IF(F22<=0,0,IF(Materiales!$G$6<=0,F22,ROUNDUP(F22/Materiales!$G$6,0)*Materiales!$G$6)) | G23: =IF(G22<=0,0,IF(Materiales!$G$6<=0,G22,ROUNDUP(G22/Materiales!$G$6,0)*Materiales!$G$6)) | H23: =IF(H22<=0,0,IF(Materiales!$G$6<=0,H22,ROUNDUP(H22/Materiales!$G$6,0)*Materiales!$G$6)) | I23: =IF(I22<=0,0,IF(Materiales!$G$6<=0,I22,ROUNDUP(I22/Materiales!$G$6,0)*Materiales!$G$6)) | J23: =IF(J22<=0,0,IF(Materiales!$G$6<=0,J22,ROUNDUP(J22/Materiales!$G$6,0)*Materiales!$G$6)) | K23: =IF(K22<=0,0,IF(Materiales!$G$6<=0,K22,ROUNDUP(K22/Materiales!$G$6,0)*Materiales!$G$6)) | L23: =IF(L22<=0,0,IF(Materiales!$G$6<=0,L22,ROUNDUP(L22/Materiales!$G$6,0)*Materiales!$G$6))
C24: LANZAMIENTO DE ORDEN — pedir esta semana | E24: =IF(1+Materiales!$F$6>8,0,INDEX($E$23:$L$23,1,1+Materiales!$F$6)) | F24: =IF(2+Materiales!$F$6>8,0,INDEX($E$23:$L$23,1,2+Materiales!$F$6)) | G24: =IF(3+Materiales!$F$6>8,0,INDEX($E$23:$L$23,1,3+Materiales!$F$6)) | H24: =IF(4+Materiales!$F$6>8,0,INDEX($E$23:$L$23,1,4+Materiales!$F$6)) | I24: =IF(5+Materiales!$F$6>8,0,INDEX($E$23:$L$23,1,5+Materiales!$F$6)) | J24: =IF(6+Materiales!$F$6>8,0,INDEX($E$23:$L$23,1,6+Materiales!$F$6)) | K24: =IF(7+Materiales!$F$6>8,0,INDEX($E$23:$L$23,1,7+Materiales!$F$6)) | L24: =IF(8+Materiales!$F$6>8,0,INDEX($E$23:$L$23,1,8+Materiales!$F$6)) | M24: =IF($A19="","",IF(SUMPRODUCT((COLUMN($E$23:$L$23)-4<=Materiales!$F$6)*$E$23:$L$23)>0,"PEDIR YA (atrasado)","OK"))
A26: =IF(Materiales!$A$7="","",Materiales!$A$7) | B26: =IF(Materiales!$B$7="","",Materiales!$B$7) | C26: Necesidad bruta | E26: =ROUND(SUMIF(Consumo!$P$4:$P$189,"#"&$A26,Consumo!H$4:H$189),4) | F26: =ROUND(SUMIF(Consumo!$P$4:$P$189,"#"&$A26,Consumo!I$4:I$189),4) | G26: =ROUND(SUMIF(Consumo!$P$4:$P$189,"#"&$A26,Consumo!J$4:J$189),4) | H26: =ROUND(SUMIF(Consumo!$P$4:$P$189,"#"&$A26,Consumo!K$4:K$189),4) | I26: =ROUND(SUMIF(Consumo!$P$4:$P$189,"#"&$A26,Consumo!L$4:L$189),4) | J26: =ROUND(SUMIF(Consumo!$P$4:$P$189,"#"&$A26,Consumo!M$4:M$189),4) | K26: =ROUND(SUMIF(Consumo!$P$4:$P$189,"#"&$A26,Consumo!N$4:N$189),4) | L26: =ROUND(SUMIF(Consumo!$P$4:$P$189,"#"&$A26,Consumo!O$4:O$189),4)
C27: Recepciones programadas (ya pedido) | E27: =SUMIF(Inventario!$M$5:$M$505,"#"&$A26,Inventario!E$5:E$505) | F27: =SUMIF(Inventario!$M$5:$M$505,"#"&$A26,Inventario!F$5:F$505) | G27: =SUMIF(Inventario!$M$5:$M$505,"#"&$A26,Inventario!G$5:G$505) | H27: =SUMIF(Inventario!$M$5:$M$505,"#"&$A26,Inventario!H$5:H$505) | I27: =SUMIF(Inventario!$M$5:$M$505,"#"&$A26,Inventario!I$5:I$505) | J27: =SUMIF(Inventario!$M$5:$M$505,"#"&$A26,Inventario!J$5:J$505) | K27: =SUMIF(Inventario!$M$5:$M$505,"#"&$A26,Inventario!K$5:K$505) | L27: =SUMIF(Inventario!$M$5:$M$505,"#"&$A26,Inventario!L$5:L$505)
C28: Stock proyectado disponible | D28: =SUMIF(Inventario!$M$5:$M$505,"#"&$A26,Inventario!$C$5:$C$505) | E28: =D28+E27+E30-E26 | F28: =E28+F27+F30-F26 | G28: =F28+G27+G30-G26 | H28: =G28+H27+H30-H26 | I28: =H28+I27+I30-I26 | J28: =I28+J27+J30-J26 | K28: =J28+K27+K30-K26 | L28: =K28+L27+L30-L26
C29: Necesidad neta | E29: =MAX(0,ROUND(E26+Materiales!$H$7-D28-E27,4)) | F29: =MAX(0,ROUND(F26+Materiales!$H$7-E28-F27,4)) | G29: =MAX(0,ROUND(G26+Materiales!$H$7-F28-G27,4)) | H29: =MAX(0,ROUND(H26+Materiales!$H$7-G28-H27,4)) | I29: =MAX(0,ROUND(I26+Materiales!$H$7-H28-I27,4)) | J29: =MAX(0,ROUND(J26+Materiales!$H$7-I28-J27,4)) | K29: =MAX(0,ROUND(K26+Materiales!$H$7-J28-K27,4)) | L29: =MAX(0,ROUND(L26+Materiales!$H$7-K28-L27,4))
