Workbook

Sheet RESUMEN
A1: MEJORAS ALCANZADAS — CARMEX VS FANEL
A2: Unidad Palca · Temual · Control de voladura · Cambio de iniciador en CR NE y Rampa Brenda
A3: ALCANCE: solo disparos tipo AVANCE con KG TOTAL > 0, y SOLO en CR NE y Rampa Brenda — 43 disparos con Carmex (25/08–11/09) y 55 con Fanel (12/09–25/09). El cuadro resumen del reporte cuenta además ESCM 4410, ESCM 4435 y GL NW 4, por eso ahí figuran 66 y 62 disparos (95.50 y 96.86 m): las dos cifras son correctas y miden alcances distintos.
A6: OJO AL COMPARAR TOTALES: el avance total no se puede leer como mérito del iniciador, porque en el periodo Fanel se dispararon 55 veces y en el Carmex 43. Lo comparable es el METRAJE POR DISPARO y la regularidad.
A9: Indicador | B9: Unidad | C9: CARMEX | D9: FANEL | E9: Variación | F9: Deseado | G9: Evaluación
A10: N° de disparos de avance | B10: disp. | C10: =COUNTIFS(DATOS!$D$2:$D$99,"Carmex") | D10: =COUNTIFS(DATOS!$D$2:$D$99,"Fanel") | E10: =IF(C10=0,"",D10/C10-1) | F10: 0 | G10: =IF(F10=0,"Referencia",IF(SIGN(D10-C10)=F10,"MEJORA",IF(D10=C10,"IGUAL","RETROCESO")))
A11: Días con disparo | B11: días | C11: =15 | D11: =14 | E11: =IF(C11=0,"",D11/C11-1) | F11: 0 | G11: =IF(F11=0,"Referencia",IF(SIGN(D11-C11)=F11,"MEJORA",IF(D11=C11,"IGUAL","RETROCESO")))
A12: Avance total | B12: m | C12: =SUMIFS(DATOS!$E$2:$E$99,DATOS!$D$2:$D$99,"Carmex") | D12: =SUMIFS(DATOS!$E$2:$E$99,DATOS!$D$2:$D$99,"Fanel") | E12: =IF(C12=0,"",D12/C12-1) | F12: 0 | G12: =IF(F12=0,"Referencia",IF(SIGN(D12-C12)=F12,"MEJORA",IF(D12=C12,"IGUAL","RETROCESO")))
A13: Avance promedio por disparo | B13: m/disp. | C13: =AVERAGEIFS(DATOS!$E$2:$E$99,DATOS!$D$2:$D$99,"Carmex") | D13: =AVERAGEIFS(DATOS!$E$2:$E$99,DATOS!$D$2:$D$99,"Fanel") | E13: =IF(C13=0,"",D13/C13-1) | F13: 1 | G13: =IF(F13=0,"Referencia",IF(SIGN(D13-C13)=F13,"MEJORA",IF(D13=C13,"IGUAL","RETROCESO")))
A14: Desviación estándar del avance | B14: m | C14: =STDEV(DATOS!$N$2:$N$99) | D14: =STDEV(DATOS!$O$2:$O$99) | E14: =IF(C14=0,"",D14/C14-1) | F14: -1 | G14: =IF(F14=0,"Referencia",IF(SIGN(D14-C14)=F14,"MEJORA",IF(D14=C14,"IGUAL","RETROCESO")))
A15: Avance mínimo | B15: m | C15: =MIN(DATOS!$N$2:$N$99) | D15: =MIN(DATOS!$O$2:$O$99) | E15: =IF(C15=0,"",D15/C15-1) | F15: 1 | G15: =IF(F15=0,"Referencia",IF(SIGN(D15-C15)=F15,"MEJORA",IF(D15=C15,"IGUAL","RETROCESO")))
A16: Avance máximo | B16: m | C16: =MAX(DATOS!$N$2:$N$99) | D16: =MAX(DATOS!$O$2:$O$99) | E16: =IF(C16=0,"",D16/C16-1) | F16: 1 | G16: =IF(F16=0,"Referencia",IF(SIGN(D16-C16)=F16,"MEJORA",IF(D16=C16,"IGUAL","RETROCESO")))
A17: Eficiencia de voladura | B17: % | C17: =AVERAGEIFS(DATOS!$E$2:$E$99,DATOS!$D$2:$D$99,"Carmex")/1.755648 | D17: =AVERAGEIFS(DATOS!$E$2:$E$99,DATOS!$D$2:$D$99,"Fanel")/1.755648 | E17: =IF(C17=0,"",D17/C17-1) | F17: 1 | G17: =IF(F17=0,"Referencia",IF(SIGN(D17-C17)=F17,"MEJORA",IF(D17=C17,"IGUAL","RETROCESO")))
A18: Disparos deficientes (< 1.40 m) | B18: disp. | C18: =COUNTIFS(DATOS!$D$2:$D$99,"Carmex",DATOS!$E$2:$E$99,"<1.4") | D18: =COUNTIFS(DATOS!$D$2:$D$99,"Fanel",DATOS!$E$2:$E$99,"<1.4") | E18: =IF(C18=0,"",D18/C18-1) | F18: -1 | G18: =IF(F18=0,"Referencia",IF(SIGN(D18-C18)=F18,"MEJORA",IF(D18=C18,"IGUAL","RETROCESO")))
A19: Explosivo total consumido | B19: kg | C19: =SUMIFS(DATOS!$H$2:$H$99,DATOS!$D$2:$D$99,"Carmex") | D19: =SUMIFS(DATOS!$H$2:$H$99,DATOS!$D$2:$D$99,"Fanel") | E19: =IF(C19=0,"",D19/C19-1) | F19: 0 | G19: =IF(F19=0,"Referencia",IF(SIGN(D19-C19)=F19,"MEJORA",IF(D19=C19,"IGUAL","RETROCESO")))
A20: Explosivo por disparo | B20: kg/disp. | C20: =AVERAGEIFS(DATOS!$H$2:$H$99,DATOS!$D$2:$D$99,"Carmex") | D20: =AVERAGEIFS(DATOS!$H$2:$H$99,DATOS!$D$2:$D$99,"Fanel") | E20: =IF(C20=0,"",D20/C20-1) | F20: -1 | G20: =IF(F20=0,"Referencia",IF(SIGN(D20-C20)=F20,"MEJORA",IF(D20=C20,"IGUAL","RETROCESO")))
A21: Volumen real roto | B21: m³ | C21: =SUMIFS(DATOS!$I$2:$I$99,DATOS!$D$2:$D$99,"Carmex") | D21: =SUMIFS(DATOS!$I$2:$I$99,DATOS!$D$2:$D$99,"Fanel") | E21: =IF(C21=0,"",D21/C21-1) | F21: 1 | G21: =IF(F21=0,"Referencia",IF(SIGN(D21-C21)=F21,"MEJORA",IF(D21=C21,"IGUAL","RETROCESO")))
A22: Factor de carga real | B22: kg/m³ | C22: =SUMIFS(DATOS!$H$2:$H$99,DATOS!$D$2:$D$99,"Carmex")/SUMIFS(DATOS!$I$2:$I$99,DATOS!$D$2:$D$99,"Carmex") | D22: =SUMIFS(DATOS!$H$2:$H$99,DATOS!$D$2:$D$99,"Fanel")/SUMIFS(DATOS!$I$2:$I$99,DATOS!$D$2:$D$99,"Fanel") | E22: =IF(C22=0,"",D22/C22-1) | F22: -1 | G22: =IF(F22=0,"Referencia",IF(SIGN(D22-C22)=F22,"MEJORA",IF(D22=C22,"IGUAL","RETROCESO")))
A23: Factor de avance (explosivo por metro) | B23: kg/m | C23: =SUMIFS(DATOS!$H$2:$H$99,DATOS!$D$2:$D$99,"Carmex")/SUMIFS(DATOS!$E$2:$E$99,DATOS!$D$2:$D$99,"Carmex") | D23: =SUMIFS(DATOS!$H$2:$H$99,DATOS!$D$2:$D$99,"Fanel")/SUMIFS(DATOS!$E$2:$E$99,DATOS!$D$2:$D$99,"Fanel") | E23: =IF(C23=0,"",D23/C23-1) | F23: -1 | G23: =IF(F23=0,"Referencia",IF(SIGN(D23-C23)=F23,"MEJORA",IF(D23=C23,"IGUAL","RETROCESO")))
A24: Sobrerotura promedio | B24: % | C24: =AVERAGEIFS(DATOS!$J$2:$J$99,DATOS!$D$2:$D$99,"Carmex") | D24: =AVERAGEIFS(DATOS!$J$2:$J$99,DATOS!$D$2:$D$99,"Fanel") | E24: =IF(C24=0,"",D24/C24-1) | F24: -1 | G24: =IF(F24=0,"Referencia",IF(SIGN(D24-C24)=F24,"MEJORA",IF(D24=C24,"IGUAL","RETROCESO")))
A26: Fuente: REPORTE CONTROL DE VOLADURA UNIDAD PALCA – TEMUAL – SETIEMBRE, hoja BASE DE DATOS. Eficiencia = avance / perforación efectiva (6 pies × 0.3048 × 96% = 1.756 m). Factores calculados como cociente de totales.

Sheet DATOS
A1: Fecha | B1: Turno | C1: Labor | D1: Periodo | E1: Avance (m) | F1: Perf. efectiva (m) | G1: Eficiencia | H1: Explosivo (kg) | I1: Volumen roto (m³) | J1: Sobrerotura | K1: kg/m | L1: N° disparo del periodo | M1: Acumulado del periodo (m) | N1: Avance si Carmex | O1: Avance si Fanel
A2: 2026-08-25 | B2: D | C2: CR NE | D2: Carmex | E2: 1.5 | F2: 1.755648 | G2: =IF(F2=0,"",E2/F2) | H2: 39.443 | I2: 15.359 | J2: 0.137678 | K2: =IF(E2=0,"",H2/E2) | L2: =COUNTIF($D$2:$D2,D2) | M2: =SUMIFS($E$2:$E2,$D$2:$D2,D2) | N2: =IF(D2="Carmex",E2,"") | O2: =IF(D2="Fanel",E2,"")
A3: 2026-08-25 | B3: D | C3: Rampa Brenda | D3: Carmex | E3: 1.5 | F3: 1.755648 | G3: =IF(F3=0,"",E3/F3) | H3: 36.641 | I3: 20.757 | J3: 0.129657 | K3: =IF(E3=0,"",H3/E3) | L3: =COUNTIF($D$2:$D3,D3) | M3: =SUMIFS($E$2:$E3,$D$2:$D3,D3) | N3: =IF(D3="Carmex",E3,"") | O3: =IF(D3="Fanel",E3,"")
A4: 2026-08-26 | B4: N | C4: CR NE | D4: Carmex | E4: 1.48 | F4: 1.755648 | G4: =IF(F4=0,"",E4/F4) | H4: 39.443 | I4: 15.154 | J4: 0.137678 | K4: =IF(E4=0,"",H4/E4) | L4: =COUNTIF($D$2:$D4,D4) | M4: =SUMIFS($E$2:$E4,$D$2:$D4,D4) | N4: =IF(D4="Carmex",E4,"") | O4: =IF(D4="Fanel",E4,"")
A5: 2026-08-26 | B5: N | C5: CR NE | D5: Carmex | E5: 1.48 | F5: 1.755648 | G5: =IF(F5=0,"",E5/F5) | H5: 39.443 | I5: 15.154 | J5: 0.137678 | K5: =IF(E5=0,"",H5/E5) | L5: =COUNTIF($D$2:$D5,D5) | M5: =SUMIFS($E$2:$E5,$D$2:$D5,D5) | N5: =IF(D5="Carmex",E5,"") | O5: =IF(D5="Fanel",E5,"")
A6: 2026-08-26 | B6: D | C6: CR NE | D6: Carmex | E6: 1.5 | F6: 1.755648 | G6: =IF(F6=0,"",E6/F6) | H6: 39.443 | I6: 15.359 | J6: 0.137678 | K6: =IF(E6=0,"",H6/E6) | L6: =COUNTIF($D$2:$D6,D6) | M6: =SUMIFS($E$2:$E6,$D$2:$D6,D6) | N6: =IF(D6="Carmex",E6,"") | O6: =IF(D6="Fanel",E6,"")
A7: 2026-08-26 | B7: N | C7: Rampa Brenda | D7: Carmex | E7: 1.49 | F7: 1.755648 | G7: =IF(F7=0,"",E7/F7) | H7: 36.641 | I7: 20.619 | J7: 0.129657 | K7: =IF(E7=0,"",H7/E7) | L7: =COUNTIF($D$2:$D7,D7) | M7: =SUMIFS($E$2:$E7,$D$2:$D7,D7) | N7: =IF(D7="Carmex",E7,"") | O7: =IF(D7="Fanel",E7,"")
A8: 2026-08-26 | B8: D | C8: Rampa Brenda | D8: Carmex | E8: 1.5 | F8: 1.755648 | G8: =IF(F8=0,"",E8/F8) | H8: 36.641 | I8: 20.757 | J8: 0.129657 | K8: =IF(E8=0,"",H8/E8) | L8: =COUNTIF($D$2:$D8,D8) | M8: =SUMIFS($E$2:$E8,$D$2:$D8,D8) | N8: =IF(D8="Carmex",E8,"") | O8: =IF(D8="Fanel",E8,"")
A9: 2026-08-27 | B9: N | C9: CR NE | D9: Carmex | E9: 1.58 | F9: 1.755648 | G9: =IF(F9=0,"",E9/F9) | H9: 39.443 | I9: 16.178 | J9: 0.137678 | K9: =IF(E9=0,"",H9/E9) | L9: =COUNTIF($D$2:$D9,D9) | M9: =SUMIFS($E$2:$E9,$D$2:$D9,D9) | N9: =IF(D9="Carmex",E9,"") | O9: =IF(D9="Fanel",E9,"")
A10: 2026-08-27 | B10: D | C10: CR NE | D10: Carmex | E10: 1.48 | F10: 1.755648 | G10: =IF(F10=0,"",E10/F10) | H10: 39.443 | I10: 15.154 | J10: 0.137678 | K10: =IF(E10=0,"",H10/E10) | L10: =COUNTIF($D$2:$D10,D10) | M10: =SUMIFS($E$2:$E10,$D$2:$D10,D10) | N10: =IF(D10="Carmex",E10,"") | O10: =IF(D10="Fanel",E10,"")
A11: 2026-08-27 | B11: N | C11: Rampa Brenda | D11: Carmex | E11: 1.48 | F11: 1.755648 | G11: =IF(F11=0,"",E11/F11) | H11: 36.641 | I11: 20.481 | J11: 0.129657 | K11: =IF(E11=0,"",H11/E11) | L11: =COUNTIF($D$2:$D11,D11) | M11: =SUMIFS($E$2:$E11,$D$2:$D11,D11) | N11: =IF(D11="Carmex",E11,"") | O11: =IF(D11="Fanel",E11,"")
A12: 2026-08-27 | B12: D | C12: Rampa Brenda | D12: Carmex | E12: 1.51 | F12: 1.755648 | G12: =IF(F12=0,"",E12/F12) | H12: 36.641 | I12: 20.896 | J12: 0.129657 | K12: =IF(E12=0,"",H12/E12) | L12: =COUNTIF($D$2:$D12,D12) | M12: =SUMIFS($E$2:$E12,$D$2:$D12,D12) | N12: =IF(D12="Carmex",E12,"") | O12: =IF(D12="Fanel",E12,"")
A13: 2026-08-28 | B13: N | C13: CR NE | D13: Carmex | E13: 1.48 | F13: 1.755648 | G13: =IF(F13=0,"",E13/F13) | H13: 39.443 | I13: 15.154 | J13: 0.137678 | K13: =IF(E13=0,"",H13/E13) | L13: =COUNTIF($D$2:$D13,D13) | M13: =SUMIFS($E$2:$E13,$D$2:$D13,D13) | N13: =IF(D13="Carmex",E13,"") | O13: =IF(D13="Fanel",E13,"")
... A99: 2026-09-25 | B99: D | C99: Rampa Brenda | D99: Fanel | E99: 1.49 | F99: 1.755648 | G99: =IF(F99=0,"",E99/F99) | H99: 36.641 | I99: 20.619 | J99: 0.129657 | K99: =IF(E99=0,"",H99/E99) | L99: =COUNTIF($D$2:$D99,D99) | M99: =SUMIFS($E$2:$E99,$D$2:$D99,D99) | N99: =IF(D99="Carmex",E99,"") | O99: =IF(D99="Fanel",E99,"")

Sheet CURVA S
A1: CURVA S · AVANCE ACUMULADO POR DISPARO
A2: Acumulado contra el NÚMERO DE DISPAROS, no contra los días. En estas dos labores se disparó a ritmos distintos (2.87 por día con Carmex y 3.93 con Fanel) porque en el periodo Fanel la unidad concentró aquí el trabajo: GL NW 4 pasó de 15 disparos a ninguno y CR NE subió de 22 a 35. Contar por día mezclaría ese traslado de frentes con lo que aporta el iniciador; contado por disparo, la pendiente de cada curva ES el metraje por disparo.
A8: N° disparo | B8: Carmex (m acum.) | C8: Fanel (m acum.)
A9: 1 | B9: =IF(1>43,NA(),SUMIFS(DATOS!$E$2:$E$99,DATOS!$D$2:$D$99,"Carmex",DATOS!$L$2:$L$99,"<="&A9)) | C9: =IF(1>55,NA(),SUMIFS(DATOS!$E$2:$E$99,DATOS!$D$2:$D$99,"Fanel",DATOS!$L$2:$L$99,"<="&A9))
A10: 2 | B10: =IF(2>43,NA(),SUMIFS(DATOS!$E$2:$E$99,DATOS!$D$2:$D$99,"Carmex",DATOS!$L$2:$L$99,"<="&A10)) | C10: =IF(2>55,NA(),SUMIFS(DATOS!$E$2:$E$99,DATOS!$D$2:$D$99,"Fanel",DATOS!$L$2:$L$99,"<="&A10))
A11: 3 | B11: =IF(3>43,NA(),SUMIFS(DATOS!$E$2:$E$99,DATOS!$D$2:$D$99,"Carmex",DATOS!$L$2:$L$99,"<="&A11)) | C11: =IF(3>55,NA(),SUMIFS(DATOS!$E$2:$E$99,DATOS!$D$2:$D$99,"Fanel",DATOS!$L$2:$L$99,"<="&A11))
A12: 4 | B12: =IF(4>43,NA(),SUMIFS(DATOS!$E$2:$E$99,DATOS!$D$2:$D$99,"Carmex",DATOS!$L$2:$L$99,"<="&A12)) | C12: =IF(4>55,NA(),SUMIFS(DATOS!$E$2:$E$99,DATOS!$D$2:$D$99,"Fanel",DATOS!$L$2:$L$99,"<="&A12))
A13: 5 | B13: =IF(5>43,NA(),SUMIFS(DATOS!$E$2:$E$99,DATOS!$D$2:$D$99,"Carmex",DATOS!$L$2:$L$99,"<="&A13)) | C13: =IF(5>55,NA(),SUMIFS(DATOS!$E$2:$E$99,DATOS!$D$2:$D$99,"Fanel",DATOS!$L$2:$L$99,"<="&A13))
A14: 6 | B14: =IF(6>43,NA(),SUMIFS(DATOS!$E$2:$E$99,DATOS!$D$2:$D$99,"Carmex",DATOS!$L$2:$L$99,"<="&A14)) | C14: =IF(6>55,NA(),SUMIFS(DATOS!$E$2:$E$99,DATOS!$D$2:$D$99,"Fanel",DATOS!$L$2:$L$99,"<="&A14))
A15: 7 | B15: =IF(7>43,NA(),SUMIFS(DATOS!$E$2:$E$99,DATOS!$D$2:$D$99,"Carmex",DATOS!$L$2:$L$99,"<="&A15)) | C15: =IF(7>55,NA(),SUMIFS(DATOS!$E$2:$E$99,DATOS!$D$2:$D$99,"Fanel",DATOS!$L$2:$L$99,"<="&A15))
A16: 8 | B16: =IF(8>43,NA(),SUMIFS(DATOS!$E$2:$E$99,DATOS!$D$2:$D$99,"Carmex",DATOS!$L$2:$L$99,"<="&A16)) | C16: =IF(8>55,NA(),SUMIFS(DATOS!$E$2:$E$99,DATOS!$D$2:$D$99,"Fanel",DATOS!$L$2:$L$99,"<="&A16))
A17: 9 | B17: =IF(9>43,NA(),SUMIFS(DATOS!$E$2:$E$99,DATOS!$D$2:$D$99,"Carmex",DATOS!$L$2:$L$99,"<="&A17)) | C17: =IF(9>55,NA(),SUMIFS(DATOS!$E$2:$E$99,DATOS!$D$2:$D$99,"Fanel",DATOS!$L$2:$L$99,"<="&A17))
A18: 10 | B18: =IF(10>43,NA(),SUMIFS(DATOS!$E$2:$E$99,DATOS!$D$2:$D$99,"Carmex",DATOS!$L$2:$L$99,"<="&A18)) | C18: =IF(10>55,NA(),SUMIFS(DATOS!$E$2:$E$99,DATOS!$D$2:$D$99,"Fanel",DATOS!$L$2:$L$99,"<="&A18))
A19: 11 | B19: =IF(11>43,NA(),SUMIFS(DATOS!$E$2:$E$99,DATOS!$D$2:$D$99,"Carmex",DATOS!$L$2:$L$99,"<="&A19)) | C19: =IF(11>55,NA(),SUMIFS(DATOS!$E$2:$E$99,DATOS!$D$2:$D$99,"Fanel",DATOS!$L$2:$L$99,"<="&A19))
A20: 12 | B20: =IF(12>43,NA(),SUMIFS(DATOS!$E$2:$E$99,DATOS!$D$2:$D$99,"Carmex",DATOS!$L$2:$L$99,"<="&A20)) | C20: =IF(12>55,NA(),SUMIFS(DATOS!$E$2:$E$99,DATOS!$D$2:$D$99,"Fanel",DATOS!$L$2:$L$99,"<="&A20))
A21: 13 | B21: =IF(13>43,NA(),SUMIFS(DATOS!$E$2:$E$99,DATOS!$D$2:$D$99,"Carmex",DATOS!$L$2:$L$99,"<="&A21)) | C21: =IF(13>55,NA(),SUMIFS(DATOS!$E$2:$E$99,DATOS!$D$2:$D$99,"Fanel",DATOS!$L$2:$L$99,"<="&A21))
A22: 14 | B22: =IF(14>43,NA(),SUMIFS(DATOS!$E$2:$E$99,DATOS!$D$2:$D$99,"Carmex",DATOS!$L$2:$L$99,"<="&A22)) | C22: =IF(14>55,NA(),SUMIFS(DATOS!$E$2:$E$99,DATOS!$D$2:$D$99,"Fanel",DATOS!$L$2:$L$99,"<="&A22))
A23: 15 | B23: =IF(15>43,NA(),SUMIFS(DATOS!$E$2:$E$99,DATOS!$D$2:$D$99,"Carmex",DATOS!$L$2:$L$99,"<="&A23)) | C23: =IF(15>55,NA(),SUMIFS(DATOS!$E$2:$E$99,DATOS!$D$2:$D$99,"Fanel",DATOS!$L$2:$L$99,"<="&A23))
A24: 16 | B24: =IF(16>43,NA(),SUMIFS(DATOS!$E$2:$E$99,DATOS!$D$2:$D$99,"Carmex",DATOS!$L$2:$L$99,"<="&A24)) | C24: =IF(16>55,NA(),SUMIFS(DATOS!$E$2:$E$99,DATOS!$D$2:$D$99,"Fanel",DATOS!$L$2:$L$99,"<="&A24))
A25: 17 | B25: =IF(17>43,NA(),SUMIFS(DATOS!$E$2:$E$99,DATOS!$D$2:$D$99,"Carmex",DATOS!$L$2:$L$99,"<="&A25)) | C25: =IF(17>55,NA(),SUMIFS(DATOS!$E$2:$E$99,DATOS!$D$2:$D$99,"Fanel",DATOS!$L$2:$L$99,"<="&A25))
A26: 18 | B26: =IF(18>43,NA(),SUMIFS(DATOS!$E$2:$E$99,DATOS!$D$2:$D$99,"Carmex",DATOS!$L$2:$L$99,"<="&A26)) | C26: =IF(18>55,NA(),SUMIFS(DATOS!$E$2:$E$99,DATOS!$D$2:$D$99,"Fanel",DATOS!$L$2:$L$99,"<="&A26))
A27: 19 | B27: =IF(19>43,NA(),SUMIFS(DATOS!$E$2:$E$99,DATOS!$D$2:$D$99,"Carmex",DATOS!$L$2:$L$99,"<="&A27)) | C27: =IF(19>55,NA(),SUMIFS(DATOS!$E$2:$E$99,DATOS!$D$2:$D$99,"Fanel",DATOS!$L$2:$L$99,"<="&A27))
A28: 20 | B28: =IF(20>43,NA(),SUMIFS(DATOS!$E$2:$E$99,DATOS!$D$2:$D$99,"Carmex",DATOS!$L$2:$L$99,"<="&A28)) | C28: =IF(20>55,NA(),SUMIFS(DATOS!$E$2:$E$99,DATOS!$D$2:$D$99,"Fanel",DATOS!$L$2:$L$99,"<="&A28))
A29: 21 | B29: =IF(21>43,NA(),SUMIFS(DATOS!$E$2:$E$99,DATOS!$D$2:$D$99,"Carmex",DATOS!$L$2:$L$99,"<="&A29)) | C29: =IF(21>55,NA(),SUMIFS(DATOS!$E$2:$E$99,DATOS!$D$2:$D$99,"Fanel",DATOS!$L$2:$L$99,"<="&A29))
A30: 22 | B30: =IF(22>43,NA(),SUMIFS(DATOS!$E$2:$E$99,DATOS!$D$2:$D$99,"Carmex",DATOS!$L$2:$L$99,"<="&A30)) | C30: =IF(22>55,NA(),SUMIFS(DATOS!$E$2:$E$99,DATOS!$D$2:$D$99,"Fanel",DATOS!$L$2:$L$99,"<="&A30))
A31: 23 | B31: =IF(23>43,NA(),SUMIFS(DATOS!$E$2:$E$99,DATOS!$D$2:$D$99,"Carmex",DATOS!$L$2:$L$99,"<="&A31)) | C31: =IF(23>55,NA(),SUMIFS(DATOS!$E$2:$E$99,DATOS!$D$2:$D$99,"Fanel",DATOS!$L$2:$L$99,"<="&A31))
A32: 24 | B32: =IF(24>43,NA(),SUMIFS(DATOS!$E$2:$E$99,DATOS!$D$2:$D$99,"Carmex",DATOS!$L$2:$L$99,"<="&A32)) | C32: =IF(24>55,NA(),SUMIFS(DATOS!$E$2:$E$99,DATOS!$D$2:$D$99,"Fanel",DATOS!$L$2:$L$99,"<="&A32))
A33: 25 | B33: =IF(25>43,NA(),SUMIFS(DATOS!$E$2:$E$99,DATOS!$D$2:$D$99,"Carmex",DATOS!$L$2:$L$99,"<="&A33)) | C33: =IF(25>55,NA(),SUMIFS(DATOS!$E$2:$E$99,DATOS!$D$2:$D$99,"Fanel",DATOS!$L$2:$L$99,"<="&A33))
A34: 26 | B34: =IF(26>43,NA(),SUMIFS(DATOS!$E$2:$E$99,DATOS!$D$2:$D$99,"Carmex",DATOS!$L$2:$L$99,"<="&A34)) | C34: =IF(26>55,NA(),SUMIFS(DATOS!$E$2:$E$99,DATOS!$D$2:$D$99,"Fanel",DATOS!$L$2:$L$99,"<="&A34))
A35: 27 | B35: =IF(27>43,NA(),SUMIFS(DATOS!$E$2:$E$99,DATOS!$D$2:$D$99,"Carmex",DATOS!$L$2:$L$99,"<="&A35)) | C35: =IF(27>55,NA(),SUMIFS(DATOS!$E$2:$E$99,DATOS!$D$2:$D$99,"Fanel",DATOS!$L$2:$L$99,"<="&A35))
A36: 28 | B36: =IF(28>43,NA(),SUMIFS(DATOS!$E$2:$E$99,DATOS!$D$2:$D$99,"Carmex",DATOS!$L$2:$L$99,"<="&A36)) | C36: =IF(28>55,NA(),SUMIFS(DATOS!$E$2:$E$99,DATOS!$D$2:$D$99,"Fanel",DATOS!$L$2:$L$99,"<="&A36))
A37: 29 | B37: =IF(29>43,NA(),SUMIFS(DATOS!$E$2:$E$99,DATOS!$D$2:$D$99,"Carmex",DATOS!$L$2:$L$99,"<="&A37)) | C37: =IF(29>55,NA(),SUMIFS(DATOS!$E$2:$E$99,DATOS!$D$2:$D$99,"Fanel",DATOS!$L$2:$L$99,"<="&A37))
A38: 30 | B38: =IF(30>43,NA(),SUMIFS(DATOS!$E$2:$E$99,DATOS!$D$2:$D$99,"Carmex",DATOS!$L$2:$L$99,"<="&A38)) | C38: =IF(30>55,NA(),SUMIFS(DATOS!$E$2:$E$99,DATOS!$D$2:$D$99,"Fanel",DATOS!$L$2:$L$99,"<="&A38))
A39: 31 | B39: =IF(31>43,NA(),SUMIFS(DATOS!$E$2:$E$99,DATOS!$D$2:$D$99,"Carmex",DATOS!$L$2:$L$99,"<="&A39)) | C39: =IF(31>55,NA(),SUMIFS(DATOS!$E$2:$E$99,DATOS!$D$2:$D$99,"Fanel",DATOS!$L$2:$L$99,"<="&A39))
A40: 32 | B40: =IF(32>43,NA(),SUMIFS(DATOS!$E$2:$E$99,DATOS!$D$2:$D$99,"Carmex",DATOS!$L$2:$L$99,"<="&A40)) | C40: =IF(32>55,NA(),SUMIFS(DATOS!$E$2:$E$99,DATOS!$D$2:$D$99,"Fanel",DATOS!$L$2:$L$99,"<="&A40))
A41: 33 | B41: =IF(33>43,NA(),SUMIFS(DATOS!$E$2:$E$99,DATOS!$D$2:$D$99,"Carmex",DATOS!$L$2:$L$99,"<="&A41)) | C41: =IF(33>55,NA(),SUMIFS(DATOS!$E$2:$E$99,DATOS!$D$2:$D$99,"Fanel",DATOS!$L$2:$L$99,"<="&A41))
A42: 34 | B42: =IF(34>43,NA(),SUMIFS(DATOS!$E$2:$E$99,DATOS!$D$2:$D$99,"Carmex",DATOS!$L$2:$L$99,"<="&A42)) | C42: =IF(34>55,NA(),SUMIFS(DATOS!$E$2:$E$99,DATOS!$D$2:$D$99,"Fanel",DATOS!$L$2:$L$99,"<="&A42))
A43: 35 | B43: =IF(35>43,NA(),SUMIFS(DATOS!$E$2:$E$99,DATOS!$D$2:$D$99,"Carmex",DATOS!$L$2:$L$99,"<="&A43)) | C43: =IF(35>55,NA(),SUMIFS(DATOS!$E$2:$E$99,DATOS!$D$2:$D$99,"Fanel",DATOS!$L$2:$L$99,"<="&A43))
A44: 36 | B44: =IF(36>43,NA(),SUMIFS(DATOS!$E$2:$E$99,DATOS!$D$2:$D$99,"Carmex",DATOS!$L$2:$L$99,"<="&A44)) | C44: =IF(36>55,NA(),SUMIFS(DATOS!$E$2:$E$99,DATOS!$D$2:$D$99,"Fanel",DATOS!$L$2:$L$99,"<="&A44))
A45: 37 | B45: =IF(37>43,NA(),SUMIFS(DATOS!$E$2:$E$99,DATOS!$D$2:$D$99,"Carmex",DATOS!$L$2:$L$99,"<="&A45)) | C45: =IF(37>55,NA(),SUMIFS(DATOS!$E$2:$E$99,DATOS!$D$2:$D$99,"Fanel",DATOS!$L$2:$L$99,"<="&A45))
...
